Workbook
Name RelicID: IDS!$E$9
Name RelicValidation: IDS!$F$7
Name IDS_BOT_LEVEL: LAMBDA(bot_name, bot_property, LET( off, (MATCH(bot_name, '_IDS'!$AS$2:$AS$17, 0) - 1), VLOOKUP(bot_property, OFFSET('_IDS'!$AU$2, off, 0, 4, 3), 3, FALSE) ))
Name IDS_WS_LEVEL: LAMBDA(ws_name, MAX(IDS_WS_COIN_LEVEL(ws_name), IDS_WS_CASH_LEVEL(ws_name)))
Name IDS_MOD_CORE_SUBSTATS: LAMBDA(name, IFERROR(OFFSET('_IDS'!$BQ$31, MATCH(name, '_IDS'!$BQ$27:$BQ, 0)-1, 0, 8, 4)))
Name IDS_UW_OWN: LAMBDA(uw_name, LET( off, (MATCH(uw_name, '_IDS'!$Z$2:$Z$37, 0) - 1), OFFSET('_IDS'!$Z$4, off, 0, 1, 1) ))
Name IDS_MOD_CORE_ASSIST_SUBSTAT_CAP: LAMBDA('_IDS'!$BR$5)
Name IDS_BOT_VALUE: LAMBDA(bot_name, bot_property, LET( off, (MATCH(bot_name, '_IDS'!$AS$2:$AS$17, 0) - 1), VLOOKUP(bot_property, OFFSET('_IDS'!$AU$2, off, 0, 4, 2), 2, FALSE) ))
Name IDS_THEMES_BOOST: LAMBDA('_IDS'!$AY$2)
Name IDS_MOD_CANNON_ASSIST_LEVEL: LAMBDA('_IDS'!$BD$2)
Name IDS_MOD_GENERATOR_BONUS: LAMBDA(name, OFFSET('_IDS'!$BN$29, MATCH(name, '_IDS'!$BL$27:$BL, 0)-1, 0, 1, 1))
Name DVT_WSP_COST: LAMBDA(ws_stat, ws_level, OFFSET(DVT_Workshop!$I$2, ws_level, MATCH(SUBSTITUTE(ws_stat, " +", ""), DVT_Workshop!$I$1:$Z$1, 0)-1, 1, 1))
Name IDS_MOD_CORE_NAME: LAMBDA(preset, OFFSET('_IDS'!$BR$8, MATCH(preset, '_IDS'!$BQ$7:$BQ$23, 0)-1, 0, 1, 1))
Name IDS_MOD_CANNON_ASSIST_MULT_CAP: LAMBDA('_IDS'!$BC$4)
Name IDS_LAB_LEVEL: LAMBDA(lab_name, IF('_IDS'!$C$1="✅", VLOOKUP(lab_name, '_IDS'!$A$2:$B, 2, FALSE), 0))
Name IDS_MOD_ARMOR_LEVEL: LAMBDA(name, OFFSET('_IDS'!$BH$29, MATCH(name, '_IDS'!$BG$27:$BG, 0)-1, 0, 1, 1))
Name IDS_MOD_CORE_LEVEL: LAMBDA(name, OFFSET('_IDS'!$BR$29, MATCH(name, '_IDS'!$BQ$27:$BQ, 0)-1, 0, 1, 1))
Name IDS_MOD_GENERATOR_NAME: LAMBDA(preset, OFFSET('_IDS'!$BM$8, MATCH(preset, '_IDS'!$BL$7:$BL$23, 0)-1, 0, 1, 1))
Name IDS_MOD_ARMOR_NAME: LAMBDA(preset, OFFSET('_IDS'!$BH$8, MATCH(preset, '_IDS'!$BG$7:$BG$23, 0)-1, 0, 1, 1))
Name IDS_UW_VALUE: LAMBDA(uw_name, uw_stat, LET( off, (MATCH(uw_name, '_IDS'!$Z$2:$Z$37, 0) - 1), VLOOKUP(uw_stat, OFFSET('_IDS'!$AB$2, off, 0, 4, 2), 2, FALSE) ))
Name IDS_CARD_PRESET: LAMBDA(preset, OFFSET('_IDS'!$AH$3, 0, MATCH(preset, '_IDS'!$AH$2:$AL$2, 0)-1, 27, 1))
Name IDS_MOD_ARMOR_ASSIST_SUBSTAT_CAP: LAMBDA('_IDS'!$BH$5)
Name DVT_WSP_VALUE: LAMBDA(ws_stat, ws_level, SWITCH(ws_stat, "Land Mine Damage", 1+0.06*ws_level, 1+0.01*ws_level ))
Name IDS_RELIC_STAT: LAMBDA(relic_stat, IFERROR(IF('_IDS'!$AO$1="✅", VLOOKUP(relic_stat,'_IDS'!$AM$2:$AN,2,FALSE), 0), 0))
Name IDS_MOD_CANNON_SUBSTATS: LAMBDA(name, IFERROR(OFFSET('_IDS'!$BB$31, MATCH(name, '_IDS'!$BB$27:$BB, 0)-1, 0, 8, 4)))
Name IDS_MOD_CORE_BONUS: LAMBDA(name, OFFSET('_IDS'!$BS$29, MATCH(name, '_IDS'!$BQ$27:$BQ, 0)-1, 0, 1, 1))
Name IDS_MOD_GENERATOR_LEVEL: LAMBDA(name, OFFSET('_IDS'!$BM$29, MATCH(name, '_IDS'!$BL$27:$BL, 0)-1, 0, 1, 1))
Name IDS_MOD_CORE_ASSIST_LEVEL: LAMBDA('_IDS'!$BS$2)
Name IDS_MOD_GENERATOR_ASSIST_SUBSTAT_CAP: LAMBDA('_IDS'!$BM$5)
Name IDS_MOD_ARMOR_BONUS: LAMBDA(name, OFFSET('_IDS'!$BI$29, MATCH(name, '_IDS'!$BG$27:$BG, 0)-1, 0, 1, 1))
Name IDS_UW_LEVEL: LAMBDA(uw_name, uw_stat, LET( off, (MATCH(uw_name, '_IDS'!$Z$2:$Z$37, 0) - 1), VLOOKUP(uw_stat, OFFSET('_IDS'!$AB$2, off, 0, 4, 3), 3, FALSE) ))
Name IDS_MOD_CORE_RARITY: LAMBDA(name, IFERROR(OFFSET('_IDS'!$BQ$29, MATCH(name, '_IDS'!$BQ$27:$BQ, 0)-1, 0, 1, 1)))
Name IDS_MOD_CANNON_BONUS: LAMBDA(name, OFFSET('_IDS'!$BD$29, MATCH(name, '_IDS'!$BB$27:$BB, 0)-1, 0, 1, 1))
Name IDS_MOD_GENERATOR_ASSIST_LEVEL: LAMBDA('_IDS'!$BN$2)
Name IDS_CARD_MASTERY: LAMBDA(card_name, VLOOKUP(card_name,'_IDS'!$AE$2:$AG$31, 3, FALSE))
Name IDS_MOD_GENERATOR_SUBSTATS: LAMBDA(name, IFERROR(OFFSET('_IDS'!$BL$31, MATCH(name, '_IDS'!$BL$27:$BL, 0)-1, 0, 8, 4)))
Name IDS_LAB_TARGET: LAMBDA(lab_name, IF('_IDS'!$C$1="✅", VLOOKUP(lab_name, '_IDS'!$A$2:$C, 3, FALSE), ))
Name IDS_MOD_GENERATOR_ASSIST_NAME: LAMBDA(preset, OFFSET('_IDS'!$BM$9, MATCH(preset, '_IDS'!$BL$7:$BL$23, 0)-1, 0, 1, 1))
Name IDS_MOD_ARMOR_SUBSTATS: LAMBDA(name, IFERROR(OFFSET('_IDS'!$BG$31, MATCH(name, '_IDS'!$BG$27:$BG, 0)-1, 0, 8, 4)))
Name IDS_WSE_LEVEL: LAMBDA(wse_name, IF('_IDS'!$G$1="✅", IFERROR(VLOOKUP(wse_name, '_IDS'!$R$2:$T, 3, FALSE), 0), 0))
Name IDS_MOD_CANNON_NAME: LAMBDA(preset, OFFSET('_IDS'!$BC$8, MATCH(preset, '_IDS'!$BB$7:$BB$23, 0)-1, 0, 1, 1))
Name IDS_MOD_CANNON_ASSIST_SUBSTAT_CAP: LAMBDA('_IDS'!$BC$5)
Name IDS_MOD_ARMOR_ASSIST_MULT_CAP: LAMBDA('_IDS'!$BH$4)
Name IDS_CARDS_IN_PRESET: LAMBDA(preset, card_name, COUNTIF(OFFSET('_IDS'!$AH$3, 0, MATCH(preset, '_IDS'!$AH$2:$AL$2, 0)-1, 30, 1) , card_name) > 0)
Name IDS_MOD_CANNON_ASSIST_NAME: LAMBDA(preset, OFFSET('_IDS'!$BC$9, MATCH(preset, '_IDS'!$BB$7:$BB$23, 0)-1, 0, 1, 1))
Name IDS_WS_COIN_LEVEL: LAMBDA(ws_name, IF('_IDS'!$G$1="✅", IFERROR(VLOOKUP(ws_name, '_IDS'!$F$2:$Q, 2, FALSE), 0), 0))
Name IDS_VAULT_STAT: LAMBDA(vault_stat, IFERROR(IF('_IDS'!$AR$1="✅", VLOOKUP(vault_stat,'_IDS'!$AP$2:$AQ,2,FALSE), 0), 0))
Name FORMAT_TIME: LAMBDA(duration, IF(duration,int(duration)&"d "&if(hour(mod(duration,1))<10,CHAR(8194),)&hour(mod(duration,1))&"h "&if(minute(mod(duration,1))<10,CHAR(8194),)&minute(mod(duration,1))&"m",))
Name IDS_BOT_OWN: LAMBDA(bot_name, LET( off, (MATCH(bot_name, '_IDS'!$AS$2:$AS$17, 0) - 1), OFFSET('_IDS'!$AS$5, off, 0, 1, 1) ))
Name IDS_MOD_CANNON_RARITY: LAMBDA(name, IFERROR(OFFSET('_IDS'!$BB$29, MATCH(name, '_IDS'!$BB$27:$BB, 0)-1, 0, 1, 1)))
Name IDS_MOD_ARMOR_ASSIST_NAME: LAMBDA(preset, OFFSET('_IDS'!$BH$9, MATCH(preset, '_IDS'!$BG$7:$BG$23, 0)-1, 0, 1, 1))
Name WSPCOST_SINGLE_ADJUSTED: LAMBDA(name, level, INDEX( DVT_Workshop!$I$3:$Z$402, level, MATCH( name, DVT_Workshop!$I$1:$Z$1, 0))*(1-'Master Sheet'!$Z$18))
Name IDS_MOD_CORE_ASSIST_NAME: LAMBDA(preset, OFFSET('_IDS'!$BR$9, MATCH(preset, '_IDS'!$BQ$7:$BQ$23, 0)-1, 0, 1, 1))
Name IDS_MOD_ARMOR_RARITY: LAMBDA(name, IFERROR(OFFSET('_IDS'!$BG$29, MATCH(name, '_IDS'!$BG$27:$BG, 0)-1, 0, 1, 1)))
Name IDS_MOD_GENERATOR_ASSIST_MULT_CAP: LAMBDA('_IDS'!$BM$4)
Name IDS_WS_CASH_LEVEL: LAMBDA(ws_name, IF('_IDS'!$G$1="✅", IFERROR(VLOOKUP(ws_name, '_IDS'!$F$2:$Q, 3, FALSE), 0), 0))
Name IDS_MOD_CORE_ASSIST_MULT_CAP: LAMBDA('_IDS'!$BR$4)
Name IDS_CARD_LEVEL: LAMBDA(card_name, IF(VLOOKUP(card_name,'_IDS'!$AE$2:$AG$31, 2, FALSE)="Locked", 1, VLOOKUP(card_name,'_IDS'!$AE$2:$AG$31, 2, FALSE)))
Name IDS_MOD_CANNON_LEVEL: LAMBDA(name, OFFSET('_IDS'!$BC$29, MATCH(name, '_IDS'!$BB$27:$BB, 0)-1, 0, 1, 1))
Name IDS_MOD_GENERATOR_RARITY: LAMBDA(name, IFERROR(OFFSET('_IDS'!$BL$29, MATCH(name, '_IDS'!$BL$27:$BL, 0)-1, 0, 1, 1)))

Sheet Home Page
B2: Workshop
B4: =HYPERLINK("https://docs.google.com/spreadsheets/d/1GRVlWERQmvfHgsWytiY6gJn8-7oDDnGbg1Bsb5x4TS8/copy", "Workshop Initial Link") -> Workshop Initial Link | G4: Sheet Tab | H4: Main Contributor | I4: Helpers
G6: IDS | H6: @Mattew | I6: @Bisse
B7: Latest remote version : | G7: Master Sheet | H7: @Mattew
B8: =IFERROR(__xludf.DUMMYFUNCTION("IMPORTRANGE(""1GRVlWERQmvfHgsWytiY6gJn8-7oDDnGbg1Bsb5x4TS8"", ""'Home Page'!B12:C13"")"),"v2.3.1") -> v2.3.1 | C8: =IFERROR(__xludf.DUMMYFUNCTION("""COMPUTED_VALUE"""),"fix: Card #28 format") -> fix: Card #28 format | G8: Desired Ratios | H8: @Meringue
B9: =IFERROR(__xludf.DUMMYFUNCTION("""COMPUTED_VALUE"""),"v2.3") -> v2.3 | C9: =IFERROR(__xludf.DUMMYFUNCTION("""COMPUTED_VALUE"""),"feat: Desired Ratio works with more fractions (X/XXX)") -> feat: Desired Ratio works with more fractions (X/XXX) | G9: Goldbox Calculator | H9: @GodzillasDaddy
G10: ELS+ ROI Calculator | H10: @Dark & @1410c
B11: Version Change : | G11: Coins+ vs ELS+ | H11: @Dark
B12: v2.3.1 | C12: fix: Card #28 format | G12: Workshop Enhancement Prices
B13: v2.3 | C13: feat: Desired Ratio works with more fractions (X/XXX)
B14: v2.2.9 | C14: Feat: X's dream fulfilled (better color conditional) | G14: Tab colors explanation
B15: v2.2.8 | C15: Feat: presets for Desired Ratios
B16: v2.2.7 | C16: Fix: Coins+ vs ELS+ used wrong EALS/ EHLS stats | G16: Home Page | H16: Input Tabs | I16: Local Tools
B17: v2.2.6 | C17: Feat: Included Vault in ELS+ ROI | H17: Static Data
B18: v2.2.5 | C18: Feat: Included Relic + Assist in ELS+ ROI
B19: v2.2.4 | C19: export WS+ coin spent
B20: v2.2.3 | C20: Fix: desired ratios custom order | G20: Enjoying those sheets? You can support me by using my creator code for any in game or webstore purchases. My creator code is : SHEETLORD
B21: v2.2.2 | C21: Fix: desired ratios
B22: v2.2.1 | C22: Fix: WS+ cost calculation
B23: v2.2 | C23: Max levels for WS+ updated
B24: v2.1 | C24: New: Desired Ratios
B25: v2.0 | C25: IDS 2.0 + V27 | G25: Want to support someone else ? Here is the creator code list
B26: v1.8 | C26: New: Goldbox Calculator
B27: v1.7 | C27: New: Coins+ vs ELS+ | G27: =IFERROR(__xludf.DUMMYFUNCTION("IMPORTRANGE(""1eCPPuQOE3Pyh8HhnApEMK3RFIutkUjWd61ppVImwWk8"", ""_Giveaway_summary!A1:A2"")"),"⚠️ 1 Giveaway(s) running - 22 Mar") -> ⚠️ 1 Giveaway(s) running - 22 Mar
B28: v1.6 | C28: Import url fix | G28: =IFERROR(__xludf.DUMMYFUNCTION("""COMPUTED_VALUE"""),"Giveaway Details") -> Giveaway Details
B29: v1.5 | C29: Added Import
B30: v1.4 | C30: Version tracking udpate
B31: v1.3 | C31: Using now IDS Master
B32: v1.2 | C32: Added Modules ID and improved ELS+
B33: v1.1 | C33: Export fix for WS+

Sheet IDS
B2: The IDS System | I2: Looking for the Import script ? Just run it as you were doing it before, but from IDS Master. It will let you import every new versions at once!
B4: This Sheet ID is : | C4: 1huHJMcyg1uRJEeRYqAgWzMc5TodPPplVZEFhwBiIeEs
B6: IDS Master's ID ➡️ | C6: 1HOIkxWbbciTIAzVruaahEGADlM8rS0-w86uBXj4PwNQ | D6: =IFERROR(__xludf.DUMMYFUNCTION("IFERROR(C6.url, IFS(LEFT(C6,8)=""https://"", C6, LEN(C6)=44, ""https://docs.google.com/spreadsheets/d/"" & C6 & ""/edit"", TRUE, C6))"),"https://docs.google.com/spreadsheets/d/1HOIkxWbbciTIAzVruaahEGADlM8rS0-w86uBXj4PwNQ/edit") -> https://docs.google.com/spreadsheets/d/1HOIkxWbbciTIAzVruaahEGADlM8rS0-w86uBXj4PwNQ/edit | E6: =IFERROR(__xludf.DUMMYFUNCTION("IF(D6<>"""", IF(IMPORTRANGE(D6,""EXPORT!A1"") = F6, ""✅"", ""Wrong ID or Version""), """")"),"✅") -> ✅ | F6: v2
B7: =HYPERLINK("https://docs.google.com/spreadsheets/d/1osjoqKmMwtOWs7Up3e21-3ofN1RHOjsgKV6y3dc6rgE/copy", "1️⃣ Copy Me") -> 1️⃣ Copy Me | C7: =IFS( ISERROR(E6), "3️⃣ Click on #REF! and then AUTHORISE ↗", E6="", "2️⃣ Please input your IDS Master's ID here ⤴️", E6="✅", HYPERLINK(D6, "Go to my IDS Master Sheet"), TRUE, "") -> Go to my IDS Master Sheet | E7: ✅ | I7: Issues
I8: Mobile Users If you are on mobile, you will not be able to do STEP 3. There is a workaround you can do still : You need to edit the viewing permissions to "anyone with the link" of all your IDs sheets If you have any other trouble, let us know in the #effective-path Discord's channel. I say us, but don't ask Fanta. Fanta hates IDS.
B9: How to use
B10: STEP 1: Click on the Copy Me link and create your copy of the IDS Master. STEP 2: Copy the ID (you will find it in the IDS page) of your newly created sheet and paste it in the light gray area. STEP 3: Wait a little bit, the F5 cell will show "Loading...", and after few seconds it will display "#REF!". Click on the cell, and "Authorize" to let this sheet access the other one.
B19: And that's it! The IDS are setuped. You can now fill sub IDS in the IDS Master with sub IDS sheets (Laboratory, Workshop, ...) just like you did in here. Every time you will change a value (let's say, a lab level in Laboratory Sheet) the change will be propagated to every other sheet using the IDS Master automatically.
B23: Is it mandatory ?
B24: No, it is not really mandatory but it is the best practice I would recommend. You should be able to override everything using the Master Sheet. But that's not how this is supposed to be used.

Sheet _IDS
A1: =IFERROR(__xludf.DUMMYFUNCTION("IMPORTRANGE(IF(IDS!E6=""✅"", IDS!D6, ""1osjoqKmMwtOWs7Up3e21-3ofN1RHOjsgKV6y3dc6rgE""), ""_IDS!A1:CE212"")"),"Labs") -> Labs | B1: =IFERROR(__xludf.DUMMYFUNCTION("""COMPUTED_VALUE"""),"https://docs.google.com/spreadsheets/d/1jojOg_XIJCzm1LCYWu2F4KCtErjUIdKuFL1PiKzA0OE/edit") -> https://docs.google.com/spreadsheets/d/1jojOg_XIJCzm1LCYWu2F4KCtErjUIdKuFL1PiKzA0OE/edit | C1: =IFERROR(__xludf.DUMMYFUNCTION("""COMPUTED_VALUE"""),"✅") -> ✅ | D1: =IFERROR(__xludf.DUMMYFUNCTION("""COMPUTED_VALUE"""),"v2.5.7") -> v2.5.7 | E1: =IFERROR(__xludf.DUMMYFUNCTION("""COMPUTED_VALUE"""),"WS") -> WS | F1: =IFERROR(__xludf.DUMMYFUNCTION("""COMPUTED_VALUE"""),"https://docs.google.com/spreadsheets/d/1huHJMcyg1uRJEeRYqAgWzMc5TodPPplVZEFhwBiIeEs/edit") -> https://docs.google.com/spreadsheets/d/1huHJMcyg1uRJEeRYqAgWzMc5TodPPplVZEFhwBiIeEs/edit | G1: =IFERROR(__xludf.DUMMYFUNCTION("""COMPUTED_VALUE"""),"✅") -> ✅ | H1: =IFERROR(__xludf.DUMMYFUNCTION("""COMPUTED_VALUE"""),"v2.3.1") -> v2.3.1 | R1: =IFERROR(__xludf.DUMMYFUNCTION("""COMPUTED_VALUE"""),"WS+") -> WS+ | Z1: =IFERROR(__xludf.DUMMYFUNCTION("""COMPUTED_VALUE"""),"UWs") -> UWs | AA1: =IFERROR(__xludf.DUMMYFUNCTION("""COMPUTED_VALUE"""),"https://docs.google.com/spreadsheets/d/1VTRhVyt28cxrjCRcgVkQr2R_u4g9irfJTHy1cfftlIE/edit") -> https://docs.google.com/spreadsheets/d/1VTRhVyt28cxrjCRcgVkQr2R_u4g9irfJTHy1cfftlIE/edit | AB1: =IFERROR(__xludf.DUMMYFUNCTION("""COMPUTED_VALUE"""),"✅") -> ✅ | AC1: =IFERROR(__xludf.DUMMYFUNCTION("""COMPUTED_VALUE"""),"v2.1.3") -> v2.1.3 | AE1: =IFERROR(__xludf.DUMMYFUNCTION("""COMPUTED_VALUE"""),"Cards") -> Cards | AF1: =IFERROR(__xludf.DUMMYFUNCTION("""COMPUTED_VALUE"""),"https://docs.google.com/spreadsheets/d/1HMQwNLTvcw7aXmjjL7cXmZSdjAF_62ehWpwDIdjqEGs/edit") -> https://docs.google.com/spreadsheets/d/1HMQwNLTvcw7aXmjjL7cXmZSdjAF_62ehWpwDIdjqEGs/edit | AG1: =IFERROR(__xludf.DUMMYFUNCTION("""COMPUTED_VALUE"""),"✅") -> ✅ | AH1: =IFERROR(__xludf.DUMMYFUNCTION("""COMPUTED_VALUE"""),"Cards Presets") -> Cards Presets | AI1: =IFERROR(__xludf.DUMMYFUNCTION("""COMPUTED_VALUE"""),"v2.2.3") -> v2.2.3 | AJ1: =IFERROR(__xludf.DUMMYFUNCTION("""COMPUTED_VALUE"""),17.0) -> 17 | AM1: =IFERROR(__xludf.DUMMYFUNCTION("""COMPUTED_VALUE"""),"Relics") -> Relics | AN1: =IFERROR(__xludf.DUMMYFUNCTION("""COMPUTED_VALUE"""),"https://docs.google.com/spreadsheets/d/1Dll0IofJTWYkzhzhRWx1aA-_xtO3i_1iD65nAP6R_Ec/edit") -> https://docs.google.com/spreadsheets/d/1Dll0IofJTWYkzhzhRWx1aA-_xtO3i_1iD65nAP6R_Ec/edit | AO1: =IFERROR(__xludf.DUMMYFUNCTION("""COMPUTED_VALUE"""),"✅") -> ✅ | AP1: =IFERROR(__xludf.DUMMYFUNCTION("""COMPUTED_VALUE"""),"Vault") -> Vault | AR1: =IFERROR(__xludf.DUMMYFUNCTION("""COMPUTED_VALUE"""),"") | AS1: =IFERROR(__xludf.DUMMYFUNCTION("""COMPUTED_VALUE"""),"Bots") -> Bots | AT1: =IFERROR(__xludf.DUMMYFUNCTION("""COMPUTED_VALUE"""),"https://docs.google.com/spreadsheets/d/1H3PYvtIH7kId6WswEeMmrx7u5_g1GlkNPJtJhkASrbs/edit") -> https://docs.google.com/spreadsheets/d/1H3PYvtIH7kId6WswEeMmrx7u5_g1GlkNPJtJhkASrbs/edit | AU1: =IFERROR(__xludf.DUMMYFUNCTION("""COMPUTED_VALUE"""),"✅") -> ✅ | AV1: =IFERROR(__xludf.DUMMYFUNCTION("""COMPUTED_VALUE"""),"v2.2.1") -> v2.2.1 | AY1: =IFERROR(__xludf.DUMMYFUNCTION("""COMPUTED_VALUE"""),"Themes & Songs") -> Themes & Songs | AZ1: =IFERROR(__xludf.DUMMYFUNCTION("""COMPUTED_VALUE"""),"https://docs.google.com/spreadsheets/d/19KliigQhAeXztRPa9cSGZ7n9Q-REp4dyqMNI9d-UB0k/edit") -> https://docs.google.com/spreadsheets/d/19KliigQhAeXztRPa9cSGZ7n9Q-REp4dyqMNI9d-UB0k/edit | BA1: =IFERROR(__xludf.DUMMYFUNCTION("""COMPUTED_VALUE"""),"✅") -> ✅ | BB1: =IFERROR(__xludf.DUMMYFUNCTION("""COMPUTED_VALUE"""),"Modules") -> Modules | BC1: =IFERROR(__xludf.DUMMYFUNCTION("""COMPUTED_VALUE"""),"https://docs.google.com/spreadsheets/d/1rOoSY6TK918myJ6Mn6zO4rmUaFbPu6qJnGI17kc9DzQ/edit") -> https://docs.google.com/spreadsheets/d/1rOoSY6TK918myJ6Mn6zO4rmUaFbPu6qJnGI17kc9DzQ/edit | BD1: =IFERROR(__xludf.DUMMYFUNCTION("""COMPUTED_VALUE"""),"✅") -> ✅ | BE1: =IFERROR(__xludf.DUMMYFUNCTION("""COMPUTED_VALUE"""),"v5.13") -> v5.13 | BU1: =IFERROR(__xludf.DUMMYFUNCTION("""COMPUTED_VALUE"""),"Guardians") -> Guardians | BV1: =IFERROR(__xludf.DUMMYFUNCTION("""COMPUTED_VALUE"""),"https://docs.google.com/spreadsheets/d/1J4UPKzR9MLY_zzM7u7SzmyclgTEYX_PUvBcua4EbsSU/edit") -> https://docs.google.com/spreadsheets/d/1J4UPKzR9MLY_zzM7u7SzmyclgTEYX_PUvBcua4EbsSU/edit | BW1: =IFERROR(__xludf.DUMMYFUNCTION("""COMPUTED_VALUE"""),"✅") -> ✅ | BX1: =IFERROR(__xludf.DUMMYFUNCTION("""COMPUTED_VALUE"""),"v2.3.6") -> v2.3.6 | BZ1: =IFERROR(__xludf.DUMMYFUNCTION("""COMPUTED_VALUE"""),"Player & Stuff") -> Player & Stuff | CA1: =IFERROR(__xludf.DUMMYFUNCTION("""COMPUTED_VALUE"""),"https://docs.google.com/spreadsheets/d/1NpLNfHLQFsJ_WyMnxP9jMtzg3gVaMfOxydrTUG0YsuM/edit") -> https://docs.google.com/spreadsheets/d/1NpLNfHLQFsJ_WyMnxP9jMtzg3gVaMfOxydrTUG0YsuM/edit | CB1: =IFERROR(__xludf.DUMMYFUNCTION("""COMPUTED_VALUE"""),"✅") -> ✅ | CC1: =IFERROR(__xludf.DUMMYFUNCTION("""COMPUTED_VALUE"""),"v3.5.3") -> v3.5.3
A2: =IFERROR(__xludf.DUMMYFUNCTION("""COMPUTED_VALUE"""),"Game Speed") -> Game Speed | B2: =IFERROR(__xludf.DUMMYFUNCTION("""COMPUTED_VALUE"""),7.0) -> 7 | C2: =IFERROR(__xludf.DUMMYFUNCTION("""COMPUTED_VALUE"""),7.0) -> 7 | D2: =IFERROR(__xludf.DUMMYFUNCTION("""COMPUTED_VALUE"""),7.0) -> 7 | E2: =IFERROR(__xludf.DUMMYFUNCTION("""COMPUTED_VALUE"""),"U") -> U | F2: =IFERROR(__xludf.DUMMYFUNCTION("""COMPUTED_VALUE"""),"Workshop Upgrade") -> Workshop Upgrade | G2: =IFERROR(__xludf.DUMMYFUNCTION("""COMPUTED_VALUE"""),"Farming") -> Farming | I2: =IFERROR(__xludf.DUMMYFUNCTION("""COMPUTED_VALUE"""),"Tourney") -> Tourney | K2: =IFERROR(__xludf.DUMMYFUNCTION("""COMPUTED_VALUE"""),"Preset 3") -> Preset 3 | M2: =IFERROR(__xludf.DUMMYFUNCTION("""COMPUTED_VALUE"""),"Preset 4") -> Preset 4 | O2: =IFERROR(__xludf.DUMMYFUNCTION("""COMPUTED_VALUE"""),"Preset 5") -> Preset 5 | R2: =IFERROR(__xludf.DUMMYFUNCTION("""COMPUTED_VALUE"""),"Workshop Enhancement") -> Workshop Enhancement | T2: =IFERROR(__xludf.DUMMYFUNCTION("""COMPUTED_VALUE"""),"Farming") -> Farming | U2: =IFERROR(__xludf.DUMMYFUNCTION("""COMPUTED_VALUE"""),"Tourney") -> Tourney | V2: =IFERROR(__xludf.DUMMYFUNCTION("""COMPUTED_VALUE"""),"Preset 3") -> Preset 3 | W2: =IFERROR(__xludf.DUMMYFUNCTION("""COMPUTED_VALUE"""),"Preset 4") -> Preset 4 | X2: =IFERROR(__xludf.DUMMYFUNCTION("""COMPUTED_VALUE"""),"Preset 5") -> Preset 5 | Y2: =IFERROR(__xludf.DUMMYFUNCTION("""COMPUTED_VALUE"""),"7 q") -> 7 q | Z2: =IFERROR(__xludf.DUMMYFUNCTION("""COMPUTED_VALUE"""),"Chain Lightning") -> Chain Lightning | AB2: =IFERROR(__xludf.DUMMYFUNCTION("""COMPUTED_VALUE"""),"Damage") -> Damage | AC2: =IFERROR(__xludf.DUMMYFUNCTION("""COMPUTED_VALUE"""),898.0) -> 898 | AD2: =IFERROR(__xludf.DUMMYFUNCTION("""COMPUTED_VALUE"""),"19 | x898 | Cost 302 ⧌ | Next 362 ⧌") -> 19 | x898 | Cost 302 ⧌ | Next 362 ⧌ | AE2: =IFERROR(__xludf.DUMMYFUNCTION("""COMPUTED_VALUE"""),"Damage") -> Damage | AF2: =IFERROR(__xludf.DUMMYFUNCTION("""COMPUTED_VALUE"""),7.0) -> 7 | AG2: =IFERROR(__xludf.DUMMYFUNCTION("""COMPUTED_VALUE"""),FALSE) -> FALSE | AH2: =IFERROR(__xludf.DUMMYFUNCTION("""COMPUTED_VALUE"""),"Farming") -> Farming | AI2: =IFERROR(__xludf.DUMMYFUNCTION("""COMPUTED_VALUE"""),"Tourney") -> Tourney | AJ2: =IFERROR(__xludf.DUMMYFUNCTION("""COMPUTED_VALUE"""),"Preset 3") -> Preset 3 | AK2: =IFERROR(__xludf.DUMMYFUNCTION("""COMPUTED_VALUE"""),"Preset 4") -> Preset 4 | AL2: =IFERROR(__xludf.DUMMYFUNCTION("""COMPUTED_VALUE"""),"Preset 5") -> Preset 5 | AM2: =IFERROR(__xludf.DUMMYFUNCTION("""COMPUTED_VALUE"""),"Relics") -> Relics | AN2: =IFERROR(__xludf.DUMMYFUNCTION("""COMPUTED_VALUE"""),"Owned") -> Owned | AO2: =IFERROR(__xludf.DUMMYFUNCTION("""COMPUTED_VALUE"""),"v2.3.7") -> v2.3.7 | AP2: =IFERROR(__xludf.DUMMYFUNCTION("""COMPUTED_VALUE"""),"Keys spent") -> Keys spent | AQ2: =IFERROR(__xludf.DUMMYFUNCTION("""COMPUTED_VALUE"""),0.0) -> 0 | AS2: =IFERROR(__xludf.DUMMYFUNCTION("""COMPUTED_VALUE"""),"Flame Bot") -> Flame Bot | AU2: =IFERROR(__xludf.DUMMYFUNCTION("""COMPUTED_VALUE"""),"Damage R.") -> Damage R. | AV2: =IFERROR(__xludf.DUMMYFUNCTION("""COMPUTED_VALUE"""),0.3500000000000001) -> 0.35 | AW2: =IFERROR(__xludf.DUMMYFUNCTION("""COMPUTED_VALUE"""),"05 | 35% | Cost 260 ⧓ | Next 300 ⧓") -> 05 | 35% | Cost 260 ⧓ | Next 300 ⧓ | AY2: =IFERROR(__xludf.DUMMYFUNCTION("""COMPUTED_VALUE"""),1.682) -> 1.682 | BA2: =IFERROR(__xludf.DUMMYFUNCTION("""COMPUTED_VALUE"""),"v2.2.3") -> v2.2.3 | BB2: =IFERROR(__xludf.DUMMYFUNCTION("""COMPUTED_VALUE"""),"Assist Slot") -> Assist Slot | BC2: =IFERROR(__xludf.DUMMYFUNCTION("""COMPUTED_VALUE"""),FALSE) -> FALSE | BD2: =IFERROR(__xludf.DUMMYFUNCTION("""COMPUTED_VALUE"""),0.0) -> 0 | BG2: =IFERROR(__xludf.DUMMYFUNCTION("""COMPUTED_VALUE"""),"Assist Slot") -> Assist Slot | BH2: =IFERROR(__xludf.DUMMYFUNCTION("""COMPUTED_VALUE"""),TRUE) -> TRUE | BI2: =IFERROR(__xludf.DUMMYFUNCTION("""COMPUTED_VALUE"""),41.0) -> 41 | BL2: =IFERROR(__xludf.DUMMYFUNCTION("""COMPUTED_VALUE"""),"Assist Slot") -> Assist Slot | BM2: =IFERROR(__xludf.DUMMYFUNCTION("""COMPUTED_VALUE"""),TRUE) -> TRUE | BN2: =IFERROR(__xludf.DUMMYFUNCTION("""COMPUTED_VALUE"""),97.0) -> 97 | BQ2: =IFERROR(__xludf.DUMMYFUNCTION("""COMPUTED_VALUE"""),"Assist Slot") -> Assist Slot | BR2: =IFERROR(__xludf.DUMMYFUNCTION("""COMPUTED_VALUE"""),TRUE) -> TRUE | BS2: =IFERROR(__xludf.DUMMYFUNCTION("""COMPUTED_VALUE"""),101.0) -> 101 | BU2: =IFERROR(__xludf.DUMMYFUNCTION("""COMPUTED_VALUE"""),"Attack") -> Attack | BW2: =IFERROR(__xludf.DUMMYFUNCTION("""COMPUTED_VALUE"""),"Percentage") -> Percentage | BX2: =IFERROR(__xludf.DUMMYFUNCTION("""COMPUTED_VALUE"""),0.01) -> 0.01 | BY2: =IFERROR(__xludf.DUMMYFUNCTION("""COMPUTED_VALUE"""),"00 | 1% | Cost 0 ⧈ | Next 25 ⧈") -> 00 | 1% | Cost 0 ⧈ | Next 25 ⧈ | BZ2: =IFERROR(__xludf.DUMMYFUNCTION("""COMPUTED_VALUE"""),"Tier") -> Tier | CA2: =IFERROR(__xludf.DUMMYFUNCTION("""COMPUTED_VALUE"""),"Wave") -> Wave | CB2: =IFERROR(__xludf.DUMMYFUNCTION("""COMPUTED_VALUE"""),"P") -> P | CD2: =IFERROR(__xludf.DUMMYFUNCTION("""COMPUTED_VALUE"""),"Stat") -> Stat | CE2: =IFERROR(__xludf.DUMMYFUNCTION("""COMPUTED_VALUE"""),"Value") -> Value
A3: =IFERROR(__xludf.DUMMYFUNCTION("""COMPUTED_VALUE"""),"Starting Cash") -> Starting Cash | B3: =IFERROR(__xludf.DUMMYFUNCTION("""COMPUTED_VALUE"""),6.0) -> 6 | D3: =IFERROR(__xludf.DUMMYFUNCTION("""COMPUTED_VALUE"""),99.0) -> 99 | G3: =IFERROR(__xludf.DUMMYFUNCTION("""COMPUTED_VALUE"""),"¢ Level") -> ¢ Level | H3: =IFERROR(__xludf.DUMMYFUNCTION("""COMPUTED_VALUE"""),"$ Level") -> $ Level | I3: =IFERROR(__xludf.DUMMYFUNCTION("""COMPUTED_VALUE"""),"¢ Level") -> ¢ Level | J3: =IFERROR(__xludf.DUMMYFUNCTION("""COMPUTED_VALUE"""),"$ Level") -> $ Level | K3: =IFERROR(__xludf.DUMMYFUNCTION("""COMPUTED_VALUE"""),"¢ Level") -> ¢ Level | L3: =IFERROR(__xludf.DUMMYFUNCTION("""COMPUTED_VALUE"""),"$ Level") -> $ Level | M3: =IFERROR(__xludf.DUMMYFUNCTION("""COMPUTED_VALUE"""),"¢ Level") -> ¢ Level | N3: =IFERROR(__xludf.DUMMYFUNCTION("""COMPUTED_VALUE"""),"$ Level") -> $ Level | O3: =IFERROR(__xludf.DUMMYFUNCTION("""COMPUTED_VALUE"""),"¢ Level") -> ¢ Level | P3: =IFERROR(__xludf.DUMMYFUNCTION("""COMPUTED_VALUE"""),"$ Level") -> $ Level | Q3: =IFERROR(__xludf.DUMMYFUNCTION("""COMPUTED_VALUE"""),"Max") -> Max | T3: =IFERROR(__xludf.DUMMYFUNCTION("""COMPUTED_VALUE"""),"WS+") -> WS+ | U3: =IFERROR(__xludf.DUMMYFUNCTION("""COMPUTED_VALUE"""),"WS+") -> WS+ | V3: =IFERROR(__xludf.DUMMYFUNCTION("""COMPUTED_VALUE"""),"WS+") -> WS+ | W3: =IFERROR(__xludf.DUMMYFUNCTION("""COMPUTED_VALUE"""),"WS+") -> WS+ | X3: =IFERROR(__xludf.DUMMYFUNCTION("""COMPUTED_VALUE"""),"WS+") -> WS+ | Y3: =IFERROR(__xludf.DUMMYFUNCTION("""COMPUTED_VALUE"""),"Max") -> Max | AB3: =IFERROR(__xludf.DUMMYFUNCTION("""COMPUTED_VALUE"""),"Quantity") -> Quantity | AC3: =IFERROR(__xludf.DUMMYFUNCTION("""COMPUTED_VALUE"""),4.0) -> 4 | AD3: =IFERROR(__xludf.DUMMYFUNCTION("""COMPUTED_VALUE"""),"03 | #4 | Cost 150 ⧌ | Next 400 ⧌") -> 03 | #4 | Cost 150 ⧌ | Next 400 ⧌ | AE3: =IFERROR(__xludf.DUMMYFUNCTION("""COMPUTED_VALUE"""),"Attack Speed") -> Attack Speed | AF3: =IFERROR(__xludf.DUMMYFUNCTION("""COMPUTED_VALUE"""),7.0) -> 7 | AG3: =IFERROR(__xludf.DUMMYFUNCTION("""COMPUTED_VALUE"""),FALSE) -> FALSE | AH3: =IFERROR(__xludf.DUMMYFUNCTION("""COMPUTED_VALUE"""),"Enemy Balance") -> Enemy Balance | AI3: =IFERROR(__xludf.DUMMYFUNCTION("""COMPUTED_VALUE"""),"Attack Speed") -> Attack Speed | AM3: =IFERROR(__xludf.DUMMYFUNCTION("""COMPUTED_VALUE"""),"Event Relics") -> Event Relics | AN3: =IFERROR(__xludf.DUMMYFUNCTION("""COMPUTED_VALUE"""),112.0) -> 112 | AU3: =IFERROR(__xludf.DUMMYFUNCTION("""COMPUTED_VALUE"""),"Cooldown") -> Cooldown | AV3: =IFERROR(__xludf.DUMMYFUNCTION("""COMPUTED_VALUE"""),51.0) -> 51 | AW3: =IFERROR(__xludf.DUMMYFUNCTION("""COMPUTED_VALUE"""),"08 | 51s | Cost 380 ⧓ | Next 420 ⧓") -> 08 | 51s | Cost 380 ⧓ | Next 420 ⧓ | BB3: =IFERROR(__xludf.DUMMYFUNCTION("""COMPUTED_VALUE"""),"Rarity Cap") -> Rarity Cap | BC3: =IFERROR(__xludf.DUMMYFUNCTION("""COMPUTED_VALUE"""),"Epic") -> Epic | BG3: =IFERROR(__xludf.DUMMYFUNCTION("""COMPUTED_VALUE"""),"Rarity Cap") -> Rarity Cap | BH3: =IFERROR(__xludf.DUMMYFUNCTION("""COMPUTED_VALUE"""),"Epic") -> Epic | BL3: =IFERROR(__xludf.DUMMYFUNCTION("""COMPUTED_VALUE"""),"Rarity Cap") -> Rarity Cap | BM3: =IFERROR(__xludf.DUMMYFUNCTION("""COMPUTED_VALUE"""),"Epic") -> Epic | BQ3: =IFERROR(__xludf.DUMMYFUNCTION("""COMPUTED_VALUE"""),"Rarity Cap") -> Rarity Cap | BR3: =IFERROR(__xludf.DUMMYFUNCTION("""COMPUTED_VALUE"""),"Epic") -> Epic | BW3: =IFERROR(__xludf.DUMMYFUNCTION("""COMPUTED_VALUE"""),"Cooldown") -> Cooldown | BX3: =IFERROR(__xludf.DUMMYFUNCTION("""COMPUTED_VALUE"""),120.0) -> 120 | BY3: =IFERROR(__xludf.DUMMYFUNCTION("""COMPUTED_VALUE"""),"00 | 120s | Cost 0 ⧈ | Next 1 ⧈") -> 00 | 120s | Cost 0 ⧈ | Next 1 ⧈ | BZ3: =IFERROR(__xludf.DUMMYFUNCTION("""COMPUTED_VALUE"""),"Tier 1") -> Tier 1 | CA3: =IFERROR(__xludf.DUMMYFUNCTION("""COMPUTED_VALUE"""),10210.0) -> 10210 | CB3: =IFERROR(__xludf.DUMMYFUNCTION("""COMPUTED_VALUE"""),TRUE) -> TRUE | CD3: =IFERROR(__xludf.DUMMYFUNCTION("""COMPUTED_VALUE"""),"Player ID") -> Player ID | CE3: =IFERROR(__xludf.DUMMYFUNCTION("""COMPUTED_VALUE"""),"4C64DCF66976FD33") -> 4C64DCF66976FD33
A4: =IFERROR(__xludf.DUMMYFUNCTION("""COMPUTED_VALUE"""),"Workshop Attack Discount") -> Workshop Attack Discount | B4: =IFERROR(__xludf.DUMMYFUNCTION("""COMPUTED_VALUE"""),27.0) -> 27 | D4: =IFERROR(__xludf.DUMMYFUNCTION("""COMPUTED_VALUE"""),99.0) -> 99 | F4: =IFERROR(__xludf.DUMMYFUNCTION("""COMPUTED_VALUE"""),"Damage") -> Damage | G4: =IFERROR(__xludf.DUMMYFUNCTION("""COMPUTED_VALUE"""),5750.0) -> 5750 | H4: =IFERROR(__xludf.DUMMYFUNCTION("""COMPUTED_VALUE"""),6000.0) -> 6000 | I4: =IFERROR(__xludf.DUMMYFUNCTION("""COMPUTED_VALUE"""),5750.0) -> 5750 | J4: =IFERROR(__xludf.DUMMYFUNCTION("""COMPUTED_VALUE"""),6000.0) -> 6000 | Q4: =IFERROR(__xludf.DUMMYFUNCTION("""COMPUTED_VALUE"""),6000.0) -> 6000 | R4: =IFERROR(__xludf.DUMMYFUNCTION("""COMPUTED_VALUE"""),"Damage +") -> Damage + | S4: =IFERROR(__xludf.DUMMYFUNCTION("""COMPUTED_VALUE"""),1.56) -> 1.56 | T4: =IFERROR(__xludf.DUMMYFUNCTION("""COMPUTED_VALUE"""),56.0) -> 56 | U4: =IFERROR(__xludf.DUMMYFUNCTION("""COMPUTED_VALUE"""),56.0) -> 56 | Y4: =IFERROR(__xludf.DUMMYFUNCTION("""COMPUTED_VALUE"""),400.0) -> 400 | Z4: =IFERROR(__xludf.DUMMYFUNCTION("""COMPUTED_VALUE"""),TRUE) -> TRUE | AA4: =IFERROR(__xludf.DUMMYFUNCTION("""COMPUTED_VALUE"""),"UW Unlocked") -> UW Unlocked | AB4: =IFERROR(__xludf.DUMMYFUNCTION("""COMPUTED_VALUE"""),"Chance") -> Chance | AC4: =IFERROR(__xludf.DUMMYFUNCTION("""COMPUTED_VALUE"""),0.17) -> 0.17 | AD4: =IFERROR(__xludf.DUMMYFUNCTION("""COMPUTED_VALUE"""),"08 | 17.0% | Cost 134 ⧌ | Next 152 ⧌") -> 08 | 17.0% | Cost 134 ⧌ | Next 152 ⧌ | AE4: =IFERROR(__xludf.DUMMYFUNCTION("""COMPUTED_VALUE"""),"Health") -> Health | AF4: =IFERROR(__xludf.DUMMYFUNCTION("""COMPUTED_VALUE"""),7.0) -> 7 | AG4: =IFERROR(__xludf.DUMMYFUNCTION("""COMPUTED_VALUE"""),FALSE) -> FALSE | AH4: =IFERROR(__xludf.DUMMYFUNCTION("""COMPUTED_VALUE"""),"Extra Defense") -> Extra Defense | AI4: =IFERROR(__xludf.DUMMYFUNCTION("""COMPUTED_VALUE"""),"Damage") -> Damage | AM4: =IFERROR(__xludf.DUMMYFUNCTION("""COMPUTED_VALUE"""),"Guild Relics") -> Guild Relics | AN4: =IFERROR(__xludf.DUMMYFUNCTION("""COMPUTED_VALUE"""),13.0) -> 13 | AP4: =IFERROR(__xludf.DUMMYFUNCTION("""COMPUTED_VALUE"""),"Total Bonuses") -> Total Bonuses | AQ4: =IFERROR(__xludf.DUMMYFUNCTION("""COMPUTED_VALUE"""),"Active") -> Active | AU4: =IFERROR(__xludf.DUMMYFUNCTION("""COMPUTED_VALUE"""),"Damage") -> Damage | AV4: =IFERROR(__xludf.DUMMYFUNCTION("""COMPUTED_VALUE"""),50.0) -> 50 | AW4: =IFERROR(__xludf.DUMMYFUNCTION("""COMPUTED_VALUE"""),"00 | x50 | Cost 0 ⧓ | Next 100 ⧓") -> 00 | x50 | Cost 0 ⧓ | Next 100 ⧓ | BB4: =IFERROR(__xludf.DUMMYFUNCTION("""COMPUTED_VALUE"""),"Multiplier Cap") -> Multiplier Cap | BC4: =IFERROR(__xludf.DUMMYFUNCTION("""COMPUTED_VALUE"""),0.01) -> 0.01 | BD4: =IFERROR(__xludf.DUMMYFUNCTION("""COMPUTED_VALUE"""),"00 | 1% | Cost 0 ⧌ | Next 15 ⧌") -> 00 | 1% | Cost 0 ⧌ | Next 15 ⧌ | BG4: =IFERROR(__xludf.DUMMYFUNCTION("""COMPUTED_VALUE"""),"Multiplier Cap") -> Multiplier Cap | BH4: =IFERROR(__xludf.DUMMYFUNCTION("""COMPUTED_VALUE"""),0.01) -> 0.01 | BI4: =IFERROR(__xludf.DUMMYFUNCTION("""COMPUTED_VALUE"""),"00 | 1% | Cost 0 ⧌ | Next 15 ⧌") -> 00 | 1% | Cost 0 ⧌ | Next 15 ⧌ | BL4: =IFERROR(__xludf.DUMMYFUNCTION("""COMPUTED_VALUE"""),"Multiplier Cap") -> Multiplier Cap | BM4: =IFERROR(__xludf.DUMMYFUNCTION("""COMPUTED_VALUE"""),0.1) -> 0.1 | BN4: =IFERROR(__xludf.DUMMYFUNCTION("""COMPUTED_VALUE"""),"09 | 10% | Cost 39 ⧌ | Next 42 ⧌") -> 09 | 10% | Cost 39 ⧌ | Next 42 ⧌ | BQ4: =IFERROR(__xludf.DUMMYFUNCTION("""COMPUTED_VALUE"""),"Multiplier Cap") -> Multiplier Cap | BR4: =IFERROR(__xludf.DUMMYFUNCTION("""COMPUTED_VALUE"""),0.1) -> 0.1 | BS4: =IFERROR(__xludf.DUMMYFUNCTION("""COMPUTED_VALUE"""),"09 | 10% | Cost 39 ⧌ | Next 42 ⧌") -> 09 | 10% | Cost 39 ⧌ | Next 42 ⧌ | BU4: =IFERROR(__xludf.DUMMYFUNCTION("""COMPUTED_VALUE"""),TRUE) -> TRUE | BV4: =IFERROR(__xludf.DUMMYFUNCTION("""COMPUTED_VALUE"""),"Unlocked") -> Unlocked | BW4: =IFERROR(__xludf.DUMMYFUNCTION("""COMPUTED_VALUE"""),"Targets") -> Targets | BX4: =IFERROR(__xludf.DUMMYFUNCTION("""COMPUTED_VALUE"""),1.0) -> 1 | BY4: =IFERROR(__xludf.DUMMYFUNCTION("""COMPUTED_VALUE"""),"00 | 1 | Cost 0 ⧈ | Next 100 ⧈") -> 00 | 1 | Cost 0 ⧈ | Next 100 ⧈ | BZ4: =IFERROR(__xludf.DUMMYFUNCTION("""COMPUTED_VALUE"""),"Tier 2") -> Tier 2 | CA4: =IFERROR(__xludf.DUMMYFUNCTION("""COMPUTED_VALUE"""),5628.0) -> 5628 | CD4: =IFERROR(__xludf.DUMMYFUNCTION("""COMPUTED_VALUE"""),"Farming Tier") -> Farming Tier | CE4: =IFERROR(__xludf.DUMMYFUNCTION("""COMPUTED_VALUE"""),"Tier 14") -> Tier 14
A5: =IFERROR(__xludf.DUMMYFUNCTION("""COMPUTED_VALUE"""),"Workshop Defense Discount") -> Workshop Defense Discount | B5: =IFERROR(__xludf.DUMMYFUNCTION("""COMPUTED_VALUE"""),28.0) -> 28 | D5: =IFERROR(__xludf.DUMMYFUNCTION("""COMPUTED_VALUE"""),99.0) -> 99 | F5: =IFERROR(__xludf.DUMMYFUNCTION("""COMPUTED_VALUE"""),"Attack Speed") -> Attack Speed | G5: =IFERROR(__xludf.DUMMYFUNCTION("""COMPUTED_VALUE"""),99.0) -> 99 | H5: =IFERROR(__xludf.DUMMYFUNCTION("""COMPUTED_VALUE"""),99.0) -> 99 | I5: =IFERROR(__xludf.DUMMYFUNCTION("""COMPUTED_VALUE"""),99.0) -> 99 | J5: =IFERROR(__xludf.DUMMYFUNCTION("""COMPUTED_VALUE"""),99.0) -> 99 | Q5: =IFERROR(__xludf.DUMMYFUNCTION("""COMPUTED_VALUE"""),99.0) -> 99 | R5: =IFERROR(__xludf.DUMMYFUNCTION("""COMPUTED_VALUE"""),"Rend Armor Mult +") -> Rend Armor Mult + | S5: =IFERROR(__xludf.DUMMYFUNCTION("""COMPUTED_VALUE"""),1.21) -> 1.21 | T5: =IFERROR(__xludf.DUMMYFUNCTION("""COMPUTED_VALUE"""),21.0) -> 21 | U5: =IFERROR(__xludf.DUMMYFUNCTION("""COMPUTED_VALUE"""),21.0) -> 21 | Y5: =IFERROR(__xludf.DUMMYFUNCTION("""COMPUTED_VALUE"""),400.0) -> 400 | Z5: =IFERROR(__xludf.DUMMYFUNCTION("""COMPUTED_VALUE"""),"UW+") -> UW+ | AB5: =IFERROR(__xludf.DUMMYFUNCTION("""COMPUTED_VALUE"""),"Smite") -> Smite | AC5: =IFERROR(__xludf.DUMMYFUNCTION("""COMPUTED_VALUE"""),"Locked") -> Locked | AD5: =IFERROR(__xludf.DUMMYFUNCTION("""COMPUTED_VALUE"""),"Lo | Locked") -> Lo | Locked | AE5: =IFERROR(__xludf.DUMMYFUNCTION("""COMPUTED_VALUE"""),"Health Regen") -> Health Regen | AF5: =IFERROR(__xludf.DUMMYFUNCTION("""COMPUTED_VALUE"""),7.0) -> 7 | AG5: =IFERROR(__xludf.DUMMYFUNCTION("""COMPUTED_VALUE"""),FALSE) -> FALSE | AH5: =IFERROR(__xludf.DUMMYFUNCTION("""COMPUTED_VALUE"""),"Health") -> Health | AI5: =IFERROR(__xludf.DUMMYFUNCTION("""COMPUTED_VALUE"""),"Berserker") -> Berserker | AM5: =IFERROR(__xludf.DUMMYFUNCTION("""COMPUTED_VALUE"""),"Other Relics") -> Other Relics | AN5: =IFERROR(__xludf.DUMMYFUNCTION("""COMPUTED_VALUE"""),22.0) -> 22 | AP5: =IFERROR(__xludf.DUMMYFUNCTION("""COMPUTED_VALUE"""),"Misc.") -> Misc. | AS5: =IFERROR(__xludf.DUMMYFUNCTION("""COMPUTED_VALUE"""),TRUE) -> TRUE | AT5: =IFERROR(__xludf.DUMMYFUNCTION("""COMPUTED_VALUE"""),"Unlocked") -> Unlocked | AU5: =IFERROR(__xludf.DUMMYFUNCTION("""COMPUTED_VALUE"""),"Range") -> Range | AV5: =IFERROR(__xludf.DUMMYFUNCTION("""COMPUTED_VALUE"""),46.0) -> 46 | AW5: =IFERROR(__xludf.DUMMYFUNCTION("""COMPUTED_VALUE"""),"04 | 46m | Cost 220 ⧓ | Next 260 ⧓") -> 04 | 46m | Cost 220 ⧓ | Next 260 ⧓ | BB5: =IFERROR(__xludf.DUMMYFUNCTION("""COMPUTED_VALUE"""),"Substat Cap") -> Substat Cap | BC5: =IFERROR(__xludf.DUMMYFUNCTION("""COMPUTED_VALUE"""),0.01) -> 0.01 | BD5: =IFERROR(__xludf.DUMMYFUNCTION("""COMPUTED_VALUE"""),"00 | 1% | Cost 0 ⧌ | Next 15 ⧌") -> 00 | 1% | Cost 0 ⧌ | Next 15 ⧌ | BG5: =IFERROR(__xludf.DUMMYFUNCTION("""COMPUTED_VALUE"""),"Substat Cap") -> Substat Cap | BH5: =IFERROR(__xludf.DUMMYFUNCTION("""COMPUTED_VALUE"""),0.1) -> 0.1 | BI5: =IFERROR(__xludf.DUMMYFUNCTION("""COMPUTED_VALUE"""),"09 | 10% | Cost 39 ⧌ | Next 42 ⧌") -> 09 | 10% | Cost 39 ⧌ | Next 42 ⧌ | BL5: =IFERROR(__xludf.DUMMYFUNCTION("""COMPUTED_VALUE"""),"Substat Cap") -> Substat Cap | BM5: =IFERROR(__xludf.DUMMYFUNCTION("""COMPUTED_VALUE"""),0.1) -> 0.1 | BN5: =IFERROR(__xludf.DUMMYFUNCTION("""COMPUTED_VALUE"""),"09 | 10% | Cost 39 ⧌ | Next 42 ⧌") -> 09 | 10% | Cost 39 ⧌ | Next 42 ⧌ | BQ5: =IFERROR(__xludf.DUMMYFUNCTION("""COMPUTED_VALUE"""),"Substat Cap") -> Substat Cap | BR5: =IFERROR(__xludf.DUMMYFUNCTION("""COMPUTED_VALUE"""),0.1) -> 0.1 | BS5: =IFERROR(__xludf.DUMMYFUNCTION("""COMPUTED_VALUE"""),"09 | 10% | Cost 39 ⧌ | Next 42 ⧌") -> 09 | 10% | Cost 39 ⧌ | Next 42 ⧌ | BU5: =IFERROR(__xludf.DUMMYFUNCTION("""COMPUTED_VALUE"""),"Ally") -> Ally | BW5: =IFERROR(__xludf.DUMMYFUNCTION("""COMPUTED_VALUE"""),"Recovery Amount") -> Recovery Amount | BX5: =IFERROR(__xludf.DUMMYFUNCTION("""COMPUTED_VALUE"""),0.01) -> 0.01 | BY5: =IFERROR(__xludf.DUMMYFUNCTION("""COMPUTED_VALUE"""),"00 | 1% | Cost 0 ⧈ | Next 10 ⧈") -> 00 | 1% | Cost 0 ⧈ | Next 10 ⧈ | BZ5: =IFERROR(__xludf.DUMMYFUNCTION("""COMPUTED_VALUE"""),"Tier 3") -> Tier 3 | CA5: =IFERROR(__xludf.DUMMYFUNCTION("""COMPUTED_VALUE"""),5402.0) -> 5402 | CD5: =IFERROR(__xludf.DUMMYFUNCTION("""COMPUTED_VALUE"""),"Tourney League") -> Tourney League | CE5: =IFERROR(__xludf.DUMMYFUNCTION("""COMPUTED_VALUE"""),"Legends") -> Legends
A6: =IFERROR(__xludf.DUMMYFUNCTION("""COMPUTED_VALUE"""),"Workshop Utility Discount") -> Workshop Utility Discount | B6: =IFERROR(__xludf.DUMMYFUNCTION("""COMPUTED_VALUE"""),41.0) -> 41 | D6: =IFERROR(__xludf.DUMMYFUNCTION("""COMPUTED_VALUE"""),99.0) -> 99 | F6: =IFERROR(__xludf.DUMMYFUNCTION("""COMPUTED_VALUE"""),"Critical Chance") -> Critical Chance | G6: =IFERROR(__xludf.DUMMYFUNCTION("""COMPUTED_VALUE"""),79.0) -> 79 | H6: =IFERROR(__xludf.DUMMYFUNCTION("""COMPUTED_VALUE"""),79.0) -> 79 | I6: =IFERROR(__xludf.DUMMYFUNCTION("""COMPUTED_VALUE"""),79.0) -> 79 | J6: =IFERROR(__xludf.DUMMYFUNCTION("""COMPUTED_VALUE"""),79.0) -> 79 | Q6: =IFERROR(__xludf.DUMMYFUNCTION("""COMPUTED_VALUE"""),79.0) -> 79 | R6: =IFERROR(__xludf.DUMMYFUNCTION("""COMPUTED_VALUE"""),"Critical Factor +") -> Critical Factor + | S6: =IFERROR(__xludf.DUMMYFUNCTION("""COMPUTED_VALUE"""),1.6) -> 1.6 | T6: =IFERROR(__xludf.DUMMYFUNCTION("""COMPUTED_VALUE"""),60.0) -> 60 | U6: =IFERROR(__xludf.DUMMYFUNCTION("""COMPUTED_VALUE"""),60.0) -> 60 | Y6: =IFERROR(__xludf.DUMMYFUNCTION("""COMPUTED_VALUE"""),400.0) -> 400 | Z6: =IFERROR(__xludf.DUMMYFUNCTION("""COMPUTED_VALUE"""),"Smart Missiles") -> Smart Missiles | AB6: =IFERROR(__xludf.DUMMYFUNCTION("""COMPUTED_VALUE"""),"Damage") -> Damage | AC6: =IFERROR(__xludf.DUMMYFUNCTION("""COMPUTED_VALUE"""),10.0) -> 10 | AD6: =IFERROR(__xludf.DUMMYFUNCTION("""COMPUTED_VALUE"""),"00 | x10 | Cost 0 ⧌ | Next 5 ⧌") -> 00 | x10 | Cost 0 ⧌ | Next 5 ⧌ | AE6: =IFERROR(__xludf.DUMMYFUNCTION("""COMPUTED_VALUE"""),"Range") -> Range | AF6: =IFERROR(__xludf.DUMMYFUNCTION("""COMPUTED_VALUE"""),7.0) -> 7 | AG6: =IFERROR(__xludf.DUMMYFUNCTION("""COMPUTED_VALUE"""),FALSE) -> FALSE | AH6: =IFERROR(__xludf.DUMMYFUNCTION("""COMPUTED_VALUE"""),"Coins") -> Coins | AI6: =IFERROR(__xludf.DUMMYFUNCTION("""COMPUTED_VALUE"""),"Critical Chance") -> Critical Chance | AM6: =IFERROR(__xludf.DUMMYFUNCTION("""COMPUTED_VALUE"""),"Total Relics") -> Total Relics | AN6: =IFERROR(__xludf.DUMMYFUNCTION("""COMPUTED_VALUE"""),147.0) -> 147 | AP6: =IFERROR(__xludf.DUMMYFUNCTION("""COMPUTED_VALUE"""),"Bot Range") -> Bot Range | AQ6: =IFERROR(__xludf.DUMMYFUNCTION("""COMPUTED_VALUE"""),0.0) -> 0 | AS6: =IFERROR(__xludf.DUMMYFUNCTION("""COMPUTED_VALUE"""),"Thunder Bot") -> Thunder Bot | AU6: =IFERROR(__xludf.DUMMYFUNCTION("""COMPUTED_VALUE"""),"Duration") -> Duration | AV6: =IFERROR(__xludf.DUMMYFUNCTION("""COMPUTED_VALUE"""),5.0) -> 5 | AW6: =IFERROR(__xludf.DUMMYFUNCTION("""COMPUTED_VALUE"""),"00 | 5.0s | Cost 0 ⧓ | Next 100 ⧓") -> 00 | 5.0s | Cost 0 ⧓ | Next 100 ⧓ | BE6: =IFERROR(__xludf.DUMMYFUNCTION("""COMPUTED_VALUE"""),0.4444444444444444) -> 0.44444444 | BW6: =IFERROR(__xludf.DUMMYFUNCTION("""COMPUTED_VALUE"""),"Max Recovery") -> Max Recovery | BX6: =IFERROR(__xludf.DUMMYFUNCTION("""COMPUTED_VALUE"""),1.1) -> 1.1 | BY6: =IFERROR(__xludf.DUMMYFUNCTION("""COMPUTED_VALUE"""),"00 | 1.1x | Cost 0 ⧈ | Next 1 ⧈") -> 00 | 1.1x | Cost 0 ⧈ | Next 1 ⧈ | BZ6: =IFERROR(__xludf.DUMMYFUNCTION("""COMPUTED_VALUE"""),"Tier 4") -> Tier 4 | CA6: =IFERROR(__xludf.DUMMYFUNCTION("""COMPUTED_VALUE"""),6310.0) -> 6310 | CB6: =IFERROR(__xludf.DUMMYFUNCTION("""COMPUTED_VALUE"""),TRUE) -> TRUE | CD6: =IFERROR(__xludf.DUMMYFUNCTION("""COMPUTED_VALUE"""),"Lifetime Coins") -> Lifetime Coins | CE6: =IFERROR(__xludf.DUMMYFUNCTION("""COMPUTED_VALUE"""),3.57E12) -> 3570000000000
A7: =IFERROR(__xludf.DUMMYFUNCTION("""COMPUTED_VALUE"""),"Labs Coin Discount") -> Labs Coin Discount | B7: =IFERROR(__xludf.DUMMYFUNCTION("""COMPUTED_VALUE"""),68.0) -> 68 | D7: =IFERROR(__xludf.DUMMYFUNCTION("""COMPUTED_VALUE"""),99.0) -> 99 | F7: =IFERROR(__xludf.DUMMYFUNCTION("""COMPUTED_VALUE"""),"Critical Factor") -> Critical Factor | G7: =IFERROR(__xludf.DUMMYFUNCTION("""COMPUTED_VALUE"""),150.0) -> 150 | H7: =IFERROR(__xludf.DUMMYFUNCTION("""COMPUTED_VALUE"""),150.0) -> 150 | I7: =IFERROR(__xludf.DUMMYFUNCTION("""COMPUTED_VALUE"""),150.0) -> 150 | J7: =IFERROR(__xludf.DUMMYFUNCTION("""COMPUTED_VALUE"""),150.0) -> 150 | Q7: =IFERROR(__xludf.DUMMYFUNCTION("""COMPUTED_VALUE"""),150.0) -> 150 | R7: =IFERROR(__xludf.DUMMYFUNCTION("""COMPUTED_VALUE"""),"Damage / Meter +") -> Damage / Meter + | S7: =IFERROR(__xludf.DUMMYFUNCTION("""COMPUTED_VALUE"""),1.17) -> 1.17 | T7: =IFERROR(__xludf.DUMMYFUNCTION("""COMPUTED_VALUE"""),17.0) -> 17 | U7: =IFERROR(__xludf.DUMMYFUNCTION("""COMPUTED_VALUE"""),17.0) -> 17 | Y7: =IFERROR(__xludf.DUMMYFUNCTION("""COMPUTED_VALUE"""),400.0) -> 400 | AB7: =IFERROR(__xludf.DUMMYFUNCTION("""COMPUTED_VALUE"""),"Quantity") -> Quantity | AC7: =IFERROR(__xludf.DUMMYFUNCTION("""COMPUTED_VALUE"""),5.0) -> 5 | AD7: =IFERROR(__xludf.DUMMYFUNCTION("""COMPUTED_VALUE"""),"00 | #5 | Cost 0 ⧌ | Next 4 ⧌") -> 00 | #5 | Cost 0 ⧌ | Next 4 ⧌ | AE7: =IFERROR(__xludf.DUMMYFUNCTION("""COMPUTED_VALUE"""),"Cash") -> Cash | AF7: =IFERROR(__xludf.DUMMYFUNCTION("""COMPUTED_VALUE"""),7.0) -> 7 | AG7: =IFERROR(__xludf.DUMMYFUNCTION("""COMPUTED_VALUE"""),TRUE) -> TRUE | AH7: =IFERROR(__xludf.DUMMYFUNCTION("""COMPUTED_VALUE"""),"Plasma Cannon") -> Plasma Cannon | AI7: =IFERROR(__xludf.DUMMYFUNCTION("""COMPUTED_VALUE"""),"Health") -> Health | AP7: =IFERROR(__xludf.DUMMYFUNCTION("""COMPUTED_VALUE"""),"Discount Enhancements") -> Discount Enhancements | AQ7: =IFERROR(__xludf.DUMMYFUNCTION("""COMPUTED_VALUE"""),0.0) -> 0 | AU7: =IFERROR(__xludf.DUMMYFUNCTION("""COMPUTED_VALUE"""),"Cooldown") -> Cooldown | AV7: =IFERROR(__xludf.DUMMYFUNCTION("""COMPUTED_VALUE"""),120.0) -> 120 | AW7: =IFERROR(__xludf.DUMMYFUNCTION("""COMPUTED_VALUE"""),"00 | 120s | Cost 0 ⧓ | Next 100 ⧓") -> 00 | 120s | Cost 0 ⧓ | Next 100 ⧓ | BB7: =IFERROR(__xludf.DUMMYFUNCTION("""COMPUTED_VALUE"""),"Farming") -> Farming | BG7: =IFERROR(__xludf.DUMMYFUNCTION("""COMPUTED_VALUE"""),"Farming") -> Farming | BL7: =IFERROR(__xludf.DUMMYFUNCTION("""COMPUTED_VALUE"""),"Farming") -> Farming | BQ7: =IFERROR(__xludf.DUMMYFUNCTION("""COMPUTED_VALUE"""),"Farming") -> Farming | BU7: =IFERROR(__xludf.DUMMYFUNCTION("""COMPUTED_VALUE"""),TRUE) -> TRUE | BV7: =IFERROR(__xludf.DUMMYFUNCTION("""COMPUTED_VALUE"""),"Unlocked") -> Unlocked | BW7: =IFERROR(__xludf.DUMMYFUNCTION("""COMPUTED_VALUE"""),"Cooldown") -> Cooldown | BX7: =IFERROR(__xludf.DUMMYFUNCTION("""COMPUTED_VALUE"""),120.0) -> 120 | BY7: =IFERROR(__xludf.DUMMYFUNCTION("""COMPUTED_VALUE"""),"00 | 120s | Cost 0 ⧈ | Next 1 ⧈") -> 00 | 120s | Cost 0 ⧈ | Next 1 ⧈ | BZ7: =IFERROR(__xludf.DUMMYFUNCTION("""COMPUTED_VALUE"""),"Tier 5") -> Tier 5 | CA7: =IFERROR(__xludf.DUMMYFUNCTION("""COMPUTED_VALUE"""),7593.0) -> 7593 | CD7: =IFERROR(__xludf.DUMMYFUNCTION("""COMPUTED_VALUE"""),"Stones") -> Stones | CE7: =IFERROR(__xludf.DUMMYFUNCTION("""COMPUTED_VALUE"""),200.0) -> 200
A8: =IFERROR(__xludf.DUMMYFUNCTION("""COMPUTED_VALUE"""),"Labs Speed") -> Labs Speed | B8: =IFERROR(__xludf.DUMMYFUNCTION("""COMPUTED_VALUE"""),91.0) -> 91 | D8: =IFERROR(__xludf.DUMMYFUNCTION("""COMPUTED_VALUE"""),99.0) -> 99 | E8: =IFERROR(__xludf.DUMMYFUNCTION("""COMPUTED_VALUE"""),TRUE) -> TRUE | F8: =IFERROR(__xludf.DUMMYFUNCTION("""COMPUTED_VALUE"""),"Range") -> Range | G8: =IFERROR(__xludf.DUMMYFUNCTION("""COMPUTED_VALUE"""),79.0) -> 79 | H8: =IFERROR(__xludf.DUMMYFUNCTION("""COMPUTED_VALUE"""),79.0) -> 79 | I8: =IFERROR(__xludf.DUMMYFUNCTION("""COMPUTED_VALUE"""),79.0) -> 79 | J8: =IFERROR(__xludf.DUMMYFUNCTION("""COMPUTED_VALUE"""),79.0) -> 79 | Q8: =IFERROR(__xludf.DUMMYFUNCTION("""COMPUTED_VALUE"""),79.0) -> 79 | R8: =IFERROR(__xludf.DUMMYFUNCTION("""COMPUTED_VALUE"""),"Super Crit Multi +") -> Super Crit Multi + | S8: =IFERROR(__xludf.DUMMYFUNCTION("""COMPUTED_VALUE"""),1.57) -> 1.57 | T8: =IFERROR(__xludf.DUMMYFUNCTION("""COMPUTED_VALUE"""),57.0) -> 57 | U8: =IFERROR(__xludf.DUMMYFUNCTION("""COMPUTED_VALUE"""),57.0) -> 57 | Y8: =IFERROR(__xludf.DUMMYFUNCTION("""COMPUTED_VALUE"""),400.0) -> 400 | Z8: =IFERROR(__xludf.DUMMYFUNCTION("""COMPUTED_VALUE"""),FALSE) -> FALSE | AA8: =IFERROR(__xludf.DUMMYFUNCTION("""COMPUTED_VALUE"""),"UW Locked") -> UW Locked | AB8: =IFERROR(__xludf.DUMMYFUNCTION("""COMPUTED_VALUE"""),"Cooldown") -> Cooldown | AC8: =IFERROR(__xludf.DUMMYFUNCTION("""COMPUTED_VALUE"""),180.0) -> 180 | AD8: =IFERROR(__xludf.DUMMYFUNCTION("""COMPUTED_VALUE"""),"00 | 180s | Cost 0 ⧌ | Next 8 ⧌") -> 00 | 180s | Cost 0 ⧌ | Next 8 ⧌ | AE8: =IFERROR(__xludf.DUMMYFUNCTION("""COMPUTED_VALUE"""),"Coins") -> Coins | AF8: =IFERROR(__xludf.DUMMYFUNCTION("""COMPUTED_VALUE"""),7.0) -> 7 | AG8: =IFERROR(__xludf.DUMMYFUNCTION("""COMPUTED_VALUE"""),FALSE) -> FALSE | AH8: =IFERROR(__xludf.DUMMYFUNCTION("""COMPUTED_VALUE"""),"Attack Speed") -> Attack Speed | AI8: =IFERROR(__xludf.DUMMYFUNCTION("""COMPUTED_VALUE"""),"Health Regen") -> Health Regen | AM8: =IFERROR(__xludf.DUMMYFUNCTION("""COMPUTED_VALUE"""),"Total Bonuses") -> Total Bonuses | AN8: =IFERROR(__xludf.DUMMYFUNCTION("""COMPUTED_VALUE"""),"Active") -> Active | AP8: =IFERROR(__xludf.DUMMYFUNCTION("""COMPUTED_VALUE"""),"Discount Rerolls") -> Discount Rerolls | AQ8: =IFERROR(__xludf.DUMMYFUNCTION("""COMPUTED_VALUE"""),0.0) -> 0 | AU8: =IFERROR(__xludf.DUMMYFUNCTION("""COMPUTED_VALUE"""),"Linger") -> Linger | AV8: =IFERROR(__xludf.DUMMYFUNCTION("""COMPUTED_VALUE"""),0.2) -> 0.2 | AW8: =IFERROR(__xludf.DUMMYFUNCTION("""COMPUTED_VALUE"""),"00 | 20% | Cost 0 ⧓ | Next 100 ⧓") -> 00 | 20% | Cost 0 ⧓ | Next 100 ⧓ | BB8: =IFERROR(__xludf.DUMMYFUNCTION("""COMPUTED_VALUE"""),"Primary Slot") -> Primary Slot | BC8: =IFERROR(__xludf.DUMMYFUNCTION("""COMPUTED_VALUE"""),"Amplifying Strike") -> Amplifying Strike | BG8: =IFERROR(__xludf.DUMMYFUNCTION("""COMPUTED_VALUE"""),"Primary Slot") -> Primary Slot | BH8: =IFERROR(__xludf.DUMMYFUNCTION("""COMPUTED_VALUE"""),"Sharp Fortitude") -> Sharp Fortitude | BL8: =IFERROR(__xludf.DUMMYFUNCTION("""COMPUTED_VALUE"""),"Primary Slot") -> Primary Slot | BM8: =IFERROR(__xludf.DUMMYFUNCTION("""COMPUTED_VALUE"""),"Singularity Harness") -> Singularity Harness | BQ8: =IFERROR(__xludf.DUMMYFUNCTION("""COMPUTED_VALUE"""),"Primary Slot") -> Primary Slot | BR8: =IFERROR(__xludf.DUMMYFUNCTION("""COMPUTED_VALUE"""),"Primordial Collapse") -> Primordial Collapse | BU8: =IFERROR(__xludf.DUMMYFUNCTION("""COMPUTED_VALUE"""),"Bounty") -> Bounty | BW8: =IFERROR(__xludf.DUMMYFUNCTION("""COMPUTED_VALUE"""),"Multiplier") -> Multiplier | BX8: =IFERROR(__xludf.DUMMYFUNCTION("""COMPUTED_VALUE"""),0.01) -> 0.01 | BY8: =IFERROR(__xludf.DUMMYFUNCTION("""COMPUTED_VALUE"""),"00 | 0.01x | Cost 0 ⧈ | Next 1 ⧈") -> 00 | 0.01x | Cost 0 ⧈ | Next 1 ⧈ | BZ8: =IFERROR(__xludf.DUMMYFUNCTION("""COMPUTED_VALUE"""),"Tier 6") -> Tier 6 | CA8: =IFERROR(__xludf.DUMMYFUNCTION("""COMPUTED_VALUE"""),8252.0) -> 8252 | CD8: =IFERROR(__xludf.DUMMYFUNCTION("""COMPUTED_VALUE"""),"Gems") -> Gems | CE8: =IFERROR(__xludf.DUMMYFUNCTION("""COMPUTED_VALUE"""),326.0) -> 326
A9: =IFERROR(__xludf.DUMMYFUNCTION("""COMPUTED_VALUE"""),"Buy Multiplier") -> Buy Multiplier | B9: =IFERROR(__xludf.DUMMYFUNCTION("""COMPUTED_VALUE"""),4.0) -> 4 | D9: =IFERROR(__xludf.DUMMYFUNCTION("""COMPUTED_VALUE"""),4.0) -> 4 | F9: =IFERROR(__xludf.DUMMYFUNCTION("""COMPUTED_VALUE"""),"Damage / Meter") -> Damage / Meter | G9: =IFERROR(__xludf.DUMMYFUNCTION("""COMPUTED_VALUE"""),180.0) -> 180 | H9: =IFERROR(__xludf.DUMMYFUNCTION("""COMPUTED_VALUE"""),200.0) -> 200 | I9: =IFERROR(__xludf.DUMMYFUNCTION("""COMPUTED_VALUE"""),180.0) -> 180 | J9: =IFERROR(__xludf.DUMMYFUNCTION("""COMPUTED_VALUE"""),200.0) -> 200 | Q9: =IFERROR(__xludf.DUMMYFUNCTION("""COMPUTED_VALUE"""),200.0) -> 200 | R9: =IFERROR(__xludf.DUMMYFUNCTION("""COMPUTED_VALUE"""),"Attack Speed +") -> Attack Speed + | S9: =IFERROR(__xludf.DUMMYFUNCTION("""COMPUTED_VALUE"""),1.13) -> 1.13 | T9: =IFERROR(__xludf.DUMMYFUNCTION("""COMPUTED_VALUE"""),13.0) -> 13 | U9: =IFERROR(__xludf.DUMMYFUNCTION("""COMPUTED_VALUE"""),13.0) -> 13 | Y9: =IFERROR(__xludf.DUMMYFUNCTION("""COMPUTED_VALUE"""),75.0) -> 75 | Z9: =IFERROR(__xludf.DUMMYFUNCTION("""COMPUTED_VALUE"""),"UW+") -> UW+ | AB9: =IFERROR(__xludf.DUMMYFUNCTION("""COMPUTED_VALUE"""),"Cover Fire") -> Cover Fire | AC9: =IFERROR(__xludf.DUMMYFUNCTION("""COMPUTED_VALUE"""),"Locked") -> Locked | AD9: =IFERROR(__xludf.DUMMYFUNCTION("""COMPUTED_VALUE"""),"Lo | Locked") -> Lo | Locked | AE9: =IFERROR(__xludf.DUMMYFUNCTION("""COMPUTED_VALUE"""),"Slow Aura") -> Slow Aura | AF9: =IFERROR(__xludf.DUMMYFUNCTION("""COMPUTED_VALUE"""),7.0) -> 7 | AG9: =IFERROR(__xludf.DUMMYFUNCTION("""COMPUTED_VALUE"""),FALSE) -> FALSE | AH9: =IFERROR(__xludf.DUMMYFUNCTION("""COMPUTED_VALUE"""),"Wave Skip") -> Wave Skip | AI9: =IFERROR(__xludf.DUMMYFUNCTION("""COMPUTED_VALUE"""),"Plasma Cannon") -> Plasma Cannon | AM9: =IFERROR(__xludf.DUMMYFUNCTION("""COMPUTED_VALUE"""),"Misc.") -> Misc. | AP9: =IFERROR(__xludf.DUMMYFUNCTION("""COMPUTED_VALUE"""),"Additional Card Slot") -> Additional Card Slot | AQ9: =IFERROR(__xludf.DUMMYFUNCTION("""COMPUTED_VALUE"""),0.0) -> 0 | AS9: =IFERROR(__xludf.DUMMYFUNCTION("""COMPUTED_VALUE"""),FALSE) -> FALSE | AT9: =IFERROR(__xludf.DUMMYFUNCTION("""COMPUTED_VALUE"""),"Locked") -> Locked | AU9: =IFERROR(__xludf.DUMMYFUNCTION("""COMPUTED_VALUE"""),"Range") -> Range | AV9: =IFERROR(__xludf.DUMMYFUNCTION("""COMPUTED_VALUE"""),25.0) -> 25 | AW9: =IFERROR(__xludf.DUMMYFUNCTION("""COMPUTED_VALUE"""),"00 | 25m | Cost 0 ⧓ | Next 100 ⧓") -> 00 | 25m | Cost 0 ⧓ | Next 100 ⧓ | BB9: =IFERROR(__xludf.DUMMYFUNCTION("""COMPUTED_VALUE"""),"Assist Slot") -> Assist Slot | BG9: =IFERROR(__xludf.DUMMYFUNCTION("""COMPUTED_VALUE"""),"Assist Slot") -> Assist Slot | BH9: =IFERROR(__xludf.DUMMYFUNCTION("""COMPUTED_VALUE"""),"Orbital Augment") -> Orbital Augment | BL9: =IFERROR(__xludf.DUMMYFUNCTION("""COMPUTED_VALUE"""),"Assist Slot") -> Assist Slot | BM9: =IFERROR(__xludf.DUMMYFUNCTION("""COMPUTED_VALUE"""),"Pulsar Harvester") -> Pulsar Harvester | BQ9: =IFERROR(__xludf.DUMMYFUNCTION("""COMPUTED_VALUE"""),"Assist Slot") -> Assist Slot | BR9: =IFERROR(__xludf.DUMMYFUNCTION("""COMPUTED_VALUE"""),"Dimension Core") -> Dimension Core | BW9: =IFERROR(__xludf.DUMMYFUNCTION("""COMPUTED_VALUE"""),"Cooldown") -> Cooldown | BX9: =IFERROR(__xludf.DUMMYFUNCTION("""COMPUTED_VALUE"""),120.0) -> 120 | BY9: =IFERROR(__xludf.DUMMYFUNCTION("""COMPUTED_VALUE"""),"00 | 120s | Cost 0 ⧈ | Next 2 ⧈") -> 00 | 120s | Cost 0 ⧈ | Next 2 ⧈ | BZ9: =IFERROR(__xludf.DUMMYFUNCTION("""COMPUTED_VALUE"""),"Tier 7") -> Tier 7 | CA9: =IFERROR(__xludf.DUMMYFUNCTION("""COMPUTED_VALUE"""),7854.0) -> 7854 | CB9: =IFERROR(__xludf.DUMMYFUNCTION("""COMPUTED_VALUE"""),TRUE) -> TRUE
A10: =IFERROR(__xludf.DUMMYFUNCTION("""COMPUTED_VALUE"""),"More Round Stats") -> More Round Stats | B10: =IFERROR(__xludf.DUMMYFUNCTION("""COMPUTED_VALUE"""),1.0) -> 1 | D10: =IFERROR(__xludf.DUMMYFUNCTION("""COMPUTED_VALUE"""),1.0) -> 1 | E10: =IFERROR(__xludf.DUMMYFUNCTION("""COMPUTED_VALUE"""),TRUE) -> TRUE | F10: =IFERROR(__xludf.DUMMYFUNCTION("""COMPUTED_VALUE"""),"Multishot Chance") -> Multishot Chance | G10: =IFERROR(__xludf.DUMMYFUNCTION("""COMPUTED_VALUE"""),99.0) -> 99 | H10: =IFERROR(__xludf.DUMMYFUNCTION("""COMPUTED_VALUE"""),99.0) -> 99 | I10: =IFERROR(__xludf.DUMMYFUNCTION("""COMPUTED_VALUE"""),99.0) -> 99 | J10: =IFERROR(__xludf.DUMMYFUNCTION("""COMPUTED_VALUE"""),99.0) -> 99 | Q10: =IFERROR(__xludf.DUMMYFUNCTION("""COMPUTED_VALUE"""),99.0) -> 99 | R10: =IFERROR(__xludf.DUMMYFUNCTION("""COMPUTED_VALUE"""),"Health +") -> Health + | S10: =IFERROR(__xludf.DUMMYFUNCTION("""COMPUTED_VALUE"""),1.62) -> 1.62 | T10: =IFERROR(__xludf.DUMMYFUNCTION("""COMPUTED_VALUE"""),62.0) -> 62 | U10: =IFERROR(__xludf.DUMMYFUNCTION("""COMPUTED_VALUE"""),62.0) -> 62 | Y10: =IFERROR(__xludf.DUMMYFUNCTION("""COMPUTED_VALUE"""),400.0) -> 400 | Z10: =IFERROR(__xludf.DUMMYFUNCTION("""COMPUTED_VALUE"""),"Death Wave") -> Death Wave | AB10: =IFERROR(__xludf.DUMMYFUNCTION("""COMPUTED_VALUE"""),"Damage") -> Damage | AC10: =IFERROR(__xludf.DUMMYFUNCTION("""COMPUTED_VALUE"""),63.0) -> 63 | AD10: =IFERROR(__xludf.DUMMYFUNCTION("""COMPUTED_VALUE"""),"08 | x63 | Cost 47 ⧌ | Next 53 ⧌") -> 08 | x63 | Cost 47 ⧌ | Next 53 ⧌ | AE10: =IFERROR(__xludf.DUMMYFUNCTION("""COMPUTED_VALUE"""),"Critical Chance") -> Critical Chance | AF10: =IFERROR(__xludf.DUMMYFUNCTION("""COMPUTED_VALUE"""),7.0) -> 7 | AG10: =IFERROR(__xludf.DUMMYFUNCTION("""COMPUTED_VALUE"""),FALSE) -> FALSE | AH10: =IFERROR(__xludf.DUMMYFUNCTION("""COMPUTED_VALUE"""),"Health Regen") -> Health Regen | AI10: =IFERROR(__xludf.DUMMYFUNCTION("""COMPUTED_VALUE"""),"Wave Skip") -> Wave Skip | AM10: =IFERROR(__xludf.DUMMYFUNCTION("""COMPUTED_VALUE"""),"Lab Speed") -> Lab Speed | AN10: =IFERROR(__xludf.DUMMYFUNCTION("""COMPUTED_VALUE"""),0.395) -> 0.395 | AP10: =IFERROR(__xludf.DUMMYFUNCTION("""COMPUTED_VALUE"""),"Workshop Respec Discount") -> Workshop Respec Discount | AQ10: =IFERROR(__xludf.DUMMYFUNCTION("""COMPUTED_VALUE"""),0.0) -> 0 | AS10: =IFERROR(__xludf.DUMMYFUNCTION("""COMPUTED_VALUE"""),"Golden Bot") -> Golden Bot | AU10: =IFERROR(__xludf.DUMMYFUNCTION("""COMPUTED_VALUE"""),"Duration") -> Duration | AV10: =IFERROR(__xludf.DUMMYFUNCTION("""COMPUTED_VALUE"""),26.0) -> 26 | AW10: =IFERROR(__xludf.DUMMYFUNCTION("""COMPUTED_VALUE"""),"12 | 26.0s | Cost 540 ⧓ | Next 580 ⧓") -> 12 | 26.0s | Cost 540 ⧓ | Next 580 ⧓ | BU10: =IFERROR(__xludf.DUMMYFUNCTION("""COMPUTED_VALUE"""),FALSE) -> FALSE | BV10: =IFERROR(__xludf.DUMMYFUNCTION("""COMPUTED_VALUE"""),"Locked") -> Locked | BW10: =IFERROR(__xludf.DUMMYFUNCTION("""COMPUTED_VALUE"""),"Targets") -> Targets | BX10: =IFERROR(__xludf.DUMMYFUNCTION("""COMPUTED_VALUE"""),1.0) -> 1 | BY10: =IFERROR(__xludf.DUMMYFUNCTION("""COMPUTED_VALUE"""),"00 | 1 | Cost 0 ⧈ | Next 100 ⧈") -> 00 | 1 | Cost 0 ⧈ | Next 100 ⧈ | BZ10: =IFERROR(__xludf.DUMMYFUNCTION("""COMPUTED_VALUE"""),"Tier 8") -> Tier 8 | CA10: =IFERROR(__xludf.DUMMYFUNCTION("""COMPUTED_VALUE"""),8119.0) -> 8119 | CD10: =IFERROR(__xludf.DUMMYFUNCTION("""COMPUTED_VALUE"""),"Premium Packs") -> Premium Packs | CE10: =IFERROR(__xludf.DUMMYFUNCTION("""COMPUTED_VALUE"""),"Unlocked") -> Unlocked
A11: =IFERROR(__xludf.DUMMYFUNCTION("""COMPUTED_VALUE"""),"Target Priority") -> Target Priority | B11: =IFERROR(__xludf.DUMMYFUNCTION("""COMPUTED_VALUE"""),2.0) -> 2 | D11: =IFERROR(__xludf.DUMMYFUNCTION("""COMPUTED_VALUE"""),2.0) -> 2 | F11: =IFERROR(__xludf.DUMMYFUNCTION("""COMPUTED_VALUE"""),"Multishot Targets") -> Multishot Targets | G11: =IFERROR(__xludf.DUMMYFUNCTION("""COMPUTED_VALUE"""),7.0) -> 7 | H11: =IFERROR(__xludf.DUMMYFUNCTION("""COMPUTED_VALUE"""),7.0) -> 7 | I11: =IFERROR(__xludf.DUMMYFUNCTION("""COMPUTED_VALUE"""),7.0) -> 7 | J11: =IFERROR(__xludf.DUMMYFUNCTION("""COMPUTED_VALUE"""),7.0) -> 7 | Q11: =IFERROR(__xludf.DUMMYFUNCTION("""COMPUTED_VALUE"""),7.0) -> 7 | R11: =IFERROR(__xludf.DUMMYFUNCTION("""COMPUTED_VALUE"""),"Health Regen +") -> Health Regen + | S11: =IFERROR(__xludf.DUMMYFUNCTION("""COMPUTED_VALUE"""),1.6) -> 1.6 | T11: =IFERROR(__xludf.DUMMYFUNCTION("""COMPUTED_VALUE"""),60.0) -> 60 | U11: =IFERROR(__xludf.DUMMYFUNCTION("""COMPUTED_VALUE"""),60.0) -> 60 | Y11: =IFERROR(__xludf.DUMMYFUNCTION("""COMPUTED_VALUE"""),400.0) -> 400 | AB11: =IFERROR(__xludf.DUMMYFUNCTION("""COMPUTED_VALUE"""),"Quantity") -> Quantity | AC11: =IFERROR(__xludf.DUMMYFUNCTION("""COMPUTED_VALUE"""),3.0) -> 3 | AD11: =IFERROR(__xludf.DUMMYFUNCTION("""COMPUTED_VALUE"""),"02 | #3 | Cost 500 ⧌ | Next 850 ⧌") -> 02 | #3 | Cost 500 ⧌ | Next 850 ⧌ | AE11: =IFERROR(__xludf.DUMMYFUNCTION("""COMPUTED_VALUE"""),"Enemy Balance") -> Enemy Balance | AF11: =IFERROR(__xludf.DUMMYFUNCTION("""COMPUTED_VALUE"""),7.0) -> 7 | AG11: =IFERROR(__xludf.DUMMYFUNCTION("""COMPUTED_VALUE"""),FALSE) -> FALSE | AH11: =IFERROR(__xludf.DUMMYFUNCTION("""COMPUTED_VALUE"""),"Wave Accelerator") -> Wave Accelerator | AI11: =IFERROR(__xludf.DUMMYFUNCTION("""COMPUTED_VALUE"""),"Energy Shield") -> Energy Shield | AM11: =IFERROR(__xludf.DUMMYFUNCTION("""COMPUTED_VALUE"""),"Bot Range") -> Bot Range | AN11: =IFERROR(__xludf.DUMMYFUNCTION("""COMPUTED_VALUE"""),9.0) -> 9 | AP11: =IFERROR(__xludf.DUMMYFUNCTION("""COMPUTED_VALUE"""),"Bot Respec Discount") -> Bot Respec Discount | AQ11: =IFERROR(__xludf.DUMMYFUNCTION("""COMPUTED_VALUE"""),0.0) -> 0 | AU11: =IFERROR(__xludf.DUMMYFUNCTION("""COMPUTED_VALUE"""),"Cooldown") -> Cooldown | AV11: =IFERROR(__xludf.DUMMYFUNCTION("""COMPUTED_VALUE"""),111.0) -> 111 | AW11: =IFERROR(__xludf.DUMMYFUNCTION("""COMPUTED_VALUE"""),"03 | 111s | Cost 180 ⧓ | Next 220 ⧓") -> 03 | 111s | Cost 180 ⧓ | Next 220 ⧓ | BB11: =IFERROR(__xludf.DUMMYFUNCTION("""COMPUTED_VALUE"""),"Tourney") -> Tourney | BG11: =IFERROR(__xludf.DUMMYFUNCTION("""COMPUTED_VALUE"""),"Tourney") -> Tourney | BL11: =IFERROR(__xludf.DUMMYFUNCTION("""COMPUTED_VALUE"""),"Tourney") -> Tourney | BQ11: =IFERROR(__xludf.DUMMYFUNCTION("""COMPUTED_VALUE"""),"Tourney") -> Tourney | BU11: =IFERROR(__xludf.DUMMYFUNCTION("""COMPUTED_VALUE"""),"Fetch") -> Fetch | BW11: =IFERROR(__xludf.DUMMYFUNCTION("""COMPUTED_VALUE"""),"Cooldown") -> Cooldown | BX11: =IFERROR(__xludf.DUMMYFUNCTION("""COMPUTED_VALUE"""),88.0) -> 88 | BY11: =IFERROR(__xludf.DUMMYFUNCTION("""COMPUTED_VALUE"""),"32 | 88.0s | Cost 64 ⧈ | Next 66 ⧈") -> 32 | 88.0s | Cost 64 ⧈ | Next 66 ⧈ | BZ11: =IFERROR(__xludf.DUMMYFUNCTION("""COMPUTED_VALUE"""),"Tier 9") -> Tier 9 | CA11: =IFERROR(__xludf.DUMMYFUNCTION("""COMPUTED_VALUE"""),6985.0) -> 6985 | CD11: =IFERROR(__xludf.DUMMYFUNCTION("""COMPUTED_VALUE"""),"Disable Ads") -> Disable Ads | CE11: =IFERROR(__xludf.DUMMYFUNCTION("""COMPUTED_VALUE"""),TRUE) -> TRUE
