Workbook
Name LC_LabTargets_Array: 'Lab Calculator'!$P$3:$P$177
Name LC_HideOption: 'Lab Calculator'!$E$1
Name LC_LabNamesOrder_Array: 'Lab Calculator'!$A$3:$A$177
Name MS_Labs_Array: EXPORT!$B$5:$E$216
Name RelicValidation: #REF!
Name LC_LabLvls_Array: 'Lab Calculator'!$C$3:$C$177
Name RelicValidation: IDS!$F$7
Name LABS_LabSearchStartPoint: DVT_Laboratory!$B$3
Name LABS_LabName_Array: DVT_Laboratory!$B$1:$LO$1
Name MS_LabNamesOrder_Array: EXPORT!$B$5:$B$177
Name RelicID: IDS!$E$9
Name RelicID: #REF!
Name MS_LabDisc_LabVal: 'Master Sheet'!$C$7
Name LABS_LabLevel_Array: DVT_Laboratory!$A$3:$A$102
Name IDS_MOD_GENERATOR_ASSIST_MULT_CAP: LAMBDA('_IDS'!$BM$4)
Name IDS_MOD_GENERATOR_NAME: LAMBDA(preset, OFFSET('_IDS'!$BM$8, MATCH(preset, '_IDS'!$BL$7:$BL$23, 0)-1, 0, 1, 1))
Name IDS_MOD_CANNON_NAME: LAMBDA(preset, OFFSET('_IDS'!$BC$8, MATCH(preset, '_IDS'!$BB$7:$BB$23, 0)-1, 0, 1, 1))
Name IDS_MOD_CORE_RARITY: LAMBDA(name, IFERROR(OFFSET('_IDS'!$BQ$29, MATCH(name, '_IDS'!$BQ$27:$BQ, 0)-1, 0, 1, 1)))
Name IDS_MOD_CORE_NAME: LAMBDA(preset, OFFSET('_IDS'!$BR$8, MATCH(preset, '_IDS'!$BQ$7:$BQ$23, 0)-1, 0, 1, 1))
Name IDS_WS_CASH_LEVEL: LAMBDA(ws_name, IF('_IDS'!$G$1="✅", IFERROR(VLOOKUP(ws_name, '_IDS'!$F$2:$Q, 3, FALSE), 0), 0))
Name IDS_MOD_GENERATOR_LEVEL: LAMBDA(name, OFFSET('_IDS'!$BM$29, MATCH(name, '_IDS'!$BL$27:$BL, 0)-1, 0, 1, 1))
Name IDS_THEMES_BOOST: LAMBDA('_IDS'!$AY$2)
Name IDS_MOD_CORE_BONUS: LAMBDA(name, OFFSET('_IDS'!$BS$29, MATCH(name, '_IDS'!$BQ$27:$BQ, 0)-1, 0, 1, 1))
Name IDS_MOD_ARMOR_LEVEL: LAMBDA(name, OFFSET('_IDS'!$BH$29, MATCH(name, '_IDS'!$BG$27:$BG, 0)-1, 0, 1, 1))
Name IDS_MOD_CORE_ASSIST_SUBSTAT_CAP: LAMBDA('_IDS'!$BR$5)
Name IDS_MOD_ARMOR_SUBSTATS: LAMBDA(name, IFERROR(OFFSET('_IDS'!$BG$31, MATCH(name, '_IDS'!$BG$27:$BG, 0)-1, 0, 8, 4)))
Name LABDURATION_SINGLE_ADJUSTED_FORMATED: LAMBDA(lab_name, lab_level, XLOOKUP(lab_level,LR_LabLevel_Array,OFFSET(LR_LabSearchStartPoint,0,MATCH(lab_name,LR_LabName_Array,0),100,1),"N/F",0,1))
Name IDS_MOD_GENERATOR_ASSIST_LEVEL: LAMBDA('_IDS'!$BN$2)
Name IDS_MOD_GENERATOR_RARITY: LAMBDA(name, IFERROR(OFFSET('_IDS'!$BL$29, MATCH(name, '_IDS'!$BL$27:$BL, 0)-1, 0, 1, 1)))
Name IDS_CARDS_IN_PRESET: LAMBDA(preset, card_name, COUNTIF(OFFSET('_IDS'!$AH$3, 0, MATCH(preset, '_IDS'!$AH$2:$AL$2, 0)-1, 30, 1) , card_name) > 0)
Name IDS_PS_TIER_PB: LAMBDA(tiername, VLOOKUP(TierName, '_IDS'!$BZ$3:$CA, 2, FALSE))
Name IDS_WS_COIN_LEVEL: LAMBDA(ws_name, IF('_IDS'!$G$1="✅", IFERROR(VLOOKUP(ws_name, '_IDS'!$F$2:$Q, 2, FALSE), 0), 0))
Name IDS_MOD_ARMOR_ASSIST_MULT_CAP: LAMBDA('_IDS'!$BH$4)
Name IDS_BOT_VALUE: LAMBDA(bot_name, bot_property, LET( off, (MATCH(bot_name, '_IDS'!$AS$2:$AS$17, 0) - 1), VLOOKUP(bot_property, OFFSET('_IDS'!$AU$2, off, 0, 4, 2), 2, FALSE) ))
Name IDS_MOD_CANNON_ASSIST_NAME: LAMBDA(preset, OFFSET('_IDS'!$BC$9, MATCH(preset, '_IDS'!$BB$7:$BB$23, 0)-1, 0, 1, 1))
Name IDS_MOD_CORE_ASSIST_LEVEL: LAMBDA('_IDS'!$BS$2)
Name IDS_CARD_PRESET: LAMBDA(preset, OFFSET('_IDS'!$AH$3, 0, MATCH(preset, '_IDS'!$AH$2:$AL$2, 0)-1, 27, 1))
Name IDS_MOD_CANNON_ASSIST_LEVEL: LAMBDA('_IDS'!$BD$2)
Name IDS_PS_COIN_MULTIPLIER: LAMBDA('_IDS'!$CE$14)
Name IDS_MOD_CANNON_ASSIST_SUBSTAT_CAP: LAMBDA('_IDS'!$BC$5)
Name RELIC_STAT: LAMBDA(relic_name, IF(RelicValidation="✅", VLOOKUP(relic_name,'_IDS'!$A$1:$B,2,FALSE), 0))
Name IDS_MOD_CANNON_SUBSTATS: LAMBDA(name, IFERROR(OFFSET('_IDS'!$BB$31, MATCH(name, '_IDS'!$BB$27:$BB, 0)-1, 0, 8, 4)))
Name IDS_MOD_CORE_LEVEL: LAMBDA(name, OFFSET('_IDS'!$BR$29, MATCH(name, '_IDS'!$BQ$27:$BQ, 0)-1, 0, 1, 1))
Name IDS_MOD_CORE_ASSIST_MULT_CAP: LAMBDA('_IDS'!$BR$4)
Name IDS_BOT_OWN: LAMBDA(bot_name, LET( off, (MATCH(bot_name, '_IDS'!$AS$2:$AS$17, 0) - 1), OFFSET('_IDS'!$AS$5, off, 0, 1, 1) ))
Name LAB_SPEED_TOTAL: LAMBDA((1+('Master Sheet'!$C$8*0.02))*(1+'Master Sheet'!$BK$5))
Name IDS_UW_LEVEL: LAMBDA(uw_name, uw_stat, LET( off, (MATCH(uw_name, '_IDS'!$Z$2:$Z$37, 0) - 1), VLOOKUP(uw_stat, OFFSET('_IDS'!$AB$2, off, 0, 4, 3), 3, FALSE) ))
Name IDS_MOD_ARMOR_NAME: LAMBDA(preset, OFFSET('_IDS'!$BH$8, MATCH(preset, '_IDS'!$BG$7:$BG$23, 0)-1, 0, 1, 1))
Name IDS_MOD_CANNON_RARITY: LAMBDA(name, IFERROR(OFFSET('_IDS'!$BB$29, MATCH(name, '_IDS'!$BB$27:$BB, 0)-1, 0, 1, 1)))
Name IDS_LAB_GODLBOXED_COUNT: LAMBDA(SUMPRODUCT(--('_IDS'!$B$2:$B='_IDS'!$D$2:$D),--('_IDS'!$D$2:$D<>"")))
Name IDS_WSE_PRESET_LEVEL: LAMBDA(preset, wse_name, IF('_IDS'!$G$1="✅", IFERROR(OFFSET('_IDS'!$T$4, MATCH(wse_name, '_IDS'!$R$4:$R, 0)-1, MATCH(preset, '_IDS'!$T$2:$X$2, 0)-1, 1, 1), 0), 0))
Name IDS_CARD_LEVEL: LAMBDA(card_name, IF(VLOOKUP(card_name,'_IDS'!$AE$2:$AG$31, 2, FALSE)="Locked", 1, VLOOKUP(card_name,'_IDS'!$AE$2:$AG, 2, FALSE)))
Name IDS_WS_LEVEL: LAMBDA(ws_name, MAX(IDS_WS_COIN_LEVEL(ws_name), IDS_WS_CASH_LEVEL(ws_name)))
Name IDS_GUARDIAN_LEVEL: LAMBDA(guardian_name, guardian_stat, LET( off, (MATCH(guardian_name, '_IDS'!$BU$2:$BU, 0) - 1), VLOOKUP(guardian_stat, OFFSET('_IDS'!$BW$2, off, 0, 4, 3), 3, FALSE) ))
Name IDS_MOD_GENERATOR_ASSIST_SUBSTAT_CAP: LAMBDA('_IDS'!$BM$5)
Name LABDURATION_SINGLE_ADJUSTED: LAMBDA(lab_name, lab_level, DVT_LAB_DURATION(lab_name, lab_level) / LAB_SPEED_TOTAL())
Name DVT_MODULE_SHARDS_COST_CUMMULATIVE: LAMBDA(level, IF(level <=1, 0, SUM(ARRAYFORMULA(DVT_MODULE_SHARDS_COST(ROW(INDIRECT("1:"&level)))))))
Name IDS_UW_VALUE: LAMBDA(uw_name, uw_stat, LET( off, (MATCH(uw_name, '_IDS'!$Z$2:$Z$37, 0) - 1), VLOOKUP(uw_stat, OFFSET('_IDS'!$AB$2, off, 0, 4, 2), 2, FALSE) ))
Name IDS_MOD_CORE_SUBSTATS: LAMBDA(name, IFERROR(OFFSET('_IDS'!$BQ$31, MATCH(name, '_IDS'!$BQ$27:$BQ, 0)-1, 0, 8, 4)))
Name IDS_VAULT_STAT: LAMBDA(vault_stat, IFERROR(IF('_IDS'!$AR$1="✅", VLOOKUP(vault_stat,'_IDS'!$AP$2:$AQ,2,FALSE), 0), 0))

Sheet Home Page
B2: Laboratory
B4: =HYPERLINK("https://docs.google.com/spreadsheets/d/165-JujisYPpKi3RWew9O5gptDJ6rgr-71BbyoQafoaU/copy", "Laboratory Initial Link") -> Laboratory Initial Link | G4: Sheet Tab | H4: Creator | I4: Main Contributor | J4: Helpers
G6: IDS | H6: @Mattew | I6: @Mattew | J6: @Bisse
B7: Latest remote version : | G7: Master Sheet | H7: @TC Team | I7: @Mattew
B8: =IFERROR(__xludf.DUMMYFUNCTION("IMPORTRANGE(""165-JujisYPpKi3RWew9O5gptDJ6rgr-71BbyoQafoaU"", ""'Home Page'!B12:C13"")"),"v2.5.7") -> v2.5.7 | C8: =IFERROR(__xludf.DUMMYFUNCTION("""COMPUTED_VALUE"""),"fix: Add x7 and x8 Boost to Lab Planner") -> fix: Add x7 and x8 Boost to Lab Planner | G8: Lab Calculator | H8: @Yornola | I8: @Mattew | J8: @TC Team
B9: =IFERROR(__xludf.DUMMYFUNCTION("""COMPUTED_VALUE"""),"v2.5.6") -> v2.5.6 | C9: =IFERROR(__xludf.DUMMYFUNCTION("""COMPUTED_VALUE"""),"fix: Tier List Speed Boost not hidden") -> fix: Tier List Speed Boost not hidden | G9: Lab Planner | H9: @JayCee101 | I9: @JayCee101
G10: Tier List | H10: @Audacious, @minionek | I10: @Mattew, @Alan M | J10: @1410c, @IGotSlain, @Iver, @zAlpha
B11: Version Change : | G11: Lab Boost Calculator | H11: @GodzillasDaddy | I11: @GodzillasDaddy
B12: v2.5.7 | C12: fix: Add x7 and x8 Boost to Lab Planner | G12: Short Lab Path | H12: @Garikover | I12: @Garikover | J12: @Mattew
B13: v2.5.6 | C13: fix: Tier List Speed Boost not hidden | G13: Goldbox Path | H13: @QuietFanta | I13: @QuietFanta
B14: v2.5.5 | C14: fix: Updated Lab Planner UI for readability. | G14: Interactive Thorns | H14: @phoenix345 | I14: @phoenix345 | J14: @Mattew, @xiao_shaa
B15: v2.5.4 | C15: fix: Lab Planner Gem Rush - missing BC labs | G15: ELS BC Reduction | H15: @yournicknm | I15: @yournicknm
B16: v2.5.3 | C16: fix: UW Labs in Gold Box Path | G16: Elites Spawncap | J16: @Mattew
B17: v2.5.2 | C17: fix: Lab Planner Gem Rush
B18: v2.5.1 | C18: fix: PB Grabber for Gold/Short Path | G18: Tab colors explanation
B19: v2.5 | C19: feat: Saving Gems by Gold Boxing
B20: v2.4.7 | C20: feat: Enhanced the Tier List Script to be way faster | G20: Home Page | H20: Input Tabs | I20: Local Tools | J20: Static Data
B21: v2.4.6 | C21: fix: Short Lab Path pulling Tier dropdown from Player&Stuff
B22: v2.4.5 | C22: fix: Goldbox Path pulling Tier dropdown from Player&Stuff
B23: v2.4.4 | C23: fix: Labs Speed double dipping in Duration | G23: Enjoying those sheets? You can support me by using my creator code for any in game or webstore purchases. My creator code is : SHEETLORD
B24: v2.4.3 | C24: feat: cost limit added to Goldbox Path
B25: v2.4.2 | C25: fix: Goldbox Path Ignores Target Levels
B26: v2.4.1 | C26: feat: Updated Rush Gem calculation
B27: v2.4 | C27: feat: Goldbox Path
B28: v2.3.2 | C28: feature: Update Lab Boost Calculator for x7 and x8 boosts | G28: Want to support someone else ? Here is the creator code list
B29: v2.3.2 | C29: fix: Lab Speed Relic formula
B30: v2.3.1 | C30: fix: Minor tweaks to Lab Boost Calculator | G30: =IFERROR(__xludf.DUMMYFUNCTION("IMPORTRANGE(""1eCPPuQOE3Pyh8HhnApEMK3RFIutkUjWd61ppVImwWk8"", ""_Giveaway_summary!A1:A2"")"),"⚠️ 1 Giveaway(s) running - 22 Mar") -> ⚠️ 1 Giveaway(s) running - 22 Mar
B31: v2.3 | C31: feat: Tier List (@Audacious, @minionek, @Alan M) | G31: =IFERROR(__xludf.DUMMYFUNCTION("""COMPUTED_VALUE"""),"Giveaway Details") -> Giveaway Details
B32: v2.2.4 | C32: feat: Thorns Calc now reads Thorns Substats
B33: v2.2.3 | C33: fix: Lab Planner 4 and 5 looked at wrong lab boost cell
B34: v2.2.2 | C34: feat: Enhanced Short Lab Path with "ignore targets"
B35: v2.2.1 | C35: feat: Lab Planner switch between time and date mode
B36: v2.2 | C36: Add: Short Lab Path
B37: v2.1.5.2 | C37: fix: Lab Calc filter (For real this time)
B38: v2.1.5.1 | C38: fix: Lab Calc filter
B39: v2.1.5 | C39: feat: Added a CPH column to Lab Calculator
B40: v2.1.4 | C40: fix: Interactive Thorns Elites+PCm for SF
B41: v2.1.3 | C41: fix: BC max lab levels on Calculator
B42: v2.1.2 | C42: feat: Fleets in Thorns Calculations
B43: v2.1.1 | C43: fix: Elite Defense labs -> Elite Health
...

Sheet IDS
B2: The IDS System | I2: Looking for the Import script ? Just run it as you were doing it before, but from IDS Master. It will let you import every new versions at once!
B4: This Sheet ID is : | C4: 1jojOg_XIJCzm1LCYWu2F4KCtErjUIdKuFL1PiKzA0OE
B6: IDS Master's ID ➡️ | C6: 1HOIkxWbbciTIAzVruaahEGADlM8rS0-w86uBXj4PwNQ | D6: =IFERROR(__xludf.DUMMYFUNCTION("IFERROR(C6.url, IFS(LEFT(C6,8)=""https://"", C6, LEN(C6)=44, ""https://docs.google.com/spreadsheets/d/"" & C6 & ""/edit"", TRUE, C6))"),"https://docs.google.com/spreadsheets/d/1HOIkxWbbciTIAzVruaahEGADlM8rS0-w86uBXj4PwNQ/edit") -> https://docs.google.com/spreadsheets/d/1HOIkxWbbciTIAzVruaahEGADlM8rS0-w86uBXj4PwNQ/edit | E6: =IFERROR(__xludf.DUMMYFUNCTION("IF(D6<>"""", IF(IMPORTRANGE(D6,""EXPORT!A1"") = F6, ""✅"", ""Wrong ID or Version""), """")"),"✅") -> ✅ | F6: v2
B7: =HYPERLINK("https://docs.google.com/spreadsheets/d/1osjoqKmMwtOWs7Up3e21-3ofN1RHOjsgKV6y3dc6rgE/copy", "1️⃣ Copy Me") -> 1️⃣ Copy Me | C7: =IFS( ISERROR(E6), "3️⃣ Click on #REF! and then AUTHORISE ↗", E6="", "2️⃣ Please input your IDS Master's ID here ⤴️", E6="✅", HYPERLINK(D6, "Go to my IDS Master Sheet"), TRUE, "") -> Go to my IDS Master Sheet | E7: ✅ | I7: Issues
I8: Mobile Users If you are on mobile, you will not be able to do STEP 3. There is a workaround you can do still : You need to edit the viewing permissions to "anyone with the link" of all your IDs sheets If you have any other trouble, let us know in the #effective-path Discord's channel. I say us, but don't ask Fanta. Fanta hates IDS.
B9: How to use
B10: STEP 1: Click on the Copy Me link and create your copy of the IDS Master. STEP 2: Copy the ID (you will find it in the IDS tab) of your newly created sheet and paste it in the light gray area. STEP 3: Wait a little bit, the F5 cell will show "Loading...", and after few seconds it will display "#REF!". Click on the cell, and "Authorize" to let this sheet access the other one.
B19: And that's it! The IDS are setuped. You can now fill sub IDS in the IDS Master with sub IDS sheets (Laboratory, Workshop, ...) just like you did in here. Every time you will change a value (let's say, a lab level in Laboratory Sheet) the change will be propagated to every other sheet using the IDS Master automatically.
B23: Is it mandatory ?
B24: No, it is not really mandatory but it is the best practice I would recommend. You should be able to override everything using the Master Sheet. But that's not how this is supposed to be used.

Sheet Master Sheet
B1: Labs | C1: Level | D1: Target | E1: Max | G1: Labs | H1: Level | I1: Target | J1: Max | L1: Labs | M1: Level | N1: Target | O1: Max | Q1: Labs | R1: Level | S1: Target | T1: Max | V1: Labs | W1: Level | X1: Target | Y1: Max | AA1: Labs | AB1: Level | AC1: Target | AD1: Max | AF1: Labs | AG1: Level | AH1: Target | AI1: Max | AK1: Labs | AL1: Level | AM1: Target | AN1: Max | AP1: Labs | AQ1: Level | AR1: Target | AS1: Max | AU1: Labs | AV1: Level | AW1: Target | AX1: Max | AZ1: Labs | BA1: Level | BB1: Target | BC1: Max | BE1: Workshop Upgrade | BF1: ¢ Level | BG1: $ Level | BH1: Max | BJ1: Card Name | BK1: Level | BL1: Mastery
A2: ="("&ROUND(C43/E43*100,0)&"%)" -> (31%) | B2: Game Speed | C2: 7 | D2: 7 | E2: =COUNTA(OFFSET(DVT_Laboratory!$B$3, 0, MATCH(B2,DVT_Laboratory!$B$1:BM$1, 0)-1, 100, 1)) -> 7 | F2: ="("&ROUND(H43/J43*100,0)&"%)" -> (50%) | G2: Damage | H2: 69 | J2: =COUNTA(OFFSET(DVT_Laboratory!$B$3, 0, MATCH(G2,DVT_Laboratory!$B$1:BM$1, 0)-1, 100, 1)) -> 100 | K2: ="("&ROUND(M43/O43*100,0)&"%)" -> (58%) | L2: Health | M2: 68 | O2: =COUNTA(OFFSET(DVT_Laboratory!$B$3, 0, MATCH(L2,DVT_Laboratory!$B$1:BM$1, 0)-1, 100, 1)) -> 100 | P2: ="("&ROUND(R43/T43*100,0)&"%)" -> (35%) | Q2: Cash Bonus | R2: 33 | T2: =COUNTA(OFFSET(DVT_Laboratory!$B$3, 0, MATCH(Q2,DVT_Laboratory!$B$1:BM$1, 0)-1, 100, 1)) -> 99 | U2: ="("&ROUND(W43/Y43*100,0)&"%)" -> (42%) | V2: Missile Despawn Time | W2: 0 | Y2: =COUNTA(OFFSET(DVT_Laboratory!$B$3, 0, MATCH(V2,DVT_Laboratory!$B$1:BM$1, 0)-1, 100, 1)) -> 20 | Z2: ="("&ROUND(AB43/AD43*100,0)&"%)" -> (9%) | AA2: Second Wind Blast | AB2: 4 | AD2: =COUNTA(OFFSET(DVT_Laboratory!$B$3, 0, MATCH(AA2,DVT_Laboratory!$B$1:BM$1, 0)-1, 100, 1)) -> 4 | AE2: ="("&ROUND(AG43/AI43*100,0)&"%)" -> (39%) | AF2: Unlock Perks | AG2: 1 | AI2: =COUNTA(OFFSET(DVT_Laboratory!$B$3, 0, MATCH(AF2,DVT_Laboratory!$B$1:BM$1, 0)-1, 100, 1)) -> 1 | AJ2: ="("&ROUND(AL43/AN43*100,0)&"%)" -> (35%) | AK2: Flame Bot - Cooldown | AL2: 25 | AN2: =COUNTA(OFFSET(DVT_Laboratory!$B$3, 0, MATCH(AK2,DVT_Laboratory!$B$1:BM$1, 0)-1, 100, 1)) -> 25 | AO2: ="("&ROUND(AQ43/AS43*100,0)&"%)" -> (0%) | AP2: Common Enemy Health | AQ2: 0 | AS2: =COUNTA(OFFSET(DVT_Laboratory!$B$3, 0, MATCH(AP2,DVT_Laboratory!$B$1:BM$1, 0)-1, 100, 1)) -> 30 | AT2: ="("&ROUND(AV43/AX43*100,0)&"%)" -> (48%) | AU2: Common Drop Chance | AV2: 10 | AX2: =COUNTA(OFFSET(DVT_Laboratory!$B$3, 0, MATCH(AU2,DVT_Laboratory!$B$1:BM$1, 0)-1, 100, 1)) -> 10 | AY2: ="("&ROUND(BA43/BC43*100,0)&"%)" -> (0%) | AZ2: Battle Condition Reduction | BA2: 0 | BC2: =COUNTA(OFFSET(DVT_Laboratory!$B$3, 0, MATCH(AZ2,DVT_Laboratory!$B$1:BM$1, 0)-1, 100, 1)) -> 10 | BD2: OTHERS - WORKSHOP | BE2: Thorn Damage | BF2: =IDS_WS_COIN_LEVEL(BE2) -> 99 | BG2: =IDS_WS_CASH_LEVEL(BE2) -> 99 | BH2: 99 | BI2: OTHERS | BJ2: Plasma Cannon | BK2: =IDS_CARD_LEVEL(BJ2) -> 7 | BL2: =IDS_CARD_MASTERY(BJ2) -> FALSE
B3: Starting Cash | C3: 6 | E3: =COUNTA(OFFSET(DVT_Laboratory!$B$3, 0, MATCH(B3,DVT_Laboratory!$B$1:BM$1, 0)-1, 100, 1)) -> 99 | G3: Attack Speed | H3: 75 | J3: =COUNTA(OFFSET(DVT_Laboratory!$B$3, 0, MATCH(G3,DVT_Laboratory!$B$1:BM$1, 0)-1, 100, 1)) -> 99 | L3: Health Regen | M3: 68 | O3: =COUNTA(OFFSET(DVT_Laboratory!$B$3, 0, MATCH(L3,DVT_Laboratory!$B$1:BM$1, 0)-1, 100, 1)) -> 100 | Q3: Cash / Wave | R3: 8 | T3: =COUNTA(OFFSET(DVT_Laboratory!$B$3, 0, MATCH(Q3,DVT_Laboratory!$B$1:BM$1, 0)-1, 100, 1)) -> 99 | V3: Missiles Explosion | W3: 0 | Y3: =COUNTA(OFFSET(DVT_Laboratory!$B$3, 0, MATCH(V3,DVT_Laboratory!$B$1:BM$1, 0)-1, 100, 1)) -> 1 | AA3: Double Death Ray | AB3: 6 | AD3: =COUNTA(OFFSET(DVT_Laboratory!$B$3, 0, MATCH(AA3,DVT_Laboratory!$B$1:BM$1, 0)-1, 100, 1)) -> 30 | AF3: Waves Required | AG3: 13 | AH3: 17 | AI3: =COUNTA(OFFSET(DVT_Laboratory!$B$3, 0, MATCH(AF3,DVT_Laboratory!$B$1:BM$1, 0)-1, 100, 1)) -> 100 | AK3: Thunder Bot - Cooldown | AL3: 0 | AN3: =COUNTA(OFFSET(DVT_Laboratory!$B$3, 0, MATCH(AK3,DVT_Laboratory!$B$1:BM$1, 0)-1, 100, 1)) -> 25 | AP3: Common Enemy Attack | AQ3: 0 | AS3: =COUNTA(OFFSET(DVT_Laboratory!$B$3, 0, MATCH(AP3,DVT_Laboratory!$B$1:BM$1, 0)-1, 100, 1)) -> 30 | AU3: Reroll Shards | AV3: 100 | AW3: 100 | AX3: =COUNTA(OFFSET(DVT_Laboratory!$B$3, 0, MATCH(AU3,DVT_Laboratory!$B$1:BM$1, 0)-1, 100, 1)) -> 100 | AZ3: Knockback Resistance | BA3: 0 | BC3: =COUNTA(OFFSET(DVT_Laboratory!$B$3, 0, MATCH(AZ3,DVT_Laboratory!$B$1:BM$1, 0)-1, 100, 1)) -> 20
B4: Workshop Attack Discount | C4: 27 | E4: =COUNTA(OFFSET(DVT_Laboratory!$B$3, 0, MATCH(B4,DVT_Laboratory!$B$1:BM$1, 0)-1, 100, 1)) -> 99 | G4: Critical Factor | H4: 83 | J4: =COUNTA(OFFSET(DVT_Laboratory!$B$3, 0, MATCH(G4,DVT_Laboratory!$B$1:BM$1, 0)-1, 100, 1)) -> 99 | L4: Defense Absolute | M4: 14 | N4: 14 | O4: =COUNTA(OFFSET(DVT_Laboratory!$B$3, 0, MATCH(L4,DVT_Laboratory!$B$1:BM$1, 0)-1, 100, 1)) -> 100 | Q4: Coins / Kill Bonus | R4: 87 | T4: =COUNTA(OFFSET(DVT_Laboratory!$B$3, 0, MATCH(Q4,DVT_Laboratory!$B$1:BM$1, 0)-1, 100, 1)) -> 99 | V4: Missile Radius | W4: 0 | Y4: =COUNTA(OFFSET(DVT_Laboratory!$B$3, 0, MATCH(V4,DVT_Laboratory!$B$1:BM$1, 0)-1, 100, 1)) -> 20 | AA4: Extra Orb Adjuster | AB4: 1 | AD4: =COUNTA(OFFSET(DVT_Laboratory!$B$3, 0, MATCH(AA4,DVT_Laboratory!$B$1:BM$1, 0)-1, 100, 1)) -> 1 | AF4: Auto Pick Perks | AG4: 1 | AI4: =COUNTA(OFFSET(DVT_Laboratory!$B$3, 0, MATCH(AF4,DVT_Laboratory!$B$1:BM$1, 0)-1, 100, 1)) -> 1 | AK4: Gold Bot - Cooldown | AL4: 21 | AN4: =COUNTA(OFFSET(DVT_Laboratory!$B$3, 0, MATCH(AK4,DVT_Laboratory!$B$1:BM$1, 0)-1, 100, 1)) -> 25 | AP4: Fast Enemy Health | AQ4: 0 | AS4: =COUNTA(OFFSET(DVT_Laboratory!$B$3, 0, MATCH(AP4,DVT_Laboratory!$B$1:BM$1, 0)-1, 100, 1)) -> 30 | AU4: Daily Mission Shards | AV4: 50 | AW4: 50 | AX4: =COUNTA(OFFSET(DVT_Laboratory!$B$3, 0, MATCH(AU4,DVT_Laboratory!$B$1:BM$1, 0)-1, 100, 1)) -> 50 | AZ4: Thorns Resistance | BA4: 0 | BC4: =COUNTA(OFFSET(DVT_Laboratory!$B$3, 0, MATCH(AZ4,DVT_Laboratory!$B$1:BM$1, 0)-1, 100, 1)) -> 20 | BJ4: =IF('_IDS'!AH1="✅", HYPERLINK('_IDS'!AG1, "Go to my Relic Sheet"), "Relic") -> Relic | BK4: Bonus
A5: MAIN RESEARCHES | B5: Workshop Defense Discount | C5: 28 | E5: =COUNTA(OFFSET(DVT_Laboratory!$B$3, 0, MATCH(B5,DVT_Laboratory!$B$1:BM$1, 0)-1, 100, 1)) -> 99 | F5: ATTACK | G5: Range | H5: 33 | J5: =COUNTA(OFFSET(DVT_Laboratory!$B$3, 0, MATCH(G5,DVT_Laboratory!$B$1:BM$1, 0)-1, 100, 1)) -> 80 | K5: DEFENSE | L5: Defense % | M5: 28 | N5: 28 | O5: =COUNTA(OFFSET(DVT_Laboratory!$B$3, 0, MATCH(L5,DVT_Laboratory!$B$1:BM$1, 0)-1, 100, 1)) -> 50 | P5: UTILITY | Q5: Coins / Wave | R5: 6 | T5: =COUNTA(OFFSET(DVT_Laboratory!$B$3, 0, MATCH(Q5,DVT_Laboratory!$B$1:BM$1, 0)-1, 100, 1)) -> 99 | U5: ULTIMATE WEAPONS | V5: Chrono Field Duration | W5: 30 | Y5: =COUNTA(OFFSET(DVT_Laboratory!$B$3, 0, MATCH(V5,DVT_Laboratory!$B$1:BM$1, 0)-1, 100, 1)) -> 30 | Z5: CARDS | AA5: Extra Extra Orbs | AB5: 2 | AD5: =COUNTA(OFFSET(DVT_Laboratory!$B$3, 0, MATCH(AA5,DVT_Laboratory!$B$1:BM$1, 0)-1, 100, 1)) -> 2 | AE5: PERKS | AF5: Standard Perks Bonus | AG5: 25 | AI5: =COUNTA(OFFSET(DVT_Laboratory!$B$3, 0, MATCH(AF5,DVT_Laboratory!$B$1:BM$1, 0)-1, 100, 1)) -> 25 | AJ5: BOTS | AK5: Amp Bot - Cooldown | AL5: 0 | AN5: =COUNTA(OFFSET(DVT_Laboratory!$B$3, 0, MATCH(AK5,DVT_Laboratory!$B$1:BM$1, 0)-1, 100, 1)) -> 25 | AO5: ENEMIES | AP5: Fast Enemy Attack | AQ5: 0 | AS5: =COUNTA(OFFSET(DVT_Laboratory!$B$3, 0, MATCH(AP5,DVT_Laboratory!$B$1:BM$1, 0)-1, 100, 1)) -> 30 | AT5: MODULES | AU5: Module Shards Cost | AV5: 30 | AX5: =COUNTA(OFFSET(DVT_Laboratory!$B$3, 0, MATCH(AU5,DVT_Laboratory!$B$1:BM$1, 0)-1, 100, 1)) -> 30 | AY5: BATTLE CONDITION | AZ5: Orb Resistance | BA5: 0 | BC5: =COUNTA(OFFSET(DVT_Laboratory!$B$3, 0, MATCH(AZ5,DVT_Laboratory!$B$1:BM$1, 0)-1, 100, 1)) -> 20 | BJ5: Lab Speed | BK5: =IDS_RELIC_STAT(BJ5) -> 0.395
B6: Workshop Utility Discount | C6: 41 | E6: =COUNTA(OFFSET(DVT_Laboratory!$B$3, 0, MATCH(B6,DVT_Laboratory!$B$1:BM$1, 0)-1, 100, 1)) -> 99 | G6: Damage / Meter | H6: 16 | J6: =COUNTA(OFFSET(DVT_Laboratory!$B$3, 0, MATCH(G6,DVT_Laboratory!$B$1:BM$1, 0)-1, 100, 1)) -> 99 | L6: Orbs Speed | M6: 20 | O6: =COUNTA(OFFSET(DVT_Laboratory!$B$3, 0, MATCH(L6,DVT_Laboratory!$B$1:BM$1, 0)-1, 100, 1)) -> 20 | Q6: Interest | R6: 11 | T6: =COUNTA(OFFSET(DVT_Laboratory!$B$3, 0, MATCH(Q6,DVT_Laboratory!$B$1:BM$1, 0)-1, 100, 1)) -> 99 | V6: Chrono Field Damage Reduction | W6: 1 | Y6: =COUNTA(OFFSET(DVT_Laboratory!$B$3, 0, MATCH(V6,DVT_Laboratory!$B$1:BM$1, 0)-1, 100, 1)) -> 1 | AA6: Energy Shield Extra Hit | AB6: 2 | AD6: =COUNTA(OFFSET(DVT_Laboratory!$B$3, 0, MATCH(AA6,DVT_Laboratory!$B$1:BM$1, 0)-1, 100, 1)) -> 2 | AF6: Perk Option Quantity | AG6: 2 | AI6: =COUNTA(OFFSET(DVT_Laboratory!$B$3, 0, MATCH(AF6,DVT_Laboratory!$B$1:BM$1, 0)-1, 100, 1)) -> 2 | AK6: Flame Bot - Burn Stack | AL6: 0 | AN6: =COUNTA(OFFSET(DVT_Laboratory!$B$3, 0, MATCH(AK6,DVT_Laboratory!$B$1:BM$1, 0)-1, 100, 1)) -> 5 | AP6: Fast Enemy Speed | AQ6: 0 | AS6: =COUNTA(OFFSET(DVT_Laboratory!$B$3, 0, MATCH(AP6,DVT_Laboratory!$B$1:BM$1, 0)-1, 100, 1)) -> 30 | AU6: Module Coin Cost | AV6: 23 | AX6: =COUNTA(OFFSET(DVT_Laboratory!$B$3, 0, MATCH(AU6,DVT_Laboratory!$B$1:BM$1, 0)-1, 100, 1)) -> 30 | AZ6: Plasma Cannon Resistance | BA6: 0 | BC6: =COUNTA(OFFSET(DVT_Laboratory!$B$3, 0, MATCH(AZ6,DVT_Laboratory!$B$1:BM$1, 0)-1, 100, 1)) -> 20 | BJ6: Thorns | BK6: =IDS_RELIC_STAT(BJ6) -> 0.09
B7: Labs Coin Discount | C7: 68 | E7: =COUNTA(OFFSET(DVT_Laboratory!$B$3, 0, MATCH(B7,DVT_Laboratory!$B$1:BM$1, 0)-1, 100, 1)) -> 99 | G7: Super Crit Chance | H7: 9 | J7: =COUNTA(OFFSET(DVT_Laboratory!$B$3, 0, MATCH(G7,DVT_Laboratory!$B$1:BM$1, 0)-1, 100, 1)) -> 50 | L7: Land Mine Damage | M7: 0 | O7: =COUNTA(OFFSET(DVT_Laboratory!$B$3, 0, MATCH(L7,DVT_Laboratory!$B$1:BM$1, 0)-1, 100, 1)) -> 20 | Q7: Max Interest | R7: 8 | T7: =COUNTA(OFFSET(DVT_Laboratory!$B$3, 0, MATCH(Q7,DVT_Laboratory!$B$1:BM$1, 0)-1, 100, 1)) -> 15 | V7: Chrono Field Reduction % | W7: 20 | Y7: =COUNTA(OFFSET(DVT_Laboratory!$B$3, 0, MATCH(V7,DVT_Laboratory!$B$1:BM$1, 0)-1, 100, 1)) -> 30 | AA7: Super Tower Bonus | AB7: 0 | AD7: =COUNTA(OFFSET(DVT_Laboratory!$B$3, 0, MATCH(AA7,DVT_Laboratory!$B$1:BM$1, 0)-1, 100, 1)) -> 30 | AF7: First Perk Choice | AG7: 1 | AI7: =COUNTA(OFFSET(DVT_Laboratory!$B$3, 0, MATCH(AF7,DVT_Laboratory!$B$1:BM$1, 0)-1, 100, 1)) -> 1 | AK7: Thunder Bot - Linger Time | AL7: 0 | AN7: =COUNTA(OFFSET(DVT_Laboratory!$B$3, 0, MATCH(AK7,DVT_Laboratory!$B$1:BM$1, 0)-1, 100, 1)) -> 20 | AP7: Tank Enemy Health | AQ7: 0 | AS7: =COUNTA(OFFSET(DVT_Laboratory!$B$3, 0, MATCH(AP7,DVT_Laboratory!$B$1:BM$1, 0)-1, 100, 1)) -> 30 | AU7: Rare Drop Chance | AV7: 10 | AW7: 10 | AX7: =COUNTA(OFFSET(DVT_Laboratory!$B$3, 0, MATCH(AU7,DVT_Laboratory!$B$1:BM$1, 0)-1, 100, 1)) -> 10 | AZ7: Death Ray Resistance | BA7: 0 | BC7: =COUNTA(OFFSET(DVT_Laboratory!$B$3, 0, MATCH(AZ7,DVT_Laboratory!$B$1:BM$1, 0)-1, 100, 1)) -> 20
B8: Labs Speed | C8: 91 | E8: =COUNTA(OFFSET(DVT_Laboratory!$B$3, 0, MATCH(B8,DVT_Laboratory!$B$1:BM$1, 0)-1, 100, 1)) -> 99 | G8: Super Crit Multi | H8: 13 | J8: =COUNTA(OFFSET(DVT_Laboratory!$B$3, 0, MATCH(G8,DVT_Laboratory!$B$1:BM$1, 0)-1, 100, 1)) -> 40 | L8: Land Mine Decay | M8: 13 | O8: =COUNTA(OFFSET(DVT_Laboratory!$B$3, 0, MATCH(L8,DVT_Laboratory!$B$1:BM$1, 0)-1, 100, 1)) -> 35 | Q8: Package After Boss | R8: 1 | T8: =COUNTA(OFFSET(DVT_Laboratory!$B$3, 0, MATCH(Q8,DVT_Laboratory!$B$1:BM$1, 0)-1, 100, 1)) -> 1 | V8: Swamp Radius | W8: 0 | Y8: =COUNTA(OFFSET(DVT_Laboratory!$B$3, 0, MATCH(V8,DVT_Laboratory!$B$1:BM$1, 0)-1, 100, 1)) -> 30 | AA8: Recharge Second Wind | AB8: 7 | AD8: =COUNTA(OFFSET(DVT_Laboratory!$B$3, 0, MATCH(AA8,DVT_Laboratory!$B$1:BM$1, 0)-1, 100, 1)) -> 7 | AF8: Ban Perks | AG8: 6 | AI8: =COUNTA(OFFSET(DVT_Laboratory!$B$3, 0, MATCH(AF8,DVT_Laboratory!$B$1:BM$1, 0)-1, 100, 1)) -> 8 | AK8: Gold Bot - Duration | AL8: 12 | AN8: =COUNTA(OFFSET(DVT_Laboratory!$B$3, 0, MATCH(AK8,DVT_Laboratory!$B$1:BM$1, 0)-1, 100, 1)) -> 20 | AP8: Tank Enemy Attack | AQ8: 0 | AS8: =COUNTA(OFFSET(DVT_Laboratory!$B$3, 0, MATCH(AP8,DVT_Laboratory!$B$1:BM$1, 0)-1, 100, 1)) -> 30 | AU8: Unmerge Module | AV8: 1 | AX8: =COUNTA(OFFSET(DVT_Laboratory!$B$3, 0, MATCH(AU8,DVT_Laboratory!$B$1:BM$1, 0)-1, 100, 1)) -> 1 | AZ8: Armored Enemies | BA8: 0 | BC8: =COUNTA(OFFSET(DVT_Laboratory!$B$3, 0, MATCH(AZ8,DVT_Laboratory!$B$1:BM$1, 0)-1, 100, 1)) -> 20 | BJ8: =IF('_IDS'!$AK$1="✅", HYPERLINK('_IDS'!AJ1, "Go to my Vault Sheet"), "Vault") -> Vault | BK8: Bonus
B9: Buy Multiplier | C9: 4 | E9: =COUNTA(OFFSET(DVT_Laboratory!$B$3, 0, MATCH(B9,DVT_Laboratory!$B$1:BM$1, 0)-1, 100, 1)) -> 4 | G9: Max Rend Armor Multiplier | H9: 0 | J9: =COUNTA(OFFSET(DVT_Laboratory!$B$3, 0, MATCH(G9,DVT_Laboratory!$B$1:BM$1, 0)-1, 100, 1)) -> 30 | L9: Shockwave Size | M9: 10 | O9: =COUNTA(OFFSET(DVT_Laboratory!$B$3, 0, MATCH(L9,DVT_Laboratory!$B$1:BM$1, 0)-1, 100, 1)) -> 20 | Q9: Recovery Package Amount | R9: 0 | T9: =COUNTA(OFFSET(DVT_Laboratory!$B$3, 0, MATCH(Q9,DVT_Laboratory!$B$1:BM$1, 0)-1, 100, 1)) -> 20 | V9: Swamp Stun | W9: 0 | Y9: =COUNTA(OFFSET(DVT_Laboratory!$B$3, 0, MATCH(V9,DVT_Laboratory!$B$1:BM$1, 0)-1, 100, 1)) -> 1 | AA9: Recharge Demon Mode | AB9: 4 | AD9: =COUNTA(OFFSET(DVT_Laboratory!$B$3, 0, MATCH(AA9,DVT_Laboratory!$B$1:BM$1, 0)-1, 100, 1)) -> 7 | AF9: Improve Trade-off Perks | AG9: 10 | AI9: =COUNTA(OFFSET(DVT_Laboratory!$B$3, 0, MATCH(AF9,DVT_Laboratory!$B$1:BM$1, 0)-1, 100, 1)) -> 10 | AK9: Amp Bot - Duration | AL9: 0 | AN9: =COUNTA(OFFSET(DVT_Laboratory!$B$3, 0, MATCH(AK9,DVT_Laboratory!$B$1:BM$1, 0)-1, 100, 1)) -> 20 | AP9: Ranged Enemy Health | AQ9: 0 | AS9: =COUNTA(OFFSET(DVT_Laboratory!$B$3, 0, MATCH(AP9,DVT_Laboratory!$B$1:BM$1, 0)-1, 100, 1)) -> 30 | AU9: Shatter Shards | AV9: 5 | AX9: =COUNTA(OFFSET(DVT_Laboratory!$B$3, 0, MATCH(AU9,DVT_Laboratory!$B$1:BM$1, 0)-1, 100, 1)) -> 5 | AZ9: Enemy Speed | BA9: 0 | BC9: =COUNTA(OFFSET(DVT_Laboratory!$B$3, 0, MATCH(AZ9,DVT_Laboratory!$B$1:BM$1, 0)-1, 100, 1)) -> 20 | BJ9: Thorn Damage | BK9: =IDS_VAULT_STAT(BJ9) -> 0
B10: More Round Stats | C10: 1 | E10: =COUNTA(OFFSET(DVT_Laboratory!$B$3, 0, MATCH(B10,DVT_Laboratory!$B$1:BM$1, 0)-1, 100, 1)) -> 1 | G10: Light Speed Shots | H10: 1 | J10: =COUNTA(OFFSET(DVT_Laboratory!$B$3, 0, MATCH(G10,DVT_Laboratory!$B$1:BM$1, 0)-1, 100, 1)) -> 1 | L10: Orb Boss Hit | M10: 10 | O10: =COUNTA(OFFSET(DVT_Laboratory!$B$3, 0, MATCH(L10,DVT_Laboratory!$B$1:BM$1, 0)-1, 100, 1)) -> 10 | Q10: Recovery Package Max | R10: 0 | T10: =COUNTA(OFFSET(DVT_Laboratory!$B$3, 0, MATCH(Q10,DVT_Laboratory!$B$1:BM$1, 0)-1, 100, 1)) -> 20 | V10: Swamp Stun Chance | W10: 0 | Y10: =COUNTA(OFFSET(DVT_Laboratory!$B$3, 0, MATCH(V10,DVT_Laboratory!$B$1:BM$1, 0)-1, 100, 1)) -> 30 | AA10: Recharge Nuke | AB10: 2 | AD10: =COUNTA(OFFSET(DVT_Laboratory!$B$3, 0, MATCH(AA10,DVT_Laboratory!$B$1:BM$1, 0)-1, 100, 1)) -> 7 | AF10: Auto Pick Ranking | AG10: 12 | AI10: =COUNTA(OFFSET(DVT_Laboratory!$B$3, 0, MATCH(AF10,DVT_Laboratory!$B$1:BM$1, 0)-1, 100, 1)) -> 32 | AP10: Ranged Enemy Attack | AQ10: 0 | AS10: =COUNTA(OFFSET(DVT_Laboratory!$B$3, 0, MATCH(AP10,DVT_Laboratory!$B$1:BM$1, 0)-1, 100, 1)) -> 30 | AU10: Cannon Effect Bans | AV10: 0 | AX10: =COUNTA(OFFSET(DVT_Laboratory!$B$3, 0, MATCH(AU10,DVT_Laboratory!$B$1:BM$1, 0)-1, 100, 1)) -> 4 | AZ10: More Enemies | BA10: 0 | BC10: =COUNTA(OFFSET(DVT_Laboratory!$B$3, 0, MATCH(AZ10,DVT_Laboratory!$B$1:BM$1, 0)-1, 100, 1)) -> 20
B11: Target Priority | C11: 2 | E11: =COUNTA(OFFSET(DVT_Laboratory!$B$3, 0, MATCH(B11,DVT_Laboratory!$B$1:BM$1, 0)-1, 100, 1)) -> 2 | L11: Wall Health | M11: 50 | O11: =COUNTA(OFFSET(DVT_Laboratory!$B$3, 0, MATCH(L11,DVT_Laboratory!$B$1:BM$1, 0)-1, 100, 1)) -> 50 | Q11: Recovery Package Chance | R11: 20 | T11: =COUNTA(OFFSET(DVT_Laboratory!$B$3, 0, MATCH(Q11,DVT_Laboratory!$B$1:BM$1, 0)-1, 100, 1)) -> 20 | V11: Swamp Stun Time | W11: 0 | Y11: =COUNTA(OFFSET(DVT_Laboratory!$B$3, 0, MATCH(V11,DVT_Laboratory!$B$1:BM$1, 0)-1, 100, 1)) -> 30 | AA11: Damage Mastery | AB11: 0 | AD11: =COUNTA(OFFSET(DVT_Laboratory!$B$3, 0, MATCH("Card Mastery",DVT_Laboratory!$B$1:BM$1, 0)-1, 100, 1)) -> 9 | AP11: Boss Health | AQ11: 0 | AS11: =COUNTA(OFFSET(DVT_Laboratory!$B$3, 0, MATCH(AP11,DVT_Laboratory!$B$1:BM$1, 0)-1, 100, 1)) -> 30 | AU11: Armor Effect Bans | AV11: 2 | AX11: =COUNTA(OFFSET(DVT_Laboratory!$B$3, 0, MATCH(AU11,DVT_Laboratory!$B$1:BM$1, 0)-1, 100, 1)) -> 4 | AZ11: Enemy Attack Speed | BA11: 0 | BC11: =COUNTA(OFFSET(DVT_Laboratory!$B$3, 0, MATCH(AZ11,DVT_Laboratory!$B$1:BM$1, 0)-1, 100, 1)) -> 20
B12: Card Presets | C12: 1 | E12: =COUNTA(OFFSET(DVT_Laboratory!$B$3, 0, MATCH(B12,DVT_Laboratory!$B$1:BM$1, 0)-1, 100, 1)) -> 1 | L12: Wall Rebuild | M12: 9 | O12: =COUNTA(OFFSET(DVT_Laboratory!$B$3, 0, MATCH(L12,DVT_Laboratory!$B$1:BM$1, 0)-1, 100, 1)) -> 20 | Q12: Enemy Attack Level Skip | R12: 20 | T12: =COUNTA(OFFSET(DVT_Laboratory!$B$3, 0, MATCH(Q12,DVT_Laboratory!$B$1:BM$1, 0)-1, 100, 1)) -> 20 | V12: Golden Tower Bonus | W12: 22 | Y12: =COUNTA(OFFSET(DVT_Laboratory!$B$3, 0, MATCH(V12,DVT_Laboratory!$B$1:BM$1, 0)-1, 100, 1)) -> 25 | AA12: Attack Speed Mastery | AB12: 0 | AD12: =COUNTA(OFFSET(DVT_Laboratory!$B$3, 0, MATCH("Card Mastery",DVT_Laboratory!$B$1:BM$1, 0)-1, 100, 1)) -> 9 | AP12: Boss Attack | AQ12: 0 | AS12: =COUNTA(OFFSET(DVT_Laboratory!$B$3, 0, MATCH(AP12,DVT_Laboratory!$B$1:BM$1, 0)-1, 100, 1)) -> 30 | AU12: Generator Effect Bans | AV12: 1 | AX12: =COUNTA(OFFSET(DVT_Laboratory!$B$3, 0, MATCH(AU12,DVT_Laboratory!$B$1:BM$1, 0)-1, 100, 1)) -> 3 | AZ12: Fast's Ultimate | BA12: 0 | BC12: =COUNTA(OFFSET(DVT_Laboratory!$B$3, 0, MATCH(AZ12,DVT_Laboratory!$B$1:BM$1, 0)-1, 100, 1)) -> 10
B13: Workshop Respec | C13: 1 | E13: =COUNTA(OFFSET(DVT_Laboratory!$B$3, 0, MATCH(B13,DVT_Laboratory!$B$1:BM$1, 0)-1, 100, 1)) -> 1 | L13: Wall Regen | M13: 21 | O13: =COUNTA(OFFSET(DVT_Laboratory!$B$3, 0, MATCH(L13,DVT_Laboratory!$B$1:BM$1, 0)-1, 100, 1)) -> 30 | Q13: Enemy Health Level Skip | R13: 20 | T13: =COUNTA(OFFSET(DVT_Laboratory!$B$3, 0, MATCH(Q13,DVT_Laboratory!$B$1:BM$1, 0)-1, 100, 1)) -> 20 | V13: Golden Tower Duration | W13: 19 | Y13: =COUNTA(OFFSET(DVT_Laboratory!$B$3, 0, MATCH(V13,DVT_Laboratory!$B$1:BM$1, 0)-1, 100, 1)) -> 20 | AA13: Health Mastery | AB13: 0 | AD13: =COUNTA(OFFSET(DVT_Laboratory!$B$3, 0, MATCH("Card Mastery",DVT_Laboratory!$B$1:BM$1, 0)-1, 100, 1)) -> 9 | AP13: Protector Health | AQ13: 0 | AS13: =COUNTA(OFFSET(DVT_Laboratory!$B$3, 0, MATCH(AP13,DVT_Laboratory!$B$1:BM$1, 0)-1, 100, 1)) -> 30 | AU13: Core Effect Bans | AV13: 4 | AX13: =COUNTA(OFFSET(DVT_Laboratory!$B$3, 0, MATCH(AU13,DVT_Laboratory!$B$1:BM$1, 0)-1, 100, 1)) -> 7 | AZ13: Ranged Ultimate | BA13: 0 | BC13: =COUNTA(OFFSET(DVT_Laboratory!$B$3, 0, MATCH(AZ13,DVT_Laboratory!$B$1:BM$1, 0)-1, 100, 1)) -> 10
B14: Reroll Daily Mission | C14: 1 | E14: =COUNTA(OFFSET(DVT_Laboratory!$B$3, 0, MATCH(B14,DVT_Laboratory!$B$1:BM$1, 0)-1, 100, 1)) -> 1 | L14: Wall Thorns | M14: 15 | O14: =COUNTA(OFFSET(DVT_Laboratory!$B$3, 0, MATCH(L14,DVT_Laboratory!$B$1:BM$1, 0)-1, 100, 1)) -> 20 | V14: Chain Lightning Shock | W14: 1 | Y14: =COUNTA(OFFSET(DVT_Laboratory!$B$3, 0, MATCH(V14,DVT_Laboratory!$B$1:BM$1, 0)-1, 100, 1)) -> 1 | AA14: Health Regen Mastery | AB14: 0 | AD14: =COUNTA(OFFSET(DVT_Laboratory!$B$3, 0, MATCH("Card Mastery",DVT_Laboratory!$B$1:BM$1, 0)-1, 100, 1)) -> 9 | AP14: Protector Radius | AQ14: 0 | AS14: =COUNTA(OFFSET(DVT_Laboratory!$B$3, 0, MATCH(AP14,DVT_Laboratory!$B$1:BM$1, 0)-1, 100, 1)) -> 30 | AU14: Assist Module Substats - Cannon | AV14: 0 | AX14: =COUNTA(OFFSET(DVT_Laboratory!$B$3, 0, MATCH(AU14,DVT_Laboratory!$B$1:BM$1, 0)-1, 100, 1)) -> 30 | AZ14: Boss's Ultimate | BA14: 0 | BC14: =COUNTA(OFFSET(DVT_Laboratory!$B$3, 0, MATCH(AZ14,DVT_Laboratory!$B$1:BM$1, 0)-1, 100, 1)) -> 10
B15: Workshop Enhancements | C15: 1 | E15: =COUNTA(OFFSET(DVT_Laboratory!$B$3, 0, MATCH(B15,DVT_Laboratory!$B$1:BM$1, 0)-1, 100, 1)) -> 1 | L15: Wall Invincibility | M15: 0 | O15: =COUNTA(OFFSET(DVT_Laboratory!$B$3, 0, MATCH(L15,DVT_Laboratory!$B$1:BM$1, 0)-1, 100, 1)) -> 10 | V15: Shock Chance | W15: 14 | Y15: =COUNTA(OFFSET(DVT_Laboratory!$B$3, 0, MATCH(V15,DVT_Laboratory!$B$1:BM$1, 0)-1, 100, 1)) -> 30 | AA15: Range Mastery | AB15: 0 | AD15: =COUNTA(OFFSET(DVT_Laboratory!$B$3, 0, MATCH("Card Mastery",DVT_Laboratory!$B$1:BM$1, 0)-1, 100, 1)) -> 9 | AP15: Protector Damage Reduction | AQ15: 0 | AS15: =COUNTA(OFFSET(DVT_Laboratory!$B$3, 0, MATCH(AP15,DVT_Laboratory!$B$1:BM$1, 0)-1, 100, 1)) -> 20 | AU15: Assist Module Substats - Armor | AV15: 0 | AX15: =COUNTA(OFFSET(DVT_Laboratory!$B$3, 0, MATCH(AU15,DVT_Laboratory!$B$1:BM$1, 0)-1, 100, 1)) -> 30 | AZ15: Basic's Ultimate | BA15: 0 | BC15: =COUNTA(OFFSET(DVT_Laboratory!$B$3, 0, MATCH(AZ15,DVT_Laboratory!$B$1:BM$1, 0)-1, 100, 1)) -> 10
B16: Enhancement Attack - Coin Discount | C16: 0 | E16: =COUNTA(OFFSET(DVT_Laboratory!$B$3, 0, MATCH(B16,DVT_Laboratory!$B$1:BM$1, 0)-1, 100, 1)) -> 100 | L16: Wall Fortification | M16: 47 | O16: =COUNTA(OFFSET(DVT_Laboratory!$B$3, 0, MATCH(L16,DVT_Laboratory!$B$1:BM$1, 0)-1, 100, 1)) -> 60 | V16: Shock Multiplier | W16: 14 | Y16: =COUNTA(OFFSET(DVT_Laboratory!$B$3, 0, MATCH(V16,DVT_Laboratory!$B$1:BM$1, 0)-1, 100, 1)) -> 14 | AA16: Cash Mastery | AB16: 1 | AD16: =COUNTA(OFFSET(DVT_Laboratory!$B$3, 0, MATCH("Card Mastery",DVT_Laboratory!$B$1:BM$1, 0)-1, 100, 1)) -> 9 | AP16: Ray Enemy Attack | AQ16: 0 | AS16: =COUNTA(OFFSET(DVT_Laboratory!$B$3, 0, MATCH(AP16,DVT_Laboratory!$B$1:BM$1, 0)-1, 100, 1)) -> 30 | AU16: Assist Module Substats - Generator | AV16: 0 | AX16: =COUNTA(OFFSET(DVT_Laboratory!$B$3, 0, MATCH(AU16,DVT_Laboratory!$B$1:BM$1, 0)-1, 100, 1)) -> 30 | AZ16: Tank's Ultimate | BA16: 0 | BC16: =COUNTA(OFFSET(DVT_Laboratory!$B$3, 0, MATCH(AZ16,DVT_Laboratory!$B$1:BM$1, 0)-1, 100, 1)) -> 10
B17: Enhancement Defense - Coin Discount | C17: 0 | E17: =COUNTA(OFFSET(DVT_Laboratory!$B$3, 0, MATCH(B17,DVT_Laboratory!$B$1:BM$1, 0)-1, 100, 1)) -> 100 | L17: Garlic Thorns | M17: 10 | O17: =COUNTA(OFFSET(DVT_Laboratory!$B$3, 0, MATCH(L17,DVT_Laboratory!$B$1:BM$1, 0)-1, 100, 1)) -> 10 | V17: Death Wave Health | W17: 30 | Y17: =COUNTA(OFFSET(DVT_Laboratory!$B$3, 0, MATCH(V17,DVT_Laboratory!$B$1:BM$1, 0)-1, 100, 1)) -> 30 | AA17: Coins Mastery | AB17: 0 | AD17: =COUNTA(OFFSET(DVT_Laboratory!$B$3, 0, MATCH("Card Mastery",DVT_Laboratory!$B$1:BM$1, 0)-1, 100, 1)) -> 9 | AP17: Ray Enemy Health | AQ17: 0 | AS17: =COUNTA(OFFSET(DVT_Laboratory!$B$3, 0, MATCH(AP17,DVT_Laboratory!$B$1:BM$1, 0)-1, 100, 1)) -> 30 | AU17: Assist Module Substats - Core | AV17: 0 | AX17: =COUNTA(OFFSET(DVT_Laboratory!$B$3, 0, MATCH(AU17,DVT_Laboratory!$B$1:BM$1, 0)-1, 100, 1)) -> 30 | AZ17: Protector's Ultimate | BA17: 0 | BC17: =COUNTA(OFFSET(DVT_Laboratory!$B$3, 0, MATCH(AZ17,DVT_Laboratory!$B$1:BM$1, 0)-1, 100, 1)) -> 10
B18: Enhancement Utility - Coin Discount | C18: 0 | E18: =COUNTA(OFFSET(DVT_Laboratory!$B$3, 0, MATCH(B18,DVT_Laboratory!$B$1:BM$1, 0)-1, 100, 1)) -> 100 | V18: Death Wave Coin Bonus | W18: 20 | Y18: =COUNTA(OFFSET(DVT_Laboratory!$B$3, 0, MATCH(V18,DVT_Laboratory!$B$1:BM$1, 0)-1, 100, 1)) -> 20 | AA18: Slow Aura Mastery | AB18: 0 | AD18: =COUNTA(OFFSET(DVT_Laboratory!$B$3, 0, MATCH("Card Mastery",DVT_Laboratory!$B$1:BM$1, 0)-1, 100, 1)) -> 9 | AP18: Vampire Enemy Attack | AQ18: 0 | AS18: =COUNTA(OFFSET(DVT_Laboratory!$B$3, 0, MATCH(AP18,DVT_Laboratory!$B$1:BM$1, 0)-1, 100, 1)) -> 30 | AU18: Assist Module Bonus - Cannon | AV18: 0 | AX18: =COUNTA(OFFSET(DVT_Laboratory!$B$3, 0, MATCH(AU18,DVT_Laboratory!$B$1:BM$1, 0)-1, 100, 1)) -> 30 | AZ18: Ultimate Weapon Durations | BA18: 0 | BC18: =COUNTA(OFFSET(DVT_Laboratory!$B$3, 0, MATCH(AZ18,DVT_Laboratory!$B$1:BM$1, 0)-1, 100, 1)) -> 10
V19: Inner Mine Blast Radius | W19: 0 | Y19: =COUNTA(OFFSET(DVT_Laboratory!$B$3, 0, MATCH(V19,DVT_Laboratory!$B$1:BM$1, 0)-1, 100, 1)) -> 20 | AA19: Critical Chance Mastery | AB19: 0 | AD19: =COUNTA(OFFSET(DVT_Laboratory!$B$3, 0, MATCH("Card Mastery",DVT_Laboratory!$B$1:BM$1, 0)-1, 100, 1)) -> 9 | AP19: Vampire Enemy Health | AQ19: 0 | AS19: =COUNTA(OFFSET(DVT_Laboratory!$B$3, 0, MATCH(AP19,DVT_Laboratory!$B$1:BM$1, 0)-1, 100, 1)) -> 30 | AU19: Assist Module Bonus - Armor | AV19: 0 | AX19: =COUNTA(OFFSET(DVT_Laboratory!$B$3, 0, MATCH(AU19,DVT_Laboratory!$B$1:BM$1, 0)-1, 100, 1)) -> 30 | AZ19: Death Defy Down | BA19: 0 | BC19: =COUNTA(OFFSET(DVT_Laboratory!$B$3, 0, MATCH(AZ19,DVT_Laboratory!$B$1:BM$1, 0)-1, 100, 1)) -> 10
V20: Inner Mine Rotation Speed | W20: 0 | Y20: =COUNTA(OFFSET(DVT_Laboratory!$B$3, 0, MATCH(V20,DVT_Laboratory!$B$1:BM$1, 0)-1, 100, 1)) -> 20 | AA20: Enemy Balance Mastery | AB20: 0 | AD20: =COUNTA(OFFSET(DVT_Laboratory!$B$3, 0, MATCH("Card Mastery",DVT_Laboratory!$B$1:BM$1, 0)-1, 100, 1)) -> 9 | AP20: Scatter Enemy Attack | AQ20: 0 | AS20: =COUNTA(OFFSET(DVT_Laboratory!$B$3, 0, MATCH(AP20,DVT_Laboratory!$B$1:BM$1, 0)-1, 100, 1)) -> 30 | AU20: Assist Module Bonus - Generator | AV20: 0 | AX20: =COUNTA(OFFSET(DVT_Laboratory!$B$3, 0, MATCH(AU20,DVT_Laboratory!$B$1:BM$1, 0)-1, 100, 1)) -> 30 | AZ20: Energy Shields Down | BA20: 0 | BC20: =COUNTA(OFFSET(DVT_Laboratory!$B$3, 0, MATCH(AZ20,DVT_Laboratory!$B$1:BM$1, 0)-1, 100, 1)) -> 10
V21: Chrono Field Range | W21: 17 | Y21: =COUNTA(OFFSET(DVT_Laboratory!$B$3, 0, MATCH(V21,DVT_Laboratory!$B$1:BM$1, 0)-1, 100, 1)) -> 20 | AA21: Extra Defense Mastery | AB21: 0 | AD21: =COUNTA(OFFSET(DVT_Laboratory!$B$3, 0, MATCH("Card Mastery",DVT_Laboratory!$B$1:BM$1, 0)-1, 100, 1)) -> 9 | AP21: Scatter Enemy Health | AQ21: 0 | AS21: =COUNTA(OFFSET(DVT_Laboratory!$B$3, 0, MATCH(AP21,DVT_Laboratory!$B$1:BM$1, 0)-1, 100, 1)) -> 30 | AU21: Assist Module Bonus - Core | AV21: 0 | AX21: =COUNTA(OFFSET(DVT_Laboratory!$B$3, 0, MATCH(AU21,DVT_Laboratory!$B$1:BM$1, 0)-1, 100, 1)) -> 30 | AZ21: Enemy Level Skip Reduction | BA21: 0 | BC21: =COUNTA(OFFSET(DVT_Laboratory!$B$3, 0, MATCH(AZ21,DVT_Laboratory!$B$1:BM$1, 0)-1, 100, 1)) -> 10
V22: Missile Amplifier | W22: 0 | Y22: =COUNTA(OFFSET(DVT_Laboratory!$B$3, 0, MATCH(V22,DVT_Laboratory!$B$1:BM$1, 0)-1, 100, 1)) -> 25 | AA22: Fortress Mastery | AB22: 0 | AD22: =COUNTA(OFFSET(DVT_Laboratory!$B$3, 0, MATCH("Card Mastery",DVT_Laboratory!$B$1:BM$1, 0)-1, 100, 1)) -> 9 | AP22: Ranged Enemy Range | AQ22: 0 | AS22: =COUNTA(OFFSET(DVT_Laboratory!$B$3, 0, MATCH(AP22,DVT_Laboratory!$B$1:BM$1, 0)-1, 100, 1)) -> 30
V23: Missile Barrage | W23: 0 | Y23: =COUNTA(OFFSET(DVT_Laboratory!$B$3, 0, MATCH(V23,DVT_Laboratory!$B$1:BM$1, 0)-1, 100, 1)) -> 1 | AA23: Free Upgrades Mastery | AB23: 0 | AD23: =COUNTA(OFFSET(DVT_Laboratory!$B$3, 0, MATCH("Card Mastery",DVT_Laboratory!$B$1:BM$1, 0)-1, 100, 1)) -> 9
V24: Missile Barrage Quantity | W24: 0 | Y24: =COUNTA(OFFSET(DVT_Laboratory!$B$3, 0, MATCH(V24,DVT_Laboratory!$B$1:BM$1, 0)-1, 100, 1)) -> 6 | AA24: Extra Orb Mastery | AB24: 0 | AD24: =COUNTA(OFFSET(DVT_Laboratory!$B$3, 0, MATCH("Card Mastery",DVT_Laboratory!$B$1:BM$1, 0)-1, 100, 1)) -> 9
V25: Inner Mine Stun | W25: 0 | Y25: =COUNTA(OFFSET(DVT_Laboratory!$B$3, 0, MATCH(V25,DVT_Laboratory!$B$1:BM$1, 0)-1, 100, 1)) -> 1 | AA25: Plasma Cannon Mastery | AB25: 0 | AD25: =COUNTA(OFFSET(DVT_Laboratory!$B$3, 0, MATCH("Card Mastery",DVT_Laboratory!$B$1:BM$1, 0)-1, 100, 1)) -> 9
V26: Black Hole Damage | W26: 10 | Y26: =COUNTA(OFFSET(DVT_Laboratory!$B$3, 0, MATCH(V26,DVT_Laboratory!$B$1:BM$1, 0)-1, 100, 1)) -> 10 | AA26: Critical Coin Mastery | AB26: 0 | AD26: =COUNTA(OFFSET(DVT_Laboratory!$B$3, 0, MATCH("Card Mastery",DVT_Laboratory!$B$1:BM$1, 0)-1, 100, 1)) -> 9
V27: Extra Black Hole | W27: 1 | Y27: =COUNTA(OFFSET(DVT_Laboratory!$B$3, 0, MATCH(V27,DVT_Laboratory!$B$1:BM$1, 0)-1, 100, 1)) -> 1 | AA27: Wave Skip Mastery | AB27: 0 | AD27: =COUNTA(OFFSET(DVT_Laboratory!$B$3, 0, MATCH("Card Mastery",DVT_Laboratory!$B$1:BM$1, 0)-1, 100, 1)) -> 9
V28: Black Hole Coin Bonus | W28: 20 | Y28: =COUNTA(OFFSET(DVT_Laboratory!$B$3, 0, MATCH(V28,DVT_Laboratory!$B$1:BM$1, 0)-1, 100, 1)) -> 20 | AA28: Intro Sprint Mastery | AB28: 0 | AD28: =COUNTA(OFFSET(DVT_Laboratory!$B$3, 0, MATCH("Card Mastery",DVT_Laboratory!$B$1:BM$1, 0)-1, 100, 1)) -> 9
V29: Spotlight Coin Bonus | W29: 20 | Y29: =COUNTA(OFFSET(DVT_Laboratory!$B$3, 0, MATCH(V29,DVT_Laboratory!$B$1:BM$1, 0)-1, 100, 1)) -> 20 | AA29: Land Mine Stun Mastery | AB29: 0 | AD29: =COUNTA(OFFSET(DVT_Laboratory!$B$3, 0, MATCH("Card Mastery",DVT_Laboratory!$B$1:BM$1, 0)-1, 100, 1)) -> 9
V30: Spotlight Missiles | W30: 1 | Y30: =COUNTA(OFFSET(DVT_Laboratory!$B$3, 0, MATCH(V30,DVT_Laboratory!$B$1:BM$1, 0)-1, 100, 1)) -> 18 | AA30: Recovery Package Chance Mastery | AB30: 3 | AD30: =COUNTA(OFFSET(DVT_Laboratory!$B$3, 0, MATCH("Card Mastery",DVT_Laboratory!$B$1:BM$1, 0)-1, 100, 1)) -> 9
V31: Black Hole Disable Ranged Enemies | W31: 1 | Y31: =COUNTA(OFFSET(DVT_Laboratory!$B$3, 0, MATCH(V31,DVT_Laboratory!$B$1:BM$1, 0)-1, 100, 1)) -> 1 | AA31: Death Ray Mastery | AB31: 0 | AD31: =COUNTA(OFFSET(DVT_Laboratory!$B$3, 0, MATCH("Card Mastery",DVT_Laboratory!$B$1:BM$1, 0)-1, 100, 1)) -> 9
V32: Recharge Missile Barrage | W32: 0 | Y32: =COUNTA(OFFSET(DVT_Laboratory!$B$3, 0, MATCH(V32,DVT_Laboratory!$B$1:BM$1, 0)-1, 100, 1)) -> 7 | AA32: Energy Net Mastery | AB32: 0 | AD32: =COUNTA(OFFSET(DVT_Laboratory!$B$3, 0, MATCH("Card Mastery",DVT_Laboratory!$B$1:BM$1, 0)-1, 100, 1)) -> 9
V33: Swamp Rend | W33: 0 | Y33: =COUNTA(OFFSET(DVT_Laboratory!$B$3, 0, MATCH(V33,DVT_Laboratory!$B$1:BM$1, 0)-1, 100, 1)) -> 30 | AA33: Super Tower Mastery | AB33: 0 | AD33: =COUNTA(OFFSET(DVT_Laboratory!$B$3, 0, MATCH("Card Mastery",DVT_Laboratory!$B$1:BM$1, 0)-1, 100, 1)) -> 9
V34: Swamp Rend - Additional Enemies | W34: 0 | Y34: =COUNTA(OFFSET(DVT_Laboratory!$B$3, 0, MATCH(V34,DVT_Laboratory!$B$1:BM$1, 0)-1, 100, 1)) -> 6 | AA34: Second Wind Mastery | AB34: 0 | AD34: =COUNTA(OFFSET(DVT_Laboratory!$B$3, 0, MATCH("Card Mastery",DVT_Laboratory!$B$1:BM$1, 0)-1, 100, 1)) -> 9
... V40: Inner Land Mine - Chrono Jump | W40: 0 | Y40: =COUNTA(OFFSET(DVT_Laboratory!$B$3, 0, MATCH(V40,DVT_Laboratory!$B$1:BM$1, 0)-1, 100, 1)) -> 10 | AA40: Nuke Mastery | AB40: 0 | AD40: =COUNTA(OFFSET(DVT_Laboratory!$B$3, 0, MATCH("Card Mastery",DVT_Laboratory!$B$1:BM$1, 0)-1, 100, 1)) -> 9
AA41: Area of Effect Mastery | AB41: 0 | AD41: =COUNTA(OFFSET(DVT_Laboratory!$B$3, 0, MATCH("Card Mastery",DVT_Laboratory!$B$1:BM$1, 0)-1, 100, 1)) -> 9
C43: =SUM(C2:C42) -> 279 | D43: =SUM(D2:D42) -> 7 | E43: =SUM(E2:E42) -> 912 | H43: =SUM(H2:H42) -> 299 | I43: =SUM(I2:I42) -> 0 | J43: =SUM(J2:J42) -> 598 | M43: =SUM(M2:M42) -> 383 | N43: =SUM(N2:N42) -> 42 | O43: =SUM(O2:O42) -> 655 | R43: =SUM(R2:R42) -> 214 | S43: =SUM(S2:S42) -> 0 | T43: =SUM(T2:T42) -> 611 | W43: =SUM(W2:W42) -> 284 | X43: =SUM(X2:X42) -> 0 | Y43: =SUM(Y2:Y42) -> 669 | AB43: =SUM(AB2:AB42) -> 32 | AC43: =SUM(AC2:AC42) -> 0 | AD43: =SUM(AD2:AD42) -> 369 | AG43: =SUM(AG2:AG42) -> 71 | AH43: =SUM(AH2:AH42) -> 17 | AI43: =SUM(AI2:AI42) -> 180 | AL43: =SUM(AL2:AL42) -> 58 | AM43: =SUM(AM2:AM42) -> 0 | AN43: =SUM(AN2:AN42) -> 165 | AQ43: =SUM(AQ2:AQ42) -> 0 | AR43: =SUM(AR2:AR42) -> 0 | AS43: =SUM(AS2:AS42) -> 620 | AV43: =SUM(AV2:AV42) -> 236 | AW43: =SUM(AW2:AW42) -> 160 | AX43: =SUM(AX2:AX42) -> 494 | BA43: =SUM(BA2:BA42) -> 0 | BB43: =SUM(BB2:BB42) -> 0 | BC43: =SUM(BC2:BC42) -> 290

Sheet _IDS
A1: =IFERROR(__xludf.DUMMYFUNCTION("IMPORTRANGE(IF(IDS!E6=""✅"", IDS!D6, ""1osjoqKmMwtOWs7Up3e21-3ofN1RHOjsgKV6y3dc6rgE""), ""_IDS!A1:CE212"")"),"Labs") -> Labs | B1: =IFERROR(__xludf.DUMMYFUNCTION("""COMPUTED_VALUE"""),"https://docs.google.com/spreadsheets/d/1jojOg_XIJCzm1LCYWu2F4KCtErjUIdKuFL1PiKzA0OE/edit") -> https://docs.google.com/spreadsheets/d/1jojOg_XIJCzm1LCYWu2F4KCtErjUIdKuFL1PiKzA0OE/edit | C1: =IFERROR(__xludf.DUMMYFUNCTION("""COMPUTED_VALUE"""),"✅") -> ✅ | D1: =IFERROR(__xludf.DUMMYFUNCTION("""COMPUTED_VALUE"""),"v2.5.7") -> v2.5.7 | E1: =IFERROR(__xludf.DUMMYFUNCTION("""COMPUTED_VALUE"""),"WS") -> WS | F1: =IFERROR(__xludf.DUMMYFUNCTION("""COMPUTED_VALUE"""),"https://docs.google.com/spreadsheets/d/1huHJMcyg1uRJEeRYqAgWzMc5TodPPplVZEFhwBiIeEs/edit") -> https://docs.google.com/spreadsheets/d/1huHJMcyg1uRJEeRYqAgWzMc5TodPPplVZEFhwBiIeEs/edit | G1: =IFERROR(__xludf.DUMMYFUNCTION("""COMPUTED_VALUE"""),"✅") -> ✅ | H1: =IFERROR(__xludf.DUMMYFUNCTION("""COMPUTED_VALUE"""),"v2.3.1") -> v2.3.1 | R1: =IFERROR(__xludf.DUMMYFUNCTION("""COMPUTED_VALUE"""),"WS+") -> WS+ | Z1: =IFERROR(__xludf.DUMMYFUNCTION("""COMPUTED_VALUE"""),"UWs") -> UWs | AA1: =IFERROR(__xludf.DUMMYFUNCTION("""COMPUTED_VALUE"""),"https://docs.google.com/spreadsheets/d/1VTRhVyt28cxrjCRcgVkQr2R_u4g9irfJTHy1cfftlIE/edit") -> https://docs.google.com/spreadsheets/d/1VTRhVyt28cxrjCRcgVkQr2R_u4g9irfJTHy1cfftlIE/edit | AB1: =IFERROR(__xludf.DUMMYFUNCTION("""COMPUTED_VALUE"""),"✅") -> ✅ | AC1: =IFERROR(__xludf.DUMMYFUNCTION("""COMPUTED_VALUE"""),"v2.1.3") -> v2.1.3 | AE1: =IFERROR(__xludf.DUMMYFUNCTION("""COMPUTED_VALUE"""),"Cards") -> Cards | AF1: =IFERROR(__xludf.DUMMYFUNCTION("""COMPUTED_VALUE"""),"https://docs.google.com/spreadsheets/d/1HMQwNLTvcw7aXmjjL7cXmZSdjAF_62ehWpwDIdjqEGs/edit") -> https://docs.google.com/spreadsheets/d/1HMQwNLTvcw7aXmjjL7cXmZSdjAF_62ehWpwDIdjqEGs/edit | AG1: =IFERROR(__xludf.DUMMYFUNCTION("""COMPUTED_VALUE"""),"✅") -> ✅ | AH1: =IFERROR(__xludf.DUMMYFUNCTION("""COMPUTED_VALUE"""),"Cards Presets") -> Cards Presets | AI1: =IFERROR(__xludf.DUMMYFUNCTION("""COMPUTED_VALUE"""),"v2.2.3") -> v2.2.3 | AJ1: =IFERROR(__xludf.DUMMYFUNCTION("""COMPUTED_VALUE"""),17.0) -> 17 | AM1: =IFERROR(__xludf.DUMMYFUNCTION("""COMPUTED_VALUE"""),"Relics") -> Relics | AN1: =IFERROR(__xludf.DUMMYFUNCTION("""COMPUTED_VALUE"""),"https://docs.google.com/spreadsheets/d/1Dll0IofJTWYkzhzhRWx1aA-_xtO3i_1iD65nAP6R_Ec/edit") -> https://docs.google.com/spreadsheets/d/1Dll0IofJTWYkzhzhRWx1aA-_xtO3i_1iD65nAP6R_Ec/edit | AO1: =IFERROR(__xludf.DUMMYFUNCTION("""COMPUTED_VALUE"""),"✅") -> ✅ | AP1: =IFERROR(__xludf.DUMMYFUNCTION("""COMPUTED_VALUE"""),"Vault") -> Vault | AR1: =IFERROR(__xludf.DUMMYFUNCTION("""COMPUTED_VALUE"""),"") | AS1: =IFERROR(__xludf.DUMMYFUNCTION("""COMPUTED_VALUE"""),"Bots") -> Bots | AT1: =IFERROR(__xludf.DUMMYFUNCTION("""COMPUTED_VALUE"""),"https://docs.google.com/spreadsheets/d/1H3PYvtIH7kId6WswEeMmrx7u5_g1GlkNPJtJhkASrbs/edit") -> https://docs.google.com/spreadsheets/d/1H3PYvtIH7kId6WswEeMmrx7u5_g1GlkNPJtJhkASrbs/edit | AU1: =IFERROR(__xludf.DUMMYFUNCTION("""COMPUTED_VALUE"""),"✅") -> ✅ | AV1: =IFERROR(__xludf.DUMMYFUNCTION("""COMPUTED_VALUE"""),"v2.2.1") -> v2.2.1 | AY1: =IFERROR(__xludf.DUMMYFUNCTION("""COMPUTED_VALUE"""),"Themes & Songs") -> Themes & Songs | AZ1: =IFERROR(__xludf.DUMMYFUNCTION("""COMPUTED_VALUE"""),"https://docs.google.com/spreadsheets/d/19KliigQhAeXztRPa9cSGZ7n9Q-REp4dyqMNI9d-UB0k/edit") -> https://docs.google.com/spreadsheets/d/19KliigQhAeXztRPa9cSGZ7n9Q-REp4dyqMNI9d-UB0k/edit | BA1: =IFERROR(__xludf.DUMMYFUNCTION("""COMPUTED_VALUE"""),"✅") -> ✅ | BB1: =IFERROR(__xludf.DUMMYFUNCTION("""COMPUTED_VALUE"""),"Modules") -> Modules | BC1: =IFERROR(__xludf.DUMMYFUNCTION("""COMPUTED_VALUE"""),"https://docs.google.com/spreadsheets/d/1rOoSY6TK918myJ6Mn6zO4rmUaFbPu6qJnGI17kc9DzQ/edit") -> https://docs.google.com/spreadsheets/d/1rOoSY6TK918myJ6Mn6zO4rmUaFbPu6qJnGI17kc9DzQ/edit | BD1: =IFERROR(__xludf.DUMMYFUNCTION("""COMPUTED_VALUE"""),"✅") -> ✅ | BE1: =IFERROR(__xludf.DUMMYFUNCTION("""COMPUTED_VALUE"""),"v5.13") -> v5.13 | BU1: =IFERROR(__xludf.DUMMYFUNCTION("""COMPUTED_VALUE"""),"Guardians") -> Guardians | BV1: =IFERROR(__xludf.DUMMYFUNCTION("""COMPUTED_VALUE"""),"https://docs.google.com/spreadsheets/d/1J4UPKzR9MLY_zzM7u7SzmyclgTEYX_PUvBcua4EbsSU/edit") -> https://docs.google.com/spreadsheets/d/1J4UPKzR9MLY_zzM7u7SzmyclgTEYX_PUvBcua4EbsSU/edit | BW1: =IFERROR(__xludf.DUMMYFUNCTION("""COMPUTED_VALUE"""),"✅") -> ✅ | BX1: =IFERROR(__xludf.DUMMYFUNCTION("""COMPUTED_VALUE"""),"v2.3.6") -> v2.3.6 | BZ1: =IFERROR(__xludf.DUMMYFUNCTION("""COMPUTED_VALUE"""),"Player & Stuff") -> Player & Stuff | CA1: =IFERROR(__xludf.DUMMYFUNCTION("""COMPUTED_VALUE"""),"https://docs.google.com/spreadsheets/d/1NpLNfHLQFsJ_WyMnxP9jMtzg3gVaMfOxydrTUG0YsuM/edit") -> https://docs.google.com/spreadsheets/d/1NpLNfHLQFsJ_WyMnxP9jMtzg3gVaMfOxydrTUG0YsuM/edit | CB1: =IFERROR(__xludf.DUMMYFUNCTION("""COMPUTED_VALUE"""),"✅") -> ✅ | CC1: =IFERROR(__xludf.DUMMYFUNCTION("""COMPUTED_VALUE"""),"v3.5.3") -> v3.5.3
A2: =IFERROR(__xludf.DUMMYFUNCTION("""COMPUTED_VALUE"""),"Game Speed") -> Game Speed | B2: =IFERROR(__xludf.DUMMYFUNCTION("""COMPUTED_VALUE"""),7.0) -> 7 | C2: =IFERROR(__xludf.DUMMYFUNCTION("""COMPUTED_VALUE"""),7.0) -> 7 | D2: =IFERROR(__xludf.DUMMYFUNCTION("""COMPUTED_VALUE"""),7.0) -> 7 | E2: =IFERROR(__xludf.DUMMYFUNCTION("""COMPUTED_VALUE"""),"U") -> U | F2: =IFERROR(__xludf.DUMMYFUNCTION("""COMPUTED_VALUE"""),"Workshop Upgrade") -> Workshop Upgrade | G2: =IFERROR(__xludf.DUMMYFUNCTION("""COMPUTED_VALUE"""),"Farming") -> Farming | I2: =IFERROR(__xludf.DUMMYFUNCTION("""COMPUTED_VALUE"""),"Tourney") -> Tourney | K2: =IFERROR(__xludf.DUMMYFUNCTION("""COMPUTED_VALUE"""),"Preset 3") -> Preset 3 | M2: =IFERROR(__xludf.DUMMYFUNCTION("""COMPUTED_VALUE"""),"Preset 4") -> Preset 4 | O2: =IFERROR(__xludf.DUMMYFUNCTION("""COMPUTED_VALUE"""),"Preset 5") -> Preset 5 | R2: =IFERROR(__xludf.DUMMYFUNCTION("""COMPUTED_VALUE"""),"Workshop Enhancement") -> Workshop Enhancement | T2: =IFERROR(__xludf.DUMMYFUNCTION("""COMPUTED_VALUE"""),"Farming") -> Farming | U2: =IFERROR(__xludf.DUMMYFUNCTION("""COMPUTED_VALUE"""),"Tourney") -> Tourney | V2: =IFERROR(__xludf.DUMMYFUNCTION("""COMPUTED_VALUE"""),"Preset 3") -> Preset 3 | W2: =IFERROR(__xludf.DUMMYFUNCTION("""COMPUTED_VALUE"""),"Preset 4") -> Preset 4 | X2: =IFERROR(__xludf.DUMMYFUNCTION("""COMPUTED_VALUE"""),"Preset 5") -> Preset 5 | Y2: =IFERROR(__xludf.DUMMYFUNCTION("""COMPUTED_VALUE"""),"7 q") -> 7 q | Z2: =IFERROR(__xludf.DUMMYFUNCTION("""COMPUTED_VALUE"""),"Chain Lightning") -> Chain Lightning | AB2: =IFERROR(__xludf.DUMMYFUNCTION("""COMPUTED_VALUE"""),"Damage") -> Damage | AC2: =IFERROR(__xludf.DUMMYFUNCTION("""COMPUTED_VALUE"""),898.0) -> 898 | AD2: =IFERROR(__xludf.DUMMYFUNCTION("""COMPUTED_VALUE"""),"19 | x898 | Cost 302 ⧌ | Next 362 ⧌") -> 19 | x898 | Cost 302 ⧌ | Next 362 ⧌ | AE2: =IFERROR(__xludf.DUMMYFUNCTION("""COMPUTED_VALUE"""),"Damage") -> Damage | AF2: =IFERROR(__xludf.DUMMYFUNCTION("""COMPUTED_VALUE"""),7.0) -> 7 | AG2: =IFERROR(__xludf.DUMMYFUNCTION("""COMPUTED_VALUE"""),FALSE) -> FALSE | AH2: =IFERROR(__xludf.DUMMYFUNCTION("""COMPUTED_VALUE"""),"Farming") -> Farming | AI2: =IFERROR(__xludf.DUMMYFUNCTION("""COMPUTED_VALUE"""),"Tourney") -> Tourney | AJ2: =IFERROR(__xludf.DUMMYFUNCTION("""COMPUTED_VALUE"""),"Preset 3") -> Preset 3 | AK2: =IFERROR(__xludf.DUMMYFUNCTION("""COMPUTED_VALUE"""),"Preset 4") -> Preset 4 | AL2: =IFERROR(__xludf.DUMMYFUNCTION("""COMPUTED_VALUE"""),"Preset 5") -> Preset 5 | AM2: =IFERROR(__xludf.DUMMYFUNCTION("""COMPUTED_VALUE"""),"Relics") -> Relics | AN2: =IFERROR(__xludf.DUMMYFUNCTION("""COMPUTED_VALUE"""),"Owned") -> Owned | AO2: =IFERROR(__xludf.DUMMYFUNCTION("""COMPUTED_VALUE"""),"v2.3.7") -> v2.3.7 | AP2: =IFERROR(__xludf.DUMMYFUNCTION("""COMPUTED_VALUE"""),"Keys spent") -> Keys spent | AQ2: =IFERROR(__xludf.DUMMYFUNCTION("""COMPUTED_VALUE"""),0.0) -> 0 | AS2: =IFERROR(__xludf.DUMMYFUNCTION("""COMPUTED_VALUE"""),"Flame Bot") -> Flame Bot | AU2: =IFERROR(__xludf.DUMMYFUNCTION("""COMPUTED_VALUE"""),"Damage R.") -> Damage R. | AV2: =IFERROR(__xludf.DUMMYFUNCTION("""COMPUTED_VALUE"""),0.3500000000000001) -> 0.35 | AW2: =IFERROR(__xludf.DUMMYFUNCTION("""COMPUTED_VALUE"""),"05 | 35% | Cost 260 ⧓ | Next 300 ⧓") -> 05 | 35% | Cost 260 ⧓ | Next 300 ⧓ | AY2: =IFERROR(__xludf.DUMMYFUNCTION("""COMPUTED_VALUE"""),1.682) -> 1.682 | BA2: =IFERROR(__xludf.DUMMYFUNCTION("""COMPUTED_VALUE"""),"v2.2.3") -> v2.2.3 | BB2: =IFERROR(__xludf.DUMMYFUNCTION("""COMPUTED_VALUE"""),"Assist Slot") -> Assist Slot | BC2: =IFERROR(__xludf.DUMMYFUNCTION("""COMPUTED_VALUE"""),FALSE) -> FALSE | BD2: =IFERROR(__xludf.DUMMYFUNCTION("""COMPUTED_VALUE"""),0.0) -> 0 | BG2: =IFERROR(__xludf.DUMMYFUNCTION("""COMPUTED_VALUE"""),"Assist Slot") -> Assist Slot | BH2: =IFERROR(__xludf.DUMMYFUNCTION("""COMPUTED_VALUE"""),TRUE) -> TRUE | BI2: =IFERROR(__xludf.DUMMYFUNCTION("""COMPUTED_VALUE"""),41.0) -> 41 | BL2: =IFERROR(__xludf.DUMMYFUNCTION("""COMPUTED_VALUE"""),"Assist Slot") -> Assist Slot | BM2: =IFERROR(__xludf.DUMMYFUNCTION("""COMPUTED_VALUE"""),TRUE) -> TRUE | BN2: =IFERROR(__xludf.DUMMYFUNCTION("""COMPUTED_VALUE"""),97.0) -> 97 | BQ2: =IFERROR(__xludf.DUMMYFUNCTION("""COMPUTED_VALUE"""),"Assist Slot") -> Assist Slot | BR2: =IFERROR(__xludf.DUMMYFUNCTION("""COMPUTED_VALUE"""),TRUE) -> TRUE | BS2: =IFERROR(__xludf.DUMMYFUNCTION("""COMPUTED_VALUE"""),101.0) -> 101 | BU2: =IFERROR(__xludf.DUMMYFUNCTION("""COMPUTED_VALUE"""),"Attack") -> Attack | BW2: =IFERROR(__xludf.DUMMYFUNCTION("""COMPUTED_VALUE"""),"Percentage") -> Percentage | BX2: =IFERROR(__xludf.DUMMYFUNCTION("""COMPUTED_VALUE"""),0.01) -> 0.01 | BY2: =IFERROR(__xludf.DUMMYFUNCTION("""COMPUTED_VALUE"""),"00 | 1% | Cost 0 ⧈ | Next 25 ⧈") -> 00 | 1% | Cost 0 ⧈ | Next 25 ⧈ | BZ2: =IFERROR(__xludf.DUMMYFUNCTION("""COMPUTED_VALUE"""),"Tier") -> Tier | CA2: =IFERROR(__xludf.DUMMYFUNCTION("""COMPUTED_VALUE"""),"Wave") -> Wave | CB2: =IFERROR(__xludf.DUMMYFUNCTION("""COMPUTED_VALUE"""),"P") -> P | CD2: =IFERROR(__xludf.DUMMYFUNCTION("""COMPUTED_VALUE"""),"Stat") -> Stat | CE2: =IFERROR(__xludf.DUMMYFUNCTION("""COMPUTED_VALUE"""),"Value") -> Value
A3: =IFERROR(__xludf.DUMMYFUNCTION("""COMPUTED_VALUE"""),"Starting Cash") -> Starting Cash | B3: =IFERROR(__xludf.DUMMYFUNCTION("""COMPUTED_VALUE"""),6.0) -> 6 | D3: =IFERROR(__xludf.DUMMYFUNCTION("""COMPUTED_VALUE"""),99.0) -> 99 | G3: =IFERROR(__xludf.DUMMYFUNCTION("""COMPUTED_VALUE"""),"¢ Level") -> ¢ Level | H3: =IFERROR(__xludf.DUMMYFUNCTION("""COMPUTED_VALUE"""),"$ Level") -> $ Level | I3: =IFERROR(__xludf.DUMMYFUNCTION("""COMPUTED_VALUE"""),"¢ Level") -> ¢ Level | J3: =IFERROR(__xludf.DUMMYFUNCTION("""COMPUTED_VALUE"""),"$ Level") -> $ Level | K3: =IFERROR(__xludf.DUMMYFUNCTION("""COMPUTED_VALUE"""),"¢ Level") -> ¢ Level | L3: =IFERROR(__xludf.DUMMYFUNCTION("""COMPUTED_VALUE"""),"$ Level") -> $ Level | M3: =IFERROR(__xludf.DUMMYFUNCTION("""COMPUTED_VALUE"""),"¢ Level") -> ¢ Level | N3: =IFERROR(__xludf.DUMMYFUNCTION("""COMPUTED_VALUE"""),"$ Level") -> $ Level | O3: =IFERROR(__xludf.DUMMYFUNCTION("""COMPUTED_VALUE"""),"¢ Level") -> ¢ Level | P3: =IFERROR(__xludf.DUMMYFUNCTION("""COMPUTED_VALUE"""),"$ Level") -> $ Level | Q3: =IFERROR(__xludf.DUMMYFUNCTION("""COMPUTED_VALUE"""),"Max") -> Max | T3: =IFERROR(__xludf.DUMMYFUNCTION("""COMPUTED_VALUE"""),"WS+") -> WS+ | U3: =IFERROR(__xludf.DUMMYFUNCTION("""COMPUTED_VALUE"""),"WS+") -> WS+ | V3: =IFERROR(__xludf.DUMMYFUNCTION("""COMPUTED_VALUE"""),"WS+") -> WS+ | W3: =IFERROR(__xludf.DUMMYFUNCTION("""COMPUTED_VALUE"""),"WS+") -> WS+ | X3: =IFERROR(__xludf.DUMMYFUNCTION("""COMPUTED_VALUE"""),"WS+") -> WS+ | Y3: =IFERROR(__xludf.DUMMYFUNCTION("""COMPUTED_VALUE"""),"Max") -> Max | AB3: =IFERROR(__xludf.DUMMYFUNCTION("""COMPUTED_VALUE"""),"Quantity") -> Quantity | AC3: =IFERROR(__xludf.DUMMYFUNCTION("""COMPUTED_VALUE"""),4.0) -> 4 | AD3: =IFERROR(__xludf.DUMMYFUNCTION("""COMPUTED_VALUE"""),"03 | #4 | Cost 150 ⧌ | Next 400 ⧌") -> 03 | #4 | Cost 150 ⧌ | Next 400 ⧌ | AE3: =IFERROR(__xludf.DUMMYFUNCTION("""COMPUTED_VALUE"""),"Attack Speed") -> Attack Speed | AF3: =IFERROR(__xludf.DUMMYFUNCTION("""COMPUTED_VALUE"""),7.0) -> 7 | AG3: =IFERROR(__xludf.DUMMYFUNCTION("""COMPUTED_VALUE"""),FALSE) -> FALSE | AH3: =IFERROR(__xludf.DUMMYFUNCTION("""COMPUTED_VALUE"""),"Enemy Balance") -> Enemy Balance | AI3: =IFERROR(__xludf.DUMMYFUNCTION("""COMPUTED_VALUE"""),"Attack Speed") -> Attack Speed | AM3: =IFERROR(__xludf.DUMMYFUNCTION("""COMPUTED_VALUE"""),"Event Relics") -> Event Relics | AN3: =IFERROR(__xludf.DUMMYFUNCTION("""COMPUTED_VALUE"""),112.0) -> 112 | AU3: =IFERROR(__xludf.DUMMYFUNCTION("""COMPUTED_VALUE"""),"Cooldown") -> Cooldown | AV3: =IFERROR(__xludf.DUMMYFUNCTION("""COMPUTED_VALUE"""),51.0) -> 51 | AW3: =IFERROR(__xludf.DUMMYFUNCTION("""COMPUTED_VALUE"""),"08 | 51s | Cost 380 ⧓ | Next 420 ⧓") -> 08 | 51s | Cost 380 ⧓ | Next 420 ⧓ | BB3: =IFERROR(__xludf.DUMMYFUNCTION("""COMPUTED_VALUE"""),"Rarity Cap") -> Rarity Cap | BC3: =IFERROR(__xludf.DUMMYFUNCTION("""COMPUTED_VALUE"""),"Epic") -> Epic | BG3: =IFERROR(__xludf.DUMMYFUNCTION("""COMPUTED_VALUE"""),"Rarity Cap") -> Rarity Cap | BH3: =IFERROR(__xludf.DUMMYFUNCTION("""COMPUTED_VALUE"""),"Epic") -> Epic | BL3: =IFERROR(__xludf.DUMMYFUNCTION("""COMPUTED_VALUE"""),"Rarity Cap") -> Rarity Cap | BM3: =IFERROR(__xludf.DUMMYFUNCTION("""COMPUTED_VALUE"""),"Epic") -> Epic | BQ3: =IFERROR(__xludf.DUMMYFUNCTION("""COMPUTED_VALUE"""),"Rarity Cap") -> Rarity Cap | BR3: =IFERROR(__xludf.DUMMYFUNCTION("""COMPUTED_VALUE"""),"Epic") -> Epic | BW3: =IFERROR(__xludf.DUMMYFUNCTION("""COMPUTED_VALUE"""),"Cooldown") -> Cooldown | BX3: =IFERROR(__xludf.DUMMYFUNCTION("""COMPUTED_VALUE"""),120.0) -> 120 | BY3: =IFERROR(__xludf.DUMMYFUNCTION("""COMPUTED_VALUE"""),"00 | 120s | Cost 0 ⧈ | Next 1 ⧈") -> 00 | 120s | Cost 0 ⧈ | Next 1 ⧈ | BZ3: =IFERROR(__xludf.DUMMYFUNCTION("""COMPUTED_VALUE"""),"Tier 1") -> Tier 1 | CA3: =IFERROR(__xludf.DUMMYFUNCTION("""COMPUTED_VALUE"""),10210.0) -> 10210 | CB3: =IFERROR(__xludf.DUMMYFUNCTION("""COMPUTED_VALUE"""),TRUE) -> TRUE | CD3: =IFERROR(__xludf.DUMMYFUNCTION("""COMPUTED_VALUE"""),"Player ID") -> Player ID | CE3: =IFERROR(__xludf.DUMMYFUNCTION("""COMPUTED_VALUE"""),"4C64DCF66976FD33") -> 4C64DCF66976FD33
