Workbook
Name MOD_ARMOR_INCREASE_ARRAY: DVT_Modules!$D$21:$D$30
Name DVT_Mod_Generator_Substats: DVT_Modules!$W$3:$W$29
Name MOD_GENERATOR_INCREASE_ARRAY: DVT_Modules!$E$21:$E$30
Name DVT_Mod_Cannon_Substats: DVT_Modules!$U$3:$U$29
Name MOD_STEPS_INCREASE_NEXT: DVT_Modules!$B$22:$B$31
Name MOD_CANNONS_LIST: DVT_Modules!$N$4:$N$79
Name MOD_BASE_STAT_ARRAY: DVT_Modules!$B$3:$F$17
Name LABS_LabLevel_Array: DVT_Laboratory!$A$3:$A$102
Name MOD_GENERATORS_LIST: DVT_Modules!$P$4:$P$79
Name MOD_CORES_LIST: DVT_Modules!$Q$4:$Q$79
Name DVT_Mod_SubStat_Value_Array: DVT_Modules!$Z$2:$AM$77
Name DVT_Mod_Core_Substats: DVT_Modules!$X$3:$X$29
Name DVT_Mod_Stat_Rarity: DVT_Modules!$T$3:$T$9
Name MOD_STEPS_INCREASE: DVT_Modules!$B$21:$B$30
Name DVT_Mod_Armor_Substats: DVT_Modules!$V$3:$V$29
Name DVT_Mod_Assist_Level: DVT_Modules!$K$2:$K$1000
Name MOD_ARMORS_LIST: DVT_Modules!$O$4:$O$79
Name MOD_CANNON_INCREASE_ARRAY: DVT_Modules!$C$21:$C$30
Name LABS_LabName_Array: DVT_Laboratory!$B$1:$LO$1
Name DVT_Mod_Base_Rarity_Uniques: DVT_Modules!$S$3:$S$15
Name DVT_Mod_Base_Rarity: DVT_Modules!$R$3:$R$18
Name LABS_LabSearchStartPoint: DVT_Laboratory!$B$3
Name MOD_CORE_INCREASE_ARRAY: DVT_Modules!$F$21:$F$30
Name LABDURATION_SINGLE_ADJUSTED: LAMBDA(lab_name, lab_level, DVT_LAB_DURATION(lab_name, lab_level) / LAB_SPEED_TOTAL())
Name IDS_MOD_CORE_SUBSTATS: LAMBDA(name, IFERROR(OFFSET('_IDS'!$BQ$31, MATCH(name, '_IDS'!$BQ$27:$BQ, 0)-1, 0, 8, 4)))
Name IDS_MOD_CANNON_ASSIST_SUBSTAT_CAP: LAMBDA('_IDS'!$BC$5)
Name IDS_MOD_ARMOR_ASSIST_NAME: LAMBDA(preset, OFFSET('_IDS'!$BH$9, MATCH(preset, '_IDS'!$BG$7:$BG$23, 0)-1, 0, 1, 1))
Name IDS_CARD_MASTERY: LAMBDA(card_name, VLOOKUP(card_name,'_IDS'!$AE$2:$AG, 3, FALSE))
Name IDS_MOD_CORE_BONUS: LAMBDA(name, OFFSET('_IDS'!$BS$29, MATCH(name, '_IDS'!$BQ$27:$BQ, 0)-1, 0, 1, 1))
Name IDS_BOT_LEVEL: LAMBDA(bot_name, bot_property, LET( off, (MATCH(bot_name, '_IDS'!$AS$2:$AS$17, 0) - 1), VLOOKUP(bot_property, OFFSET('_IDS'!$AU$2, off, 0, 4, 3), 3, FALSE) ))
Name IDS_PS_FARMING_TIER: LAMBDA('_IDS'!$CE$4)
Name IDS_MOD_GENERATOR_BONUS: LAMBDA(name, OFFSET('_IDS'!$BN$29, MATCH(name, '_IDS'!$BL$27:$BL, 0)-1, 0, 1, 1))
Name IDS_MOD_CORE_ASSIST_NAME: LAMBDA(preset, OFFSET('_IDS'!$BR$9, MATCH(preset, '_IDS'!$BQ$7:$BQ$23, 0)-1, 0, 1, 1))
Name IDS_MOD_GENERATOR_ASSIST_LEVEL: LAMBDA('_IDS'!$BN$2)
Name IDS_MOD_ARMOR_ASSIST_SUBSTAT_CAP: LAMBDA('_IDS'!$BH$5)
Name IDS_MOD_CANNON_ASSIST_MULT_CAP: LAMBDA('_IDS'!$BC$4)
Name IDS_MOD_GENERATOR_RARITY: LAMBDA(name, IFERROR(OFFSET('_IDS'!$BL$29, MATCH(name, '_IDS'!$BL$27:$BL, 0)-1, 0, 1, 1)))
Name IDS_WS_LEVEL: LAMBDA(ws_name, MAX(IDS_WS_COIN_LEVEL(ws_name), IDS_WS_CASH_LEVEL(ws_name)))
Name IDS_WS_PRESET_LEVEL: LAMBDA(preset, ws_name, MAX(IDS_WS_PRESET_COIN_LEVEL(preset, ws_name), IDS_WS_PRESET_CASH_LEVEL(preset, ws_name)))
Name LABDURATION_SINGLE_BASE: LAMBDA(lab_name, lab_level, XLOOKUP(lab_level,LABS_LabLevel_Array,OFFSET(LABS_LabSearchStartPoint,0,MATCH(lab_name,LABS_LabName_Array,0)-1,100,1),"N/F",0,1))
Name IDS_LAB_LEVEL: LAMBDA(lab_name, IF('_IDS'!$C$1="✅", VLOOKUP(lab_name, '_IDS'!$A$2:$B, 2, FALSE), 0))
Name IDS_MOD_ARMOR_ASSIST_MULT_CAP: LAMBDA('_IDS'!$BH$4)
Name IDS_CARD_PRESET: LAMBDA(preset, OFFSET('_IDS'!$AH$3, 0, MATCH(preset, '_IDS'!$AH$2:$AL$2, 0)-1, 27, 1))
Name DVT_MODULE_COINS_COST_CUMMULATIVE: LAMBDA(level, IF(level <= 1, 0, SUM(ARRAYFORMULA(DVT_MODULE_COINS_COST(ROW(INDIRECT("1:"&level)))))))
Name IDS_MOD_CORE_NAME: LAMBDA(preset, OFFSET('_IDS'!$BR$8, MATCH(preset, '_IDS'!$BQ$7:$BQ$23, 0)-1, 0, 1, 1))
Name IDS_CARD_LEVEL: LAMBDA(card_name, IF(VLOOKUP(card_name,'_IDS'!$AE$2:$AG$31, 2, FALSE)="Locked", 1, VLOOKUP(card_name,'_IDS'!$AE$2:$AG, 2, FALSE)))
Name IDS_MOD_ARMOR_ASSIST_LEVEL: LAMBDA('_IDS'!$BI$2)
Name IDS_MOD_CANNON_ASSIST_LEVEL: LAMBDA('_IDS'!$BD$2)
Name IDS_MOD_GENERATOR_ASSIST_SUBSTAT_CAP: LAMBDA('_IDS'!$BM$5)
Name IDS_PS_TIER_PB: LAMBDA(tiername, VLOOKUP(TierName, '_IDS'!$BZ$3:$CA, 2))
Name IDS_RELIC_STAT: LAMBDA(relic_stat, IFERROR(IF('_IDS'!$AO$1="✅", VLOOKUP(relic_stat,'_IDS'!$AM$2:$AN,2,FALSE), 0), 0))
Name IDS_MOD_CANNON_LEVEL: LAMBDA(name, OFFSET('_IDS'!$BC$29, MATCH(name, '_IDS'!$BB$27:$BB, 0)-1, 0, 1, 1))
Name DVT_MODULE_SHARDS_COST_CUMMULATIVE: LAMBDA(level, IF(level <=1, 0, SUM(ARRAYFORMULA(DVT_MODULE_SHARDS_COST(ROW(INDIRECT("1:"&level)))))))
Name IDS_MOD_GENERATOR_NAME: LAMBDA(preset, OFFSET('_IDS'!$BM$8, MATCH(preset, '_IDS'!$BL$7:$BL$23, 0)-1, 0, 1, 1))
Name IDS_MOD_GENERATOR_LEVEL: LAMBDA(name, OFFSET('_IDS'!$BM$29, MATCH(name, '_IDS'!$BL$27:$BL, 0)-1, 0, 1, 1))
Name IDS_BOT_OWN: LAMBDA(bot_name, LET( off, (MATCH(bot_name, '_IDS'!$AS$2:$AS$17, 0) - 1), OFFSET('_IDS'!$AS$5, off, 0, 1, 1) ))
Name LAB_SPEED_TOTAL: LAMBDA((1+('Master Sheet'!$C$3*0.02))*(1+'Master Sheet'!$G$2))
Name RELIC_STAT: LAMBDA(relic_name, IF(RelicValidation="✅", VLOOKUP(relic_name,'_IDS'!$A$1:$B,2,FALSE), 0))
Name IDS_UW_VALUE: LAMBDA(uw_name, uw_stat, LET( off, (MATCH(uw_name, '_IDS'!$Z$2:$Z$37, 0) - 1), VLOOKUP(uw_stat, OFFSET('_IDS'!$AB$2, off, 0, 4, 2), 2, FALSE) ))
Name IDS_MOD_ARMOR_NAME: LAMBDA(preset, OFFSET('_IDS'!$BH$8, MATCH(preset, '_IDS'!$BG$7:$BG$23, 0)-1, 0, 1, 1))

Sheet Home Page
B2: Modules
B4: =HYPERLINK("https://docs.google.com/spreadsheets/d/1KCxnSAvhstAbFdBSYSO_3bKUPtCFX42Eb7Z13agPU9s/copy", "Modules Initial Link") -> Modules Initial Link | G4: Sheet Tab | H4: Creator | I4: Main Contributor | J4: Helpers
G6: IDS | H6: @Mattew | I6: @Mattew | J6: @Bisse
B7: Latest remote version : | G7: Master Sheet | H7: @Mattew | I7: @Mattew | J7: @TC Team
B8: =IFERROR(__xludf.DUMMYFUNCTION("IMPORTRANGE(""1KCxnSAvhstAbFdBSYSO_3bKUPtCFX42Eb7Z13agPU9s"", ""'Home Page'!B12:C13"")"),"v5.13") -> v5.13 | C8: =IFERROR(__xludf.DUMMYFUNCTION("""COMPUTED_VALUE"""),"feat: Shattered epic tracker (@ghostofthecommentsection)") -> feat: Shattered epic tracker (@ghostofthecommentsection) | G8: Inventory | H8: @Shiriru94 | I8: @Shiriru94, @Mattew
B9: =IFERROR(__xludf.DUMMYFUNCTION("""COMPUTED_VALUE"""),"v5.12.1") -> v5.12.1 | C9: =IFERROR(__xludf.DUMMYFUNCTION("""COMPUTED_VALUE"""),"feat: Enhanced OAL button") -> feat: Enhanced OAL button | G9: Presets | H9: @Shiriru94, @Mattew | I9: @Mattew | J9: @Shiriru94
G10: Tracker | H10: @Audacious, @gtsum | I10: @Shiriru94 | J10: @Meringue
B11: Version Change : | G11: Reroll Calculator V3 | H11: @Freeman0916
B12: v5.13 | C12: feat: Shattered epic tracker (@ghostofthecommentsection) | G12: Optimal Assist levels | H12: @Eyethberg | I12: @Eyethberg | J12: @avacede
B13: v5.12.1 | C13: feat: Enhanced OAL button | G13: Shard Path | H13: @QuietFanta
B14: v5.12 | C14: feat: Optimal Assist Levels "Apply" button | G14: Overview | H14: @GodzillasDaddy
B15: v5.11.1 | C15: fix: Optimal Assist Levels fix for Assist Level = 0 | G15: Substats | H15: @kosmirionepos | I15: @Mattew
B16: v5.11 | C16: feat: Added Spare OA and Spare RB
B17: v5.10 | C17: feat: Minimum levels for Optimal Assist & performance improvements | G17: Tab colors explanation
B18: v5.9 | C18: feat: New Module: Orbital Augment
B19: v5.8 | C19: fix: Any Other 2 Substat values are grabbed | G19: Home Page | H19: Input Tabs | I19: Local Tools | J19: Static Data
B20: v5.7 | C20: feat: New Module: Restorative Bonus
B21: v5.6.4 | C21: fix: Optimal assist current now mults properly | G21: Related tools
B22: v5.6.3 | C22: feat: Optimal Assist Levels Multi update | G22: =HYPERLINK(IF('_IDS'!AB1="✅",'_IDS'!AF1, "https://docs.google.com/spreadsheets/d/1wVLlvWfmcjHRkAnQJzAQu_YZo_eW1FXMVTfYYQnF7Xc")&"#gid=2001828042", "RPC Mastery") -> RPC Mastery | H22: Shows Shard earning prediction
B23: v5.6.2 | C23: Fix: Level cap for Common, Rare, Rare+
B24: v5.6.1 | C24: fix: Shard Path (@Gladiator)
B25: v5.6 | C25: Add: Shard Path (@QuietFanta)
B26: v5.5.5 | C26: fix: dropdown for spare modules | G26: Enjoying those sheets? You can support me by using my creator code for any in game or webstore purchases. My creator code is : SHEETLORD
B27: v5.5.4 | C27: fix: #ref! and data validations
B28: v5.5.3 | C28: fix: Max Assist Level #ref!
B29: v5.5.2 | C29: fix: 7th substat export for SR and AS
B30: v5.5.1 | C30: Tracker: Fodder text bar improvements
B31: v5.5 | C31: Add: Amplifying Strike | G31: Want to support someone else ? Here is the creator code list
B32: v5.4.4 | C32: fix: Export Completion
B33: v5.4.3 | C33: fix: OAL not showing optimal levels | G33: =IFERROR(__xludf.DUMMYFUNCTION("IMPORTRANGE(""1eCPPuQOE3Pyh8HhnApEMK3RFIutkUjWd61ppVImwWk8"", ""_Giveaway_summary!A1:A2"")"),"⚠️ 1 Giveaway(s) running - 22 Mar") -> ⚠️ 1 Giveaway(s) running - 22 Mar
B34: v5.4.2 | C34: fix: Tracker showing correct merge instructions now | G34: =IFERROR(__xludf.DUMMYFUNCTION("""COMPUTED_VALUE"""),"Giveaway Details") -> Giveaway Details
B35: v5.4.1 | C35: fix: Optimal Assist Levels referencing only Cannon level
B36: v5.4 | C36: Tracker: 6th Mod series included
B37: v5.3 | C37: Add: Primordial Collapse
B38: v5.2.1 | C38: Internal changes / Renames
B39: v5.2 | C39: Add: Modules Overview Sheet
B40: v5.1.1 | C40: fix: Optimal Assist Levels n/a's and other references
B41: v5.1 | C41: Add: Optimal Assist Levels
B42: v5.0 | C42: IDS 2.0 + V27
B43: v4.7 | C43: Added Modules Tracker (hidden Mods Obtained)
...

Sheet IDS
B2: The IDS System | I2: Looking for the Import script ? Just run it as you were doing it before, but from IDS Master. It will let you import every new versions at once!
B4: This Sheet ID is : | C4: 1rOoSY6TK918myJ6Mn6zO4rmUaFbPu6qJnGI17kc9DzQ
B6: IDS Master's ID ➡️ | C6: 1HOIkxWbbciTIAzVruaahEGADlM8rS0-w86uBXj4PwNQ | D6: =IFERROR(__xludf.DUMMYFUNCTION("IFERROR(C6.url, IFS(LEFT(C6,8)=""https://"", C6, LEN(C6)=44, ""https://docs.google.com/spreadsheets/d/"" & C6 & ""/edit"", TRUE, C6))"),"https://docs.google.com/spreadsheets/d/1HOIkxWbbciTIAzVruaahEGADlM8rS0-w86uBXj4PwNQ/edit") -> https://docs.google.com/spreadsheets/d/1HOIkxWbbciTIAzVruaahEGADlM8rS0-w86uBXj4PwNQ/edit | E6: =IFERROR(__xludf.DUMMYFUNCTION("IF(D6<>"""", IF(IMPORTRANGE(D6,""EXPORT!A1"") = F6, ""✅"", ""Wrong ID or Version""), """")"),"✅") -> ✅ | F6: v2
B7: =HYPERLINK("https://docs.google.com/spreadsheets/d/1osjoqKmMwtOWs7Up3e21-3ofN1RHOjsgKV6y3dc6rgE/copy", "1️⃣ Copy Me") -> 1️⃣ Copy Me | C7: =IFS( ISERROR(E6), "3️⃣ Click on #REF! and then AUTHORISE ↗", E6="", "2️⃣ Please input your IDS Master's ID here ⤴️", E6="✅", HYPERLINK(D6, "Go to my IDS Master Sheet"), TRUE, "") -> Go to my IDS Master Sheet | E7: ✅ | I7: Issues
I8: Mobile Users If you are on mobile, you will not be able to do STEP 3. There is a workaround you can do still : You need to edit the viewing permissions to "anyone with the link" of all your IDs sheets If you have any other trouble, let us know in the #effective-path Discord's channel. I say us, but don't ask Fanta. Fanta hates IDS.
B9: How to use
B10: STEP 1: Click on the Copy Me link and create your copy of the IDS Master. STEP 2: Copy the ID (you will find it in the IDS page) of your newly created sheet and paste it in the light gray area. STEP 3: Wait a little bit, the F5 cell will show "Loading...", and after few seconds it will display "#REF!". Click on the cell, and "Authorize" to let this sheet access the other one.
B19: And that's it! The IDS are setuped. You can now fill sub IDS in the IDS Master with sub IDS sheets (Laboratory, Workshop, ...) just like you did in here. Every time you will change a value (let's say, a lab level in Laboratory Sheet) the change will be propagated to every other sheet using the IDS Master automatically.

Sheet Master Sheet
B1: =IF('_IDS'!C1="✅", HYPERLINK('_IDS'!B1, "Go to my Laboratory Sheet"), "Labs") -> Go to my Laboratory Sheet | C1: Level | D1: Max | F1: =IF('_IDS'!AO1="✅", HYPERLINK('_IDS'!AN1, "Go to my Relic Sheet"), "Relic") -> Go to my Relic Sheet | G1: Bonus
A2: LABS | B2: Labs Coin Discount | C2: =IDS_LAB_LEVEL(B2) -> 68 | D2: 99 | E2: VAULT TREE | F2: Lab Speed | G2: =IDS_RELIC_STAT(F2) -> 0.395
B3: Labs Speed | C3: =IDS_LAB_LEVEL(B3) -> 91 | D3: 99
B4: Package After Boss | C4: =IDS_LAB_LEVEL(B4) -> 1 | D4: =COUNTA(OFFSET(DVT_Laboratory!$B$3, 0, MATCH(A2,DVT_Laboratory!$B$1:I$1, 0)-1, 100, 1)) -> 1 | F4: =IF('_IDS'!AF1="✅", HYPERLINK('_IDS'!AE1, "Go to my Vault Sheet"), "Vault Upgrade") -> Vault Upgrade | G4: Bonus
B5: Recovery Package Chance | C5: =IDS_LAB_LEVEL(B5) -> 20 | D5: 20 | F5: Discount Rerolls | G5: =IDS_VAULT_STAT(F5) -> 0
B6: Recovery Package Chance Mastery | C6: =IDS_LAB_LEVEL(B6) -> 3 | D6: 9
B7: Common Drop Chance | C7: =IDS_LAB_LEVEL(B7) -> 10 | D7: 10
B8: Daily Mission Shards | C8: =IDS_LAB_LEVEL(B8) -> 50 | D8: 50
B9: Module Shards Cost | C9: =IDS_LAB_LEVEL(B9) -> 30 | D9: 30
B10: Rare Drop Chance | C10: =IDS_LAB_LEVEL(B10) -> 10 | D10: 10
B11: Shatter Shards | C11: =IDS_LAB_LEVEL(B11) -> 5 | D11: 5
B12: Cannon Effect Bans | C12: =IDS_LAB_LEVEL(B12) -> 0 | D12: 4
B13: Armor Effect Bans | C13: =IDS_LAB_LEVEL(B13) -> 2 | D13: 4
B14: Generator Effect Bans | C14: =IDS_LAB_LEVEL(B14) -> 1 | D14: 3
B15: Core Effect Bans | C15: =IDS_LAB_LEVEL(B15) -> 4 | D15: 7
B16: Assist Module Bonus - Cannon | C16: =IDS_LAB_LEVEL(B16) -> 0 | D16: 30
B17: Assist Module Bonus - Armor | C17: =IDS_LAB_LEVEL(B17) -> 0 | D17: 30
... B19: Assist Module Bonus - Core | C19: =IDS_LAB_LEVEL(B19) -> 0 | D19: 30

Sheet Inventory
F1: Module Inventory
A3: 🔵 CANNON | F3: Astral Deliverance | K3: Being Annihilator | P3: Death Penalty | U3: Havoc Bringer | Z3: Shrink Ray | AE3: Amplifying Strike | AJ3: Any Other | AO3: Any Other 2
D4: Highest Level | F4: Rarity | G4: Level | H4: Stat | K4: Rarity | L4: Level | M4: Stat | P4: Rarity | Q4: Level | R4: Stat | U4: Rarity | V4: Level | W4: Stat | Z4: Rarity | AA4: Level | AB4: Stat | AE4: Rarity | AF4: Level | AG4: Stat | AJ4: Rarity | AK4: Level | AL4: Stat | AO4: Rarity | AP4: Level | AQ4: Stat
B5: Tower Damage | D5: 164 | F5: Mythic+ | G5: =CAP_MOD_LEVEL($D5,F5) -> 160 | H5: =IF(F5="None",1,MODSTAT_CANNON(F5,G5)) -> 8.19 | K5: Ancestral | L5: =CAP_MOD_LEVEL($D5,K5) -> 164 | M5: =IF(K5="None",1,MODSTAT_CANNON(K5,L5)) -> 9.04 | P5: Mythic+ | Q5: =CAP_MOD_LEVEL($D5,P5) -> 160 | R5: =IF(P5="None",1,MODSTAT_CANNON(P5,Q5)) -> 8.19 | U5: Ancestral | V5: =CAP_MOD_LEVEL($D5,U5) -> 164 | W5: =IF(U5="None",1,MODSTAT_CANNON(U5,V5)) -> 9.04 | Z5: Legendary | AA5: =CAP_MOD_LEVEL($D5,Z5) -> 100 | AB5: =IF(Z5="None",1,MODSTAT_CANNON(Z5,AA5)) -> 2.27 | AE5: Ancestral | AF5: =CAP_MOD_LEVEL($D5,AE5) -> 164 | AG5: =IF(AE5="None",1,MODSTAT_CANNON(AE5,AF5)) -> 9.04 | AJ5: Epic | AK5: =CAP_MOD_LEVEL($D5,AJ5) -> 60 | AL5: =IF(AJ5="None",1,MODSTAT_CANNON(AJ5,AK5)) -> 1.37 | AO5: Common | AP5: =CAP_MOD_LEVEL($D5,AO5) -> 20 | AQ5: =IF(AO5="None",1,MODSTAT_CANNON(AO5,AP5)) -> 1.05
D7: Assist Level | H7: =MOD_SUBSTAT_LOOKUP(F7,G7,1) | I7: =IF(ISBLANK(F7), "", MOD_SUBSTAT_LOOKUP(F7,G7,0)) | K7: Attack Speed | L7: Mythic | M7: =MOD_SUBSTAT_LOOKUP(K7,L7,1) -> +3 | N7: =IF(ISBLANK(K7), "", MOD_SUBSTAT_LOOKUP(K7,L7,0)) -> 3 | P7: MultiShot Chance | Q7: Mythic | R7: =MOD_SUBSTAT_LOOKUP(P7,Q7,1) -> +10% | S7: =IF(ISBLANK(P7), "", MOD_SUBSTAT_LOOKUP(P7,Q7,0)) -> 0.1 | W7: =MOD_SUBSTAT_LOOKUP(U7,V7,1) | X7: =IF(ISBLANK(U7), "", MOD_SUBSTAT_LOOKUP(U7,V7,0)) | AB7: =MOD_SUBSTAT_LOOKUP(Z7,AA7,1) | AC7: =IF(ISBLANK(Z7), "", MOD_SUBSTAT_LOOKUP(Z7,AA7,0)) | AE7: Bounce Shot Chance | AF7: Mythic | AG7: =MOD_SUBSTAT_LOOKUP(AE7,AF7,1) -> +9% | AH7: =IF(ISBLANK(AE7), "", MOD_SUBSTAT_LOOKUP(AE7,AF7,0)) -> 0.09 | AL7: =MOD_SUBSTAT_LOOKUP(AJ7,AK7,1) | AM7: =IF(ISBLANK(AJ7), "", MOD_SUBSTAT_LOOKUP(AJ7,AK7,0)) | AQ7: =MOD_SUBSTAT_LOOKUP(AO7,AP7,1) | AR7: =IF(ISBLANK(AO7), "", MOD_SUBSTAT_LOOKUP(AO7,AP7,0))
D8: 0 | H8: =MOD_SUBSTAT_LOOKUP(F8,G8,1) | I8: =IF(ISBLANK(F8), "", MOD_SUBSTAT_LOOKUP(F8,G8,0)) | K8: Multishot Targets | L8: Mythic | M8: =MOD_SUBSTAT_LOOKUP(K8,L8,1) -> +3 | N8: =IF(ISBLANK(K8), "", MOD_SUBSTAT_LOOKUP(K8,L8,0)) -> 3 | P8: Bounce Shot Chance | Q8: Mythic | R8: =MOD_SUBSTAT_LOOKUP(P8,Q8,1) -> +9% | S8: =IF(ISBLANK(P8), "", MOD_SUBSTAT_LOOKUP(P8,Q8,0)) -> 0.09 | W8: =MOD_SUBSTAT_LOOKUP(U8,V8,1) | X8: =IF(ISBLANK(U8), "", MOD_SUBSTAT_LOOKUP(U8,V8,0)) | AB8: =MOD_SUBSTAT_LOOKUP(Z8,AA8,1) | AC8: =IF(ISBLANK(Z8), "", MOD_SUBSTAT_LOOKUP(Z8,AA8,0)) | AE8: Attack Speed | AF8: Mythic | AG8: =MOD_SUBSTAT_LOOKUP(AE8,AF8,1) -> +3 | AH8: =IF(ISBLANK(AE8), "", MOD_SUBSTAT_LOOKUP(AE8,AF8,0)) -> 3 | AL8: =MOD_SUBSTAT_LOOKUP(AJ8,AK8,1) | AM8: =IF(ISBLANK(AJ8), "", MOD_SUBSTAT_LOOKUP(AJ8,AK8,0)) | AQ8: =MOD_SUBSTAT_LOOKUP(AO8,AP8,1) | AR8: =IF(ISBLANK(AO8), "", MOD_SUBSTAT_LOOKUP(AO8,AP8,0))
H9: =MOD_SUBSTAT_LOOKUP(F9,G9,1) | I9: =IF(ISBLANK(F9), "", MOD_SUBSTAT_LOOKUP(F9,G9,0)) | K9: Critical Factor | L9: Mythic | M9: =MOD_SUBSTAT_LOOKUP(K9,L9,1) -> +12x | N9: =IF(ISBLANK(K9), "", MOD_SUBSTAT_LOOKUP(K9,L9,0)) -> 12 | P9: Bounce Shot Targets | Q9: Mythic | R9: =MOD_SUBSTAT_LOOKUP(P9,Q9,1) -> +3 | S9: =IF(ISBLANK(P9), "", MOD_SUBSTAT_LOOKUP(P9,Q9,0)) -> 3 | W9: =MOD_SUBSTAT_LOOKUP(U9,V9,1) | X9: =IF(ISBLANK(U9), "", MOD_SUBSTAT_LOOKUP(U9,V9,0)) | AB9: =MOD_SUBSTAT_LOOKUP(Z9,AA9,1) | AC9: =IF(ISBLANK(Z9), "", MOD_SUBSTAT_LOOKUP(Z9,AA9,0)) | AE9: Multishot Targets | AF9: Ancestral | AG9: =MOD_SUBSTAT_LOOKUP(AE9,AF9,1) -> +4 | AH9: =IF(ISBLANK(AE9), "", MOD_SUBSTAT_LOOKUP(AE9,AF9,0)) -> 4 | AL9: =MOD_SUBSTAT_LOOKUP(AJ9,AK9,1) | AM9: =IF(ISBLANK(AJ9), "", MOD_SUBSTAT_LOOKUP(AJ9,AK9,0)) | AQ9: =MOD_SUBSTAT_LOOKUP(AO9,AP9,1) | AR9: =IF(ISBLANK(AO9), "", MOD_SUBSTAT_LOOKUP(AO9,AP9,0))
H10: =MOD_SUBSTAT_LOOKUP(F10,G10,1) | I10: =IF(ISBLANK(F10), "", MOD_SUBSTAT_LOOKUP(F10,G10,0)) | K10: Bounce Shot Chance | L10: Mythic | M10: =MOD_SUBSTAT_LOOKUP(K10,L10,1) -> +9% | N10: =IF(ISBLANK(K10), "", MOD_SUBSTAT_LOOKUP(K10,L10,0)) -> 0.09 | P10: Multishot Targets | Q10: Mythic | R10: =MOD_SUBSTAT_LOOKUP(P10,Q10,1) -> +3 | S10: =IF(ISBLANK(P10), "", MOD_SUBSTAT_LOOKUP(P10,Q10,0)) -> 3 | W10: =MOD_SUBSTAT_LOOKUP(U10,V10,1) | X10: =IF(ISBLANK(U10), "", MOD_SUBSTAT_LOOKUP(U10,V10,0)) | AB10: =MOD_SUBSTAT_LOOKUP(Z10,AA10,1) | AC10: =IF(ISBLANK(Z10), "", MOD_SUBSTAT_LOOKUP(Z10,AA10,0)) | AE10: Critical Factor | AF10: Ancestral | AG10: =MOD_SUBSTAT_LOOKUP(AE10,AF10,1) -> +15x | AH10: =IF(ISBLANK(AE10), "", MOD_SUBSTAT_LOOKUP(AE10,AF10,0)) -> 15 | AL10: =MOD_SUBSTAT_LOOKUP(AJ10,AK10,1) | AM10: =IF(ISBLANK(AJ10), "", MOD_SUBSTAT_LOOKUP(AJ10,AK10,0)) | AQ10: =MOD_SUBSTAT_LOOKUP(AO10,AP10,1) | AR10: =IF(ISBLANK(AO10), "", MOD_SUBSTAT_LOOKUP(AO10,AP10,0))
H11: =MOD_SUBSTAT_LOOKUP(F11,G11,1) | I11: =IF(ISBLANK(F11), "", MOD_SUBSTAT_LOOKUP(F11,G11,0)) | M11: =MOD_SUBSTAT_LOOKUP(K11,L11,1) | N11: =IF(ISBLANK(K11), "", MOD_SUBSTAT_LOOKUP(K11,L11,0)) | R11: =MOD_SUBSTAT_LOOKUP(P11,Q11,1) | S11: =IF(ISBLANK(P11), "", MOD_SUBSTAT_LOOKUP(P11,Q11,0)) | W11: =MOD_SUBSTAT_LOOKUP(U11,V11,1) | X11: =IF(ISBLANK(U11), "", MOD_SUBSTAT_LOOKUP(U11,V11,0)) | AB11: =MOD_SUBSTAT_LOOKUP(Z11,AA11,1) | AC11: =IF(ISBLANK(Z11), "", MOD_SUBSTAT_LOOKUP(Z11,AA11,0)) | AE11: Super Crit Multi | AF11: Mythic | AG11: =MOD_SUBSTAT_LOOKUP(AE11,AF11,1) -> +5x | AH11: =IF(ISBLANK(AE11), "", MOD_SUBSTAT_LOOKUP(AE11,AF11,0)) -> 5 | AL11: =MOD_SUBSTAT_LOOKUP(AJ11,AK11,1) | AM11: =IF(ISBLANK(AJ11), "", MOD_SUBSTAT_LOOKUP(AJ11,AK11,0)) | AQ11: =MOD_SUBSTAT_LOOKUP(AO11,AP11,1) | AR11: =IF(ISBLANK(AO11), "", MOD_SUBSTAT_LOOKUP(AO11,AP11,0))
H12: =MOD_SUBSTAT_LOOKUP(F12,G12,1) | I12: =IF(ISBLANK(F12), "", MOD_SUBSTAT_LOOKUP(F12,G12,0)) | M12: =MOD_SUBSTAT_LOOKUP(K12,L12,1) | N12: =IF(ISBLANK(K12), "", MOD_SUBSTAT_LOOKUP(K12,L12,0)) | R12: =MOD_SUBSTAT_LOOKUP(P12,Q12,1) | S12: =IF(ISBLANK(P12), "", MOD_SUBSTAT_LOOKUP(P12,Q12,0)) | W12: =MOD_SUBSTAT_LOOKUP(U12,V12,1) | X12: =IF(ISBLANK(U12), "", MOD_SUBSTAT_LOOKUP(U12,V12,0)) | AB12: =MOD_SUBSTAT_LOOKUP(Z12,AA12,1) | AC12: =IF(ISBLANK(Z12), "", MOD_SUBSTAT_LOOKUP(Z12,AA12,0)) | AG12: =MOD_SUBSTAT_LOOKUP(AE12,AF12,1) | AH12: =IF(ISBLANK(AE12), "", MOD_SUBSTAT_LOOKUP(AE12,AF12,0)) | AL12: =MOD_SUBSTAT_LOOKUP(AJ12,AK12,1) | AM12: =IF(ISBLANK(AJ12), "", MOD_SUBSTAT_LOOKUP(AJ12,AK12,0)) | AQ12: =MOD_SUBSTAT_LOOKUP(AO12,AP12,1) | AR12: =IF(ISBLANK(AO12), "", MOD_SUBSTAT_LOOKUP(AO12,AP12,0))
H13: =MOD_SUBSTAT_LOOKUP(F13,G13,1) | I13: =IF(ISBLANK(F13), "", MOD_SUBSTAT_LOOKUP(F13,G13,0)) | M13: =MOD_SUBSTAT_LOOKUP(K13,L13,1) | N13: =IF(ISBLANK(K13), "", MOD_SUBSTAT_LOOKUP(K13,L13,0)) | R13: =MOD_SUBSTAT_LOOKUP(P13,Q13,1) | S13: =IF(ISBLANK(P13), "", MOD_SUBSTAT_LOOKUP(P13,Q13,0)) | W13: =MOD_SUBSTAT_LOOKUP(U13,V13,1) | X13: =IF(ISBLANK(U13), "", MOD_SUBSTAT_LOOKUP(U13,V13,0)) | AB13: =MOD_SUBSTAT_LOOKUP(Z13,AA13,1) | AC13: =IF(ISBLANK(Z13), "", MOD_SUBSTAT_LOOKUP(Z13,AA13,0)) | AG13: =MOD_SUBSTAT_LOOKUP(AE13,AF13,1) | AH13: =IF(ISBLANK(AE13), "", MOD_SUBSTAT_LOOKUP(AE13,AF13,0)) | AL13: =MOD_SUBSTAT_LOOKUP(AJ13,AK13,1) | AM13: =IF(ISBLANK(AJ13), "", MOD_SUBSTAT_LOOKUP(AJ13,AK13,0)) | AQ13: =MOD_SUBSTAT_LOOKUP(AO13,AP13,1) | AR13: =IF(ISBLANK(AO13), "", MOD_SUBSTAT_LOOKUP(AO13,AP13,0))
H14: =MOD_SUBSTAT_LOOKUP(F14,G14,1) | I14: =IF(ISBLANK(F14), "", MOD_SUBSTAT_LOOKUP(F14,G14,0)) | M14: =MOD_SUBSTAT_LOOKUP(K14,L14,1) | N14: =IF(ISBLANK(K14), "", MOD_SUBSTAT_LOOKUP(K14,L14,0)) | R14: =MOD_SUBSTAT_LOOKUP(P14,Q14,1) | S14: =IF(ISBLANK(P14), "", MOD_SUBSTAT_LOOKUP(P14,Q14,0)) | W14: =MOD_SUBSTAT_LOOKUP(U14,V14,1) | X14: =IF(ISBLANK(U14), "", MOD_SUBSTAT_LOOKUP(U14,V14,0)) | AB14: =MOD_SUBSTAT_LOOKUP(Z14,AA14,1) | AC14: =IF(ISBLANK(Z14), "", MOD_SUBSTAT_LOOKUP(Z14,AA14,0)) | AG14: =MOD_SUBSTAT_LOOKUP(AE14,AF14,1) | AH14: =IF(ISBLANK(AE14), "", MOD_SUBSTAT_LOOKUP(AE14,AF14,0)) | AL14: =MOD_SUBSTAT_LOOKUP(AJ14,AK14,1) | AM14: =IF(ISBLANK(AJ14), "", MOD_SUBSTAT_LOOKUP(AJ14,AK14,0)) | AQ14: =MOD_SUBSTAT_LOOKUP(AO14,AP14,1) | AR14: =IF(ISBLANK(AO14), "", MOD_SUBSTAT_LOOKUP(AO14,AP14,0))
A16: 🟥 ARMOR | F16: Anti-Cube Portal | K16: Negative Mass Projector | P16: Space Displacer | U16: Wormhole Redirector | Z16: Sharp Fortitude | AE16: Orbital Augment | AJ16: Any Other | AO16: Any Other 2
D17: Highest Level | F17: Rarity | G17: Level | H17: Stat | K17: Rarity | L17: Level | M17: Stat | P17: Rarity | Q17: Level | R17: Stat | U17: Rarity | V17: Level | W17: Stat | Z17: Rarity | AA17: Level | AB17: Stat | AE17: Rarity | AF17: Level | AG17: Stat | AJ17: Rarity | AK17: Level | AL17: Stat | AO17: Rarity | AP17: Level | AQ17: Stat
B18: Tower Health | D18: 163 | F18: Mythic+ | G18: =CAP_MOD_LEVEL($D18,F18) -> 160 | H18: =IF(F18="None",1,MODSTAT_ARMOR(F18,G18)) -> 8.19 | K18: Legendary | L18: =CAP_MOD_LEVEL($D18,K18) -> 100 | M18: =IF(K18="None",1,MODSTAT_ARMOR(K18,L18)) -> 2.27 | P18: Ancestral 2* | Q18: =CAP_MOD_LEVEL($D18,P18) -> 163 | R18: =IF(P18="None",1,MODSTAT_ARMOR(P18,Q18)) -> 9.467 | U18: Mythic+ | V18: =CAP_MOD_LEVEL($D18,U18) -> 160 | W18: =IF(U18="None",1,MODSTAT_ARMOR(U18,V18)) -> 8.19 | Z18: Ancestral | AA18: =CAP_MOD_LEVEL($D18,Z18) -> 163 | AB18: =IF(Z18="None",1,MODSTAT_ARMOR(Z18,AA18)) -> 8.84 | AE18: Ancestral 1* | AF18: =CAP_MOD_LEVEL($D18,AE18) -> 163 | AG18: =IF(AE18="None",1,MODSTAT_ARMOR(AE18,AF18)) -> 9.154 | AJ18: Epic | AK18: =CAP_MOD_LEVEL($D18,AJ18) -> 60 | AL18: =IF(AJ18="None",1,MODSTAT_ARMOR(AJ18,AK18)) -> 1.37 | AO18: Common | AP18: =CAP_MOD_LEVEL($D18,AO18) -> 20 | AQ18: =IF(AO18="None",1,MODSTAT_ARMOR(AO18,AP18)) -> 1.05
D20: Assist Level | F20: Orb Speed | G20: Legendary | H20: =MOD_SUBSTAT_LOOKUP(F20,G20,1) -> +1.5 | I20: =IF(ISBLANK(F20), "", MOD_SUBSTAT_LOOKUP(F20,G20,0)) -> 1.5 | M20: =MOD_SUBSTAT_LOOKUP(K20,L20,1) | N20: =IF(ISBLANK(K20), "", MOD_SUBSTAT_LOOKUP(K20,L20,0)) | R20: =MOD_SUBSTAT_LOOKUP(P20,Q20,1) | S20: =IF(ISBLANK(P20), "", MOD_SUBSTAT_LOOKUP(P20,Q20,0)) | U20: Defense % | V20: Legendary | W20: =MOD_SUBSTAT_LOOKUP(U20,V20,1) -> +5% | X20: =IF(ISBLANK(U20), "", MOD_SUBSTAT_LOOKUP(U20,V20,0)) -> 0.05 | Z20: Health Regen | AA20: Ancestral | AB20: =MOD_SUBSTAT_LOOKUP(Z20,AA20,1) -> +400% | AC20: =IF(ISBLANK(Z20), "", MOD_SUBSTAT_LOOKUP(Z20,AA20,0)) -> 4 | AE20: Defense % | AF20: Ancestral | AG20: =MOD_SUBSTAT_LOOKUP(AE20,AF20,1) -> +8% | AH20: =IF(ISBLANK(AE20), "", MOD_SUBSTAT_LOOKUP(AE20,AF20,0)) -> 0.08 | AL20: =MOD_SUBSTAT_LOOKUP(AJ20,AK20,1) | AM20: =IF(ISBLANK(AJ20), "", MOD_SUBSTAT_LOOKUP(AJ20,AK20,0)) | AQ20: =MOD_SUBSTAT_LOOKUP(AO20,AP20,1) | AR20: =IF(ISBLANK(AO20), "", MOD_SUBSTAT_LOOKUP(AO20,AP20,0))
D21: 41 | F21: Shockwave Size | G21: Legendary | H21: =MOD_SUBSTAT_LOOKUP(F21,G21,1) -> +0.3 | I21: =IF(ISBLANK(F21), "", MOD_SUBSTAT_LOOKUP(F21,G21,0)) -> 0.3 | M21: =MOD_SUBSTAT_LOOKUP(K21,L21,1) | N21: =IF(ISBLANK(K21), "", MOD_SUBSTAT_LOOKUP(K21,L21,0)) | R21: =MOD_SUBSTAT_LOOKUP(P21,Q21,1) | S21: =IF(ISBLANK(P21), "", MOD_SUBSTAT_LOOKUP(P21,Q21,0)) | U21: Wall Health | V21: Legendary | W21: =MOD_SUBSTAT_LOOKUP(U21,V21,1) -> +40% | X21: =IF(ISBLANK(U21), "", MOD_SUBSTAT_LOOKUP(U21,V21,0)) -> 0.4 | Z21: Knockback Force | AA21: Mythic | AB21: =MOD_SUBSTAT_LOOKUP(Z21,AA21,1) -> +0.9 | AC21: =IF(ISBLANK(Z21), "", MOD_SUBSTAT_LOOKUP(Z21,AA21,0)) -> 0.9 | AE21: Health Regen | AF21: Ancestral | AG21: =MOD_SUBSTAT_LOOKUP(AE21,AF21,1) -> +400% | AH21: =IF(ISBLANK(AE21), "", MOD_SUBSTAT_LOOKUP(AE21,AF21,0)) -> 4 | AL21: =MOD_SUBSTAT_LOOKUP(AJ21,AK21,1) | AM21: =IF(ISBLANK(AJ21), "", MOD_SUBSTAT_LOOKUP(AJ21,AK21,0)) | AQ21: =MOD_SUBSTAT_LOOKUP(AO21,AP21,1) | AR21: =IF(ISBLANK(AO21), "", MOD_SUBSTAT_LOOKUP(AO21,AP21,0))
F22: Death Defy | G22: Legendary | H22: =MOD_SUBSTAT_LOOKUP(F22,G22,1) -> +1.5% | I22: =IF(ISBLANK(F22), "", MOD_SUBSTAT_LOOKUP(F22,G22,0)) -> 0.015 | M22: =MOD_SUBSTAT_LOOKUP(K22,L22,1) | N22: =IF(ISBLANK(K22), "", MOD_SUBSTAT_LOOKUP(K22,L22,0)) | R22: =MOD_SUBSTAT_LOOKUP(P22,Q22,1) | S22: =IF(ISBLANK(P22), "", MOD_SUBSTAT_LOOKUP(P22,Q22,0)) | U22: Health Regen | V22: Legendary | W22: =MOD_SUBSTAT_LOOKUP(U22,V22,1) -> +100% | X22: =IF(ISBLANK(U22), "", MOD_SUBSTAT_LOOKUP(U22,V22,0)) -> 1 | Z22: Defense % | AA22: Ancestral | AB22: =MOD_SUBSTAT_LOOKUP(Z22,AA22,1) -> +8% | AC22: =IF(ISBLANK(Z22), "", MOD_SUBSTAT_LOOKUP(Z22,AA22,0)) -> 0.08 | AE22: Wall Health | AF22: Ancestral | AG22: =MOD_SUBSTAT_LOOKUP(AE22,AF22,1) -> +120% | AH22: =IF(ISBLANK(AE22), "", MOD_SUBSTAT_LOOKUP(AE22,AF22,0)) -> 1.2 | AL22: =MOD_SUBSTAT_LOOKUP(AJ22,AK22,1) | AM22: =IF(ISBLANK(AJ22), "", MOD_SUBSTAT_LOOKUP(AJ22,AK22,0)) | AQ22: =MOD_SUBSTAT_LOOKUP(AO22,AP22,1) | AR22: =IF(ISBLANK(AO22), "", MOD_SUBSTAT_LOOKUP(AO22,AP22,0))
H23: =MOD_SUBSTAT_LOOKUP(F23,G23,1) | I23: =IF(ISBLANK(F23), "", MOD_SUBSTAT_LOOKUP(F23,G23,0)) | M23: =MOD_SUBSTAT_LOOKUP(K23,L23,1) | N23: =IF(ISBLANK(K23), "", MOD_SUBSTAT_LOOKUP(K23,L23,0)) | R23: =MOD_SUBSTAT_LOOKUP(P23,Q23,1) | S23: =IF(ISBLANK(P23), "", MOD_SUBSTAT_LOOKUP(P23,Q23,0)) | W23: =MOD_SUBSTAT_LOOKUP(U23,V23,1) | X23: =IF(ISBLANK(U23), "", MOD_SUBSTAT_LOOKUP(U23,V23,0)) | Z23: Wall Health | AA23: Ancestral | AB23: =MOD_SUBSTAT_LOOKUP(Z23,AA23,1) -> +120% | AC23: =IF(ISBLANK(Z23), "", MOD_SUBSTAT_LOOKUP(Z23,AA23,0)) -> 1.2 | AE23: Thorns Damage | AF23: Ancestral | AG23: =MOD_SUBSTAT_LOOKUP(AE23,AF23,1) -> +10% | AH23: =IF(ISBLANK(AE23), "", MOD_SUBSTAT_LOOKUP(AE23,AF23,0)) -> 0.1 | AL23: =MOD_SUBSTAT_LOOKUP(AJ23,AK23,1) | AM23: =IF(ISBLANK(AJ23), "", MOD_SUBSTAT_LOOKUP(AJ23,AK23,0)) | AQ23: =MOD_SUBSTAT_LOOKUP(AO23,AP23,1) | AR23: =IF(ISBLANK(AO23), "", MOD_SUBSTAT_LOOKUP(AO23,AP23,0))
H24: =MOD_SUBSTAT_LOOKUP(F24,G24,1) | I24: =IF(ISBLANK(F24), "", MOD_SUBSTAT_LOOKUP(F24,G24,0)) | M24: =MOD_SUBSTAT_LOOKUP(K24,L24,1) | N24: =IF(ISBLANK(K24), "", MOD_SUBSTAT_LOOKUP(K24,L24,0)) | R24: =MOD_SUBSTAT_LOOKUP(P24,Q24,1) | S24: =IF(ISBLANK(P24), "", MOD_SUBSTAT_LOOKUP(P24,Q24,0)) | W24: =MOD_SUBSTAT_LOOKUP(U24,V24,1) | X24: =IF(ISBLANK(U24), "", MOD_SUBSTAT_LOOKUP(U24,V24,0)) | Z24: Thorns Damage | AA24: Ancestral | AB24: =MOD_SUBSTAT_LOOKUP(Z24,AA24,1) -> +10% | AC24: =IF(ISBLANK(Z24), "", MOD_SUBSTAT_LOOKUP(Z24,AA24,0)) -> 0.1 | AG24: =MOD_SUBSTAT_LOOKUP(AE24,AF24,1) | AH24: =IF(ISBLANK(AE24), "", MOD_SUBSTAT_LOOKUP(AE24,AF24,0)) | AL24: =MOD_SUBSTAT_LOOKUP(AJ24,AK24,1) | AM24: =IF(ISBLANK(AJ24), "", MOD_SUBSTAT_LOOKUP(AJ24,AK24,0)) | AQ24: =MOD_SUBSTAT_LOOKUP(AO24,AP24,1) | AR24: =IF(ISBLANK(AO24), "", MOD_SUBSTAT_LOOKUP(AO24,AP24,0))
H25: =MOD_SUBSTAT_LOOKUP(F25,G25,1) | I25: =IF(ISBLANK(F25), "", MOD_SUBSTAT_LOOKUP(F25,G25,0)) | M25: =MOD_SUBSTAT_LOOKUP(K25,L25,1) | N25: =IF(ISBLANK(K25), "", MOD_SUBSTAT_LOOKUP(K25,L25,0)) | R25: =MOD_SUBSTAT_LOOKUP(P25,Q25,1) | S25: =IF(ISBLANK(P25), "", MOD_SUBSTAT_LOOKUP(P25,Q25,0)) | W25: =MOD_SUBSTAT_LOOKUP(U25,V25,1) | X25: =IF(ISBLANK(U25), "", MOD_SUBSTAT_LOOKUP(U25,V25,0)) | Z25: Orb Speed | AA25: Epic | AB25: =MOD_SUBSTAT_LOOKUP(Z25,AA25,1) -> +1 | AC25: =IF(ISBLANK(Z25), "", MOD_SUBSTAT_LOOKUP(Z25,AA25,0)) -> 1 | AG25: =MOD_SUBSTAT_LOOKUP(AE25,AF25,1) | AH25: =IF(ISBLANK(AE25), "", MOD_SUBSTAT_LOOKUP(AE25,AF25,0)) | AL25: =MOD_SUBSTAT_LOOKUP(AJ25,AK25,1) | AM25: =IF(ISBLANK(AJ25), "", MOD_SUBSTAT_LOOKUP(AJ25,AK25,0)) | AQ25: =MOD_SUBSTAT_LOOKUP(AO25,AP25,1) | AR25: =IF(ISBLANK(AO25), "", MOD_SUBSTAT_LOOKUP(AO25,AP25,0))
H26: =MOD_SUBSTAT_LOOKUP(F26,G26,1) | I26: =IF(ISBLANK(F26), "", MOD_SUBSTAT_LOOKUP(F26,G26,0)) | M26: =MOD_SUBSTAT_LOOKUP(K26,L26,1) | N26: =IF(ISBLANK(K26), "", MOD_SUBSTAT_LOOKUP(K26,L26,0)) | R26: =MOD_SUBSTAT_LOOKUP(P26,Q26,1) | S26: =IF(ISBLANK(P26), "", MOD_SUBSTAT_LOOKUP(P26,Q26,0)) | W26: =MOD_SUBSTAT_LOOKUP(U26,V26,1) | X26: =IF(ISBLANK(U26), "", MOD_SUBSTAT_LOOKUP(U26,V26,0)) | AB26: =MOD_SUBSTAT_LOOKUP(Z26,AA26,1) | AC26: =IF(ISBLANK(Z26), "", MOD_SUBSTAT_LOOKUP(Z26,AA26,0)) | AG26: =MOD_SUBSTAT_LOOKUP(AE26,AF26,1) | AH26: =IF(ISBLANK(AE26), "", MOD_SUBSTAT_LOOKUP(AE26,AF26,0)) | AL26: =MOD_SUBSTAT_LOOKUP(AJ26,AK26,1) | AM26: =IF(ISBLANK(AJ26), "", MOD_SUBSTAT_LOOKUP(AJ26,AK26,0)) | AQ26: =MOD_SUBSTAT_LOOKUP(AO26,AP26,1) | AR26: =IF(ISBLANK(AO26), "", MOD_SUBSTAT_LOOKUP(AO26,AP26,0))
H27: =MOD_SUBSTAT_LOOKUP(F27,G27,1) | I27: =IF(ISBLANK(F27), "", MOD_SUBSTAT_LOOKUP(F27,G27,0)) | M27: =MOD_SUBSTAT_LOOKUP(K27,L27,1) | N27: =IF(ISBLANK(K27), "", MOD_SUBSTAT_LOOKUP(K27,L27,0)) | R27: =MOD_SUBSTAT_LOOKUP(P27,Q27,1) | S27: =IF(ISBLANK(P27), "", MOD_SUBSTAT_LOOKUP(P27,Q27,0)) | W27: =MOD_SUBSTAT_LOOKUP(U27,V27,1) | X27: =IF(ISBLANK(U27), "", MOD_SUBSTAT_LOOKUP(U27,V27,0)) | AB27: =MOD_SUBSTAT_LOOKUP(Z27,AA27,1) | AC27: =IF(ISBLANK(Z27), "", MOD_SUBSTAT_LOOKUP(Z27,AA27,0)) | AG27: =MOD_SUBSTAT_LOOKUP(AE27,AF27,1) | AH27: =IF(ISBLANK(AE27), "", MOD_SUBSTAT_LOOKUP(AE27,AF27,0)) | AL27: =MOD_SUBSTAT_LOOKUP(AJ27,AK27,1) | AM27: =IF(ISBLANK(AJ27), "", MOD_SUBSTAT_LOOKUP(AJ27,AK27,0)) | AQ27: =MOD_SUBSTAT_LOOKUP(AO27,AP27,1) | AR27: =IF(ISBLANK(AO27), "", MOD_SUBSTAT_LOOKUP(AO27,AP27,0))
A29: ▲ GENERATOR | F29: Black Hole Digestor | K29: Galaxy Compressor | P29: Singularity Harness | U29: Pulsar Harvester | Z29: Project Funding | AE29: Restorative Bonus | AJ29: Any Other | AO29: Any Other 2
D30: Highest Level | F30: Rarity | G30: Level | H30: Stat | K30: Rarity | L30: Level | M30: Stat | P30: Rarity | Q30: Level | R30: Stat | U30: Rarity | V30: Level | W30: Stat | Z30: Rarity | AA30: Level | AB30: Stat | AE30: Rarity | AF30: Level | AG30: Stat | AJ30: Rarity | AK30: Level | AL30: Stat | AO30: Rarity | AP30: Level | AQ30: Stat
B31: Coin Bonus | D31: 161 | F31: Legendary | G31: =CAP_MOD_LEVEL($D31,F31) -> 100 | H31: =IF(F31="None",1,MODSTAT_GENERATOR(F31,G31)) -> 1.275 | K31: Mythic+ | L31: =CAP_MOD_LEVEL($D31,K31) -> 160 | M31: =IF(K31="None",1,MODSTAT_GENERATOR(K31,L31)) -> 1.665 | P31: Ancestral | Q31: =CAP_MOD_LEVEL($D31,P31) -> 161 | R31: =IF(P31="None",1,MODSTAT_GENERATOR(P31,Q31)) -> 1.68 | U31: Ancestral 1* | V31: =CAP_MOD_LEVEL($D31,U31) -> 161 | W31: =IF(U31="None",1,MODSTAT_GENERATOR(U31,V31)) -> 1.707 | Z31: Mythic+ | AA31: =CAP_MOD_LEVEL($D31,Z31) -> 160 | AB31: =IF(Z31="None",1,MODSTAT_GENERATOR(Z31,AA31)) -> 1.665 | AE31: Mythic+ | AF31: =CAP_MOD_LEVEL($D31,AE31) -> 160 | AG31: =IF(AE31="None",1,MODSTAT_GENERATOR(AE31,AF31)) -> 1.665 | AJ31: Legendary | AK31: =CAP_MOD_LEVEL($D31,AJ31) -> 100 | AL31: =IF(AJ31="None",1,MODSTAT_GENERATOR(AJ31,AK31)) -> 1.275 | AO31: Common | AP31: =CAP_MOD_LEVEL($D31,AO31) -> 20 | AQ31: =IF(AO31="None",1,MODSTAT_GENERATOR(AO31,AP31)) -> 1.03
D33: Assist Level | F33: Coins / Kill Bonus | G33: Legendary | H33: =MOD_SUBSTAT_LOOKUP(F33,G33,1) -> +0.4x | I33: =IF(ISBLANK(F33), "", MOD_SUBSTAT_LOOKUP(F33,G33,0)) -> 0.4 | K33: Package Chance | L33: Legendary | M33: =MOD_SUBSTAT_LOOKUP(K33,L33,1) -> +8% | N33: =IF(ISBLANK(K33), "", MOD_SUBSTAT_LOOKUP(K33,L33,0)) -> 0.08 | P33: Free Utility Upgrade | Q33: Mythic | R33: =MOD_SUBSTAT_LOOKUP(P33,Q33,1) -> +10% | S33: =IF(ISBLANK(P33), "", MOD_SUBSTAT_LOOKUP(P33,Q33,0)) -> 0.1 | U33: Free Utility Upgrade | V33: Ancestral | W33: =MOD_SUBSTAT_LOOKUP(U33,V33,1) -> +12% | X33: =IF(ISBLANK(U33), "", MOD_SUBSTAT_LOOKUP(U33,V33,0)) -> 0.12 | Z33: Enemy Attack Level Skip | AA33: Mythic | AB33: =MOD_SUBSTAT_LOOKUP(Z33,AA33,1) -> +6% | AC33: =IF(ISBLANK(Z33), "", MOD_SUBSTAT_LOOKUP(Z33,AA33,0)) -> 0.06 | AE33: Enemy Health Level Skip | AF33: Mythic | AG33: =MOD_SUBSTAT_LOOKUP(AE33,AF33,1) -> +6% | AH33: =IF(ISBLANK(AE33), "", MOD_SUBSTAT_LOOKUP(AE33,AF33,0)) -> 0.06 | AJ33: Enemy Attack Level Skip | AK33: Legendary | AL33: =MOD_SUBSTAT_LOOKUP(AJ33,AK33,1) -> +4% | AM33: =IF(ISBLANK(AJ33), "", MOD_SUBSTAT_LOOKUP(AJ33,AK33,0)) -> 0.04 | AQ33: =MOD_SUBSTAT_LOOKUP(AO33,AP33,1) | AR33: =IF(ISBLANK(AO33), "", MOD_SUBSTAT_LOOKUP(AO33,AP33,0))
D34: 97 | F34: Enemy Attack Level Skip | G34: Legendary | H34: =MOD_SUBSTAT_LOOKUP(F34,G34,1) -> +4% | I34: =IF(ISBLANK(F34), "", MOD_SUBSTAT_LOOKUP(F34,G34,0)) -> 0.04 | K34: Enemy Attack Level Skip | L34: Legendary | M34: =MOD_SUBSTAT_LOOKUP(K34,L34,1) -> +4% | N34: =IF(ISBLANK(K34), "", MOD_SUBSTAT_LOOKUP(K34,L34,0)) -> 0.04 | P34: Coins / Kill Bonus | Q34: Mythic | R34: =MOD_SUBSTAT_LOOKUP(P34,Q34,1) -> +0.5x | S34: =IF(ISBLANK(P34), "", MOD_SUBSTAT_LOOKUP(P34,Q34,0)) -> 0.5 | U34: Enemy Attack Level Skip | V34: Ancestral | W34: =MOD_SUBSTAT_LOOKUP(U34,V34,1) -> +8% | X34: =IF(ISBLANK(U34), "", MOD_SUBSTAT_LOOKUP(U34,V34,0)) -> 0.08 | Z34: Enemy Health Level Skip | AA34: Mythic | AB34: =MOD_SUBSTAT_LOOKUP(Z34,AA34,1) -> +6% | AC34: =IF(ISBLANK(Z34), "", MOD_SUBSTAT_LOOKUP(Z34,AA34,0)) -> 0.06 | AE34: Enemy Attack Level Skip | AF34: Mythic | AG34: =MOD_SUBSTAT_LOOKUP(AE34,AF34,1) -> +6% | AH34: =IF(ISBLANK(AE34), "", MOD_SUBSTAT_LOOKUP(AE34,AF34,0)) -> 0.06 | AJ34: Coins / Kill Bonus | AK34: Epic | AL34: =MOD_SUBSTAT_LOOKUP(AJ34,AK34,1) -> +0.3x | AM34: =IF(ISBLANK(AJ34), "", MOD_SUBSTAT_LOOKUP(AJ34,AK34,0)) -> 0.3 | AQ34: =MOD_SUBSTAT_LOOKUP(AO34,AP34,1) | AR34: =IF(ISBLANK(AO34), "", MOD_SUBSTAT_LOOKUP(AO34,AP34,0))
F35: Free Utility Upgrade | G35: Legendary | H35: =MOD_SUBSTAT_LOOKUP(F35,G35,1) -> +8% | I35: =IF(ISBLANK(F35), "", MOD_SUBSTAT_LOOKUP(F35,G35,0)) -> 0.08 | K35: Free Utility Upgrade | L35: Legendary | M35: =MOD_SUBSTAT_LOOKUP(K35,L35,1) -> +8% | N35: =IF(ISBLANK(K35), "", MOD_SUBSTAT_LOOKUP(K35,L35,0)) -> 0.08 | P35: Enemy Health Level Skip | Q35: Mythic | R35: =MOD_SUBSTAT_LOOKUP(P35,Q35,1) -> +6% | S35: =IF(ISBLANK(P35), "", MOD_SUBSTAT_LOOKUP(P35,Q35,0)) -> 0.06 | U35: Coins / Kill Bonus | V35: Ancestral | W35: =MOD_SUBSTAT_LOOKUP(U35,V35,1) -> +0.6x | X35: =IF(ISBLANK(U35), "", MOD_SUBSTAT_LOOKUP(U35,V35,0)) -> 0.6 | Z35: Free Utility Upgrade | AA35: Mythic | AB35: =MOD_SUBSTAT_LOOKUP(Z35,AA35,1) -> +10% | AC35: =IF(ISBLANK(Z35), "", MOD_SUBSTAT_LOOKUP(Z35,AA35,0)) -> 0.1 | AE35: Free Utility Upgrade | AF35: Legendary | AG35: =MOD_SUBSTAT_LOOKUP(AE35,AF35,1) -> +8% | AH35: =IF(ISBLANK(AE35), "", MOD_SUBSTAT_LOOKUP(AE35,AF35,0)) -> 0.08 | AJ35: Free Utility Upgrade | AK35: Legendary | AL35: =MOD_SUBSTAT_LOOKUP(AJ35,AK35,1) -> +8% | AM35: =IF(ISBLANK(AJ35), "", MOD_SUBSTAT_LOOKUP(AJ35,AK35,0)) -> 0.08 | AQ35: =MOD_SUBSTAT_LOOKUP(AO35,AP35,1) | AR35: =IF(ISBLANK(AO35), "", MOD_SUBSTAT_LOOKUP(AO35,AP35,0))
H36: =MOD_SUBSTAT_LOOKUP(F36,G36,1) | I36: =IF(ISBLANK(F36), "", MOD_SUBSTAT_LOOKUP(F36,G36,0)) | M36: =MOD_SUBSTAT_LOOKUP(K36,L36,1) | N36: =IF(ISBLANK(K36), "", MOD_SUBSTAT_LOOKUP(K36,L36,0)) | P36: Enemy Attack Level Skip | Q36: Ancestral | R36: =MOD_SUBSTAT_LOOKUP(P36,Q36,1) -> +8% | S36: =IF(ISBLANK(P36), "", MOD_SUBSTAT_LOOKUP(P36,Q36,0)) -> 0.08 | U36: Enemy Health Level Skip | V36: Ancestral | W36: =MOD_SUBSTAT_LOOKUP(U36,V36,1) -> +8% | X36: =IF(ISBLANK(U36), "", MOD_SUBSTAT_LOOKUP(U36,V36,0)) -> 0.08 | Z36: Free Defense Upgrade | AA36: Epic | AB36: =MOD_SUBSTAT_LOOKUP(Z36,AA36,1) -> +6% | AC36: =IF(ISBLANK(Z36), "", MOD_SUBSTAT_LOOKUP(Z36,AA36,0)) -> 0.06 | AE36: Package Chance | AF36: Mythic | AG36: =MOD_SUBSTAT_LOOKUP(AE36,AF36,1) -> +11% | AH36: =IF(ISBLANK(AE36), "", MOD_SUBSTAT_LOOKUP(AE36,AF36,0)) -> 0.11 | AJ36: Free Attack Upgrade | AK36: Legendary | AL36: =MOD_SUBSTAT_LOOKUP(AJ36,AK36,1) -> +8% | AM36: =IF(ISBLANK(AJ36), "", MOD_SUBSTAT_LOOKUP(AJ36,AK36,0)) -> 0.08 | AQ36: =MOD_SUBSTAT_LOOKUP(AO36,AP36,1) | AR36: =IF(ISBLANK(AO36), "", MOD_SUBSTAT_LOOKUP(AO36,AP36,0))
H37: =MOD_SUBSTAT_LOOKUP(F37,G37,1) | I37: =IF(ISBLANK(F37), "", MOD_SUBSTAT_LOOKUP(F37,G37,0)) | M37: =MOD_SUBSTAT_LOOKUP(K37,L37,1) | N37: =IF(ISBLANK(K37), "", MOD_SUBSTAT_LOOKUP(K37,L37,0)) | P37: Package Chance | Q37: Mythic | R37: =MOD_SUBSTAT_LOOKUP(P37,Q37,1) -> +11% | S37: =IF(ISBLANK(P37), "", MOD_SUBSTAT_LOOKUP(P37,Q37,0)) -> 0.11 | U37: Package Chance | V37: Epic | W37: =MOD_SUBSTAT_LOOKUP(U37,V37,1) -> +5% | X37: =IF(ISBLANK(U37), "", MOD_SUBSTAT_LOOKUP(U37,V37,0)) -> 0.05 | Z37: Package Chance | AA37: Mythic | AB37: =MOD_SUBSTAT_LOOKUP(Z37,AA37,1) -> +11% | AC37: =IF(ISBLANK(Z37), "", MOD_SUBSTAT_LOOKUP(Z37,AA37,0)) -> 0.11 | AG37: =MOD_SUBSTAT_LOOKUP(AE37,AF37,1) | AH37: =IF(ISBLANK(AE37), "", MOD_SUBSTAT_LOOKUP(AE37,AF37,0)) | AL37: =MOD_SUBSTAT_LOOKUP(AJ37,AK37,1) | AM37: =IF(ISBLANK(AJ37), "", MOD_SUBSTAT_LOOKUP(AJ37,AK37,0)) | AQ37: =MOD_SUBSTAT_LOOKUP(AO37,AP37,1) | AR37: =IF(ISBLANK(AO37), "", MOD_SUBSTAT_LOOKUP(AO37,AP37,0))
H38: =MOD_SUBSTAT_LOOKUP(F38,G38,1) | I38: =IF(ISBLANK(F38), "", MOD_SUBSTAT_LOOKUP(F38,G38,0)) | M38: =MOD_SUBSTAT_LOOKUP(K38,L38,1) | N38: =IF(ISBLANK(K38), "", MOD_SUBSTAT_LOOKUP(K38,L38,0)) | R38: =MOD_SUBSTAT_LOOKUP(P38,Q38,1) | S38: =IF(ISBLANK(P38), "", MOD_SUBSTAT_LOOKUP(P38,Q38,0)) | W38: =MOD_SUBSTAT_LOOKUP(U38,V38,1) | X38: =IF(ISBLANK(U38), "", MOD_SUBSTAT_LOOKUP(U38,V38,0)) | AB38: =MOD_SUBSTAT_LOOKUP(Z38,AA38,1) | AC38: =IF(ISBLANK(Z38), "", MOD_SUBSTAT_LOOKUP(Z38,AA38,0)) | AG38: =MOD_SUBSTAT_LOOKUP(AE38,AF38,1) | AH38: =IF(ISBLANK(AE38), "", MOD_SUBSTAT_LOOKUP(AE38,AF38,0)) | AL38: =MOD_SUBSTAT_LOOKUP(AJ38,AK38,1) | AM38: =IF(ISBLANK(AJ38), "", MOD_SUBSTAT_LOOKUP(AJ38,AK38,0)) | AQ38: =MOD_SUBSTAT_LOOKUP(AO38,AP38,1) | AR38: =IF(ISBLANK(AO38), "", MOD_SUBSTAT_LOOKUP(AO38,AP38,0))
H39: =MOD_SUBSTAT_LOOKUP(F39,G39,1) | I39: =IF(ISBLANK(F39), "", MOD_SUBSTAT_LOOKUP(F39,G39,0)) | M39: =MOD_SUBSTAT_LOOKUP(K39,L39,1) | N39: =IF(ISBLANK(K39), "", MOD_SUBSTAT_LOOKUP(K39,L39,0)) | R39: =MOD_SUBSTAT_LOOKUP(P39,Q39,1) | S39: =IF(ISBLANK(P39), "", MOD_SUBSTAT_LOOKUP(P39,Q39,0)) | W39: =MOD_SUBSTAT_LOOKUP(U39,V39,1) | X39: =IF(ISBLANK(U39), "", MOD_SUBSTAT_LOOKUP(U39,V39,0)) | AB39: =MOD_SUBSTAT_LOOKUP(Z39,AA39,1) | AC39: =IF(ISBLANK(Z39), "", MOD_SUBSTAT_LOOKUP(Z39,AA39,0)) | AG39: =MOD_SUBSTAT_LOOKUP(AE39,AF39,1) | AH39: =IF(ISBLANK(AE39), "", MOD_SUBSTAT_LOOKUP(AE39,AF39,0)) | AL39: =MOD_SUBSTAT_LOOKUP(AJ39,AK39,1) | AM39: =IF(ISBLANK(AJ39), "", MOD_SUBSTAT_LOOKUP(AJ39,AK39,0)) | AQ39: =MOD_SUBSTAT_LOOKUP(AO39,AP39,1) | AR39: =IF(ISBLANK(AO39), "", MOD_SUBSTAT_LOOKUP(AO39,AP39,0))
H40: =MOD_SUBSTAT_LOOKUP(F40,G40,1) | I40: =IF(ISBLANK(F40), "", MOD_SUBSTAT_LOOKUP(F40,G40,0)) | M40: =MOD_SUBSTAT_LOOKUP(K40,L40,1) | N40: =IF(ISBLANK(K40), "", MOD_SUBSTAT_LOOKUP(K40,L40,0)) | R40: =MOD_SUBSTAT_LOOKUP(P40,Q40,1) | S40: =IF(ISBLANK(P40), "", MOD_SUBSTAT_LOOKUP(P40,Q40,0)) | W40: =MOD_SUBSTAT_LOOKUP(U40,V40,1) | X40: =IF(ISBLANK(U40), "", MOD_SUBSTAT_LOOKUP(U40,V40,0)) | AB40: =MOD_SUBSTAT_LOOKUP(Z40,AA40,1) | AC40: =IF(ISBLANK(Z40), "", MOD_SUBSTAT_LOOKUP(Z40,AA40,0)) | AG40: =MOD_SUBSTAT_LOOKUP(AE40,AF40,1) | AH40: =IF(ISBLANK(AE40), "", MOD_SUBSTAT_LOOKUP(AE40,AF40,0)) | AL40: =MOD_SUBSTAT_LOOKUP(AJ40,AK40,1) | AM40: =IF(ISBLANK(AJ40), "", MOD_SUBSTAT_LOOKUP(AJ40,AK40,0)) | AQ40: =MOD_SUBSTAT_LOOKUP(AO40,AP40,1) | AR40: =IF(ISBLANK(AO40), "", MOD_SUBSTAT_LOOKUP(AO40,AP40,0))
A42: 🔶 CORE | F42: Multiverse Nexus | K42: Dimension Core | P42: Harmony Conductor | U42: Om Chip | Z42: Magnetic Hook | AE42: Primordial Collapse | AJ42: Any Other | AO42: Any Other 2
D43: Highest Level | F43: Rarity | G43: Level | H43: Stat | K43: Rarity | L43: Level | M43: Stat | P43: Rarity | Q43: Level | R43: Stat | U43: Rarity | V43: Level | W43: Stat | Z43: Rarity | AA43: Level | AB43: Stat | AE43: Rarity | AF43: Level | AG43: Stat | AJ43: Rarity | AK43: Level | AL43: Stat | AO43: Rarity | AP43: Level | AQ43: Stat
B44: UW Damage | D44: 159 | F44: Ancestral 2* | G44: =CAP_MOD_LEVEL($D44,F44) -> 159 | H44: =IF(F44="None",1,MODSTAT_CORE(F44,G44)) -> 11.692 | K44: Ancestral | L44: =CAP_MOD_LEVEL($D44,K44) -> 159 | M44: =IF(K44="None",1,MODSTAT_CORE(K44,L44)) -> 10.9 | P44: Ancestral 5* | Q44: =CAP_MOD_LEVEL($D44,P44) -> 159 | R44: =IF(P44="None",1,MODSTAT_CORE(P44,Q44)) -> 12.88 | U44: Ancestral | V44: =CAP_MOD_LEVEL($D44,U44) -> 159 | W44: =IF(U44="None",1,MODSTAT_CORE(U44,V44)) -> 10.9 | Z44: Ancestral | AA44: =CAP_MOD_LEVEL($D44,Z44) -> 159 | AB44: =IF(Z44="None",1,MODSTAT_CORE(Z44,AA44)) -> 10.9 | AE44: Ancestral 2* | AF44: =CAP_MOD_LEVEL($D44,AE44) -> 159 | AG44: =IF(AE44="None",1,MODSTAT_CORE(AE44,AF44)) -> 11.692 | AJ44: Epic | AK44: =CAP_MOD_LEVEL($D44,AJ44) -> 60 | AL44: =IF(AJ44="None",1,MODSTAT_CORE(AJ44,AK44)) -> 2.17 | AO44: Common | AP44: =CAP_MOD_LEVEL($D44,AO44) -> 20 | AQ44: =IF(AO44="None",1,MODSTAT_CORE(AO44,AP44)) -> 1.23
D46: Assist Level | F46: Death Wave - Quantity | G46: Legendary | H46: =MOD_SUBSTAT_LOOKUP(F46,G46,1) -> +1 | I46: =IF(ISBLANK(F46), "", MOD_SUBSTAT_LOOKUP(F46,G46,0)) -> 1 | K46: Chain Lightning - Chance | L46: Mythic | M46: =MOD_SUBSTAT_LOOKUP(K46,L46,1) -> +12% | N46: =IF(ISBLANK(K46), "", MOD_SUBSTAT_LOOKUP(K46,L46,0)) -> 0.12 | R46: =MOD_SUBSTAT_LOOKUP(P46,Q46,1) | S46: =IF(ISBLANK(P46), "", MOD_SUBSTAT_LOOKUP(P46,Q46,0)) | U46: Chrono Field - Duration | V46: Mythic | W46: =MOD_SUBSTAT_LOOKUP(U46,V46,1) -> +7s | X46: =IF(ISBLANK(U46), "", MOD_SUBSTAT_LOOKUP(U46,V46,0)) -> 7 | AB46: =MOD_SUBSTAT_LOOKUP(Z46,AA46,1) | AC46: =IF(ISBLANK(Z46), "", MOD_SUBSTAT_LOOKUP(Z46,AA46,0)) | AE46: Black Hole - Duration | AF46: Ancestral | AG46: =MOD_SUBSTAT_LOOKUP(AE46,AF46,1) -> +4s | AH46: =IF(ISBLANK(AE46), "", MOD_SUBSTAT_LOOKUP(AE46,AF46,0)) -> 4 | AL46: =MOD_SUBSTAT_LOOKUP(AJ46,AK46,1) | AM46: =IF(ISBLANK(AJ46), "", MOD_SUBSTAT_LOOKUP(AJ46,AK46,0)) | AQ46: =MOD_SUBSTAT_LOOKUP(AO46,AP46,1) | AR46: =IF(ISBLANK(AO46), "", MOD_SUBSTAT_LOOKUP(AO46,AP46,0))
D47: 101 | F47: Golden Tower - Bonus | G47: Legendary | H47: =MOD_SUBSTAT_LOOKUP(F47,G47,1) -> +2x | I47: =IF(ISBLANK(F47), "", MOD_SUBSTAT_LOOKUP(F47,G47,0)) -> 2 | K47: Spotlight - Angle | L47: Mythic | M47: =MOD_SUBSTAT_LOOKUP(K47,L47,1) -> +11° | N47: =IF(ISBLANK(K47), "", MOD_SUBSTAT_LOOKUP(K47,L47,0)) -> 11 | R47: =MOD_SUBSTAT_LOOKUP(P47,Q47,1) | S47: =IF(ISBLANK(P47), "", MOD_SUBSTAT_LOOKUP(P47,Q47,0)) | U47: Spotlight - Bonus | V47: Mythic | W47: =MOD_SUBSTAT_LOOKUP(U47,V47,1) -> +15x | X47: =IF(ISBLANK(U47), "", MOD_SUBSTAT_LOOKUP(U47,V47,0)) -> 15 | AB47: =MOD_SUBSTAT_LOOKUP(Z47,AA47,1) | AC47: =IF(ISBLANK(Z47), "", MOD_SUBSTAT_LOOKUP(Z47,AA47,0)) | AE47: Black Hole - Cooldown | AF47: Ancestral | AG47: =MOD_SUBSTAT_LOOKUP(AE47,AF47,1) -> -4s | AH47: =IF(ISBLANK(AE47), "", MOD_SUBSTAT_LOOKUP(AE47,AF47,0)) -> -4 | AL47: =MOD_SUBSTAT_LOOKUP(AJ47,AK47,1) | AM47: =IF(ISBLANK(AJ47), "", MOD_SUBSTAT_LOOKUP(AJ47,AK47,0)) | AQ47: =MOD_SUBSTAT_LOOKUP(AO47,AP47,1) | AR47: =IF(ISBLANK(AO47), "", MOD_SUBSTAT_LOOKUP(AO47,AP47,0))
F48: Black Hole - Size | G48: Legendary | H48: =MOD_SUBSTAT_LOOKUP(F48,G48,1) -> +8.00m | I48: =IF(ISBLANK(F48), "", MOD_SUBSTAT_LOOKUP(F48,G48,0)) -> 8 | K48: Spotlight - Bonus | L48: Mythic | M48: =MOD_SUBSTAT_LOOKUP(K48,L48,1) -> +15x | N48: =IF(ISBLANK(K48), "", MOD_SUBSTAT_LOOKUP(K48,L48,0)) -> 15 | R48: =MOD_SUBSTAT_LOOKUP(P48,Q48,1) | S48: =IF(ISBLANK(P48), "", MOD_SUBSTAT_LOOKUP(P48,Q48,0)) | U48: Spotlight - Angle | V48: Epic | W48: =MOD_SUBSTAT_LOOKUP(U48,V48,1) -> +3° | X48: =IF(ISBLANK(U48), "", MOD_SUBSTAT_LOOKUP(U48,V48,0)) -> 3 | AB48: =MOD_SUBSTAT_LOOKUP(Z48,AA48,1) | AC48: =IF(ISBLANK(Z48), "", MOD_SUBSTAT_LOOKUP(Z48,AA48,0)) | AE48: Death Wave - Quantity | AF48: Mythic | AG48: =MOD_SUBSTAT_LOOKUP(AE48,AF48,1) -> +2 | AH48: =IF(ISBLANK(AE48), "", MOD_SUBSTAT_LOOKUP(AE48,AF48,0)) -> 2 | AL48: =MOD_SUBSTAT_LOOKUP(AJ48,AK48,1) | AM48: =IF(ISBLANK(AJ48), "", MOD_SUBSTAT_LOOKUP(AJ48,AK48,0)) | AQ48: =MOD_SUBSTAT_LOOKUP(AO48,AP48,1) | AR48: =IF(ISBLANK(AO48), "", MOD_SUBSTAT_LOOKUP(AO48,AP48,0))
...

Sheet _IDS
A1: =IFERROR(__xludf.DUMMYFUNCTION("IMPORTRANGE(IF(IDS!E6=""✅"", IDS!D6, ""1osjoqKmMwtOWs7Up3e21-3ofN1RHOjsgKV6y3dc6rgE""), ""_IDS!A1:BY212"")"),"Labs") -> Labs | B1: =IFERROR(__xludf.DUMMYFUNCTION("""COMPUTED_VALUE"""),"https://docs.google.com/spreadsheets/d/1jojOg_XIJCzm1LCYWu2F4KCtErjUIdKuFL1PiKzA0OE/edit") -> https://docs.google.com/spreadsheets/d/1jojOg_XIJCzm1LCYWu2F4KCtErjUIdKuFL1PiKzA0OE/edit | C1: =IFERROR(__xludf.DUMMYFUNCTION("""COMPUTED_VALUE"""),"✅") -> ✅ | D1: =IFERROR(__xludf.DUMMYFUNCTION("""COMPUTED_VALUE"""),"v2.5.7") -> v2.5.7 | E1: =IFERROR(__xludf.DUMMYFUNCTION("""COMPUTED_VALUE"""),"WS") -> WS | F1: =IFERROR(__xludf.DUMMYFUNCTION("""COMPUTED_VALUE"""),"https://docs.google.com/spreadsheets/d/1huHJMcyg1uRJEeRYqAgWzMc5TodPPplVZEFhwBiIeEs/edit") -> https://docs.google.com/spreadsheets/d/1huHJMcyg1uRJEeRYqAgWzMc5TodPPplVZEFhwBiIeEs/edit | G1: =IFERROR(__xludf.DUMMYFUNCTION("""COMPUTED_VALUE"""),"✅") -> ✅ | H1: =IFERROR(__xludf.DUMMYFUNCTION("""COMPUTED_VALUE"""),"v2.3.1") -> v2.3.1 | R1: =IFERROR(__xludf.DUMMYFUNCTION("""COMPUTED_VALUE"""),"WS+") -> WS+ | Z1: =IFERROR(__xludf.DUMMYFUNCTION("""COMPUTED_VALUE"""),"UWs") -> UWs | AA1: =IFERROR(__xludf.DUMMYFUNCTION("""COMPUTED_VALUE"""),"https://docs.google.com/spreadsheets/d/1VTRhVyt28cxrjCRcgVkQr2R_u4g9irfJTHy1cfftlIE/edit") -> https://docs.google.com/spreadsheets/d/1VTRhVyt28cxrjCRcgVkQr2R_u4g9irfJTHy1cfftlIE/edit | AB1: =IFERROR(__xludf.DUMMYFUNCTION("""COMPUTED_VALUE"""),"✅") -> ✅ | AC1: =IFERROR(__xludf.DUMMYFUNCTION("""COMPUTED_VALUE"""),"v2.1.3") -> v2.1.3 | AE1: =IFERROR(__xludf.DUMMYFUNCTION("""COMPUTED_VALUE"""),"Cards") -> Cards | AF1: =IFERROR(__xludf.DUMMYFUNCTION("""COMPUTED_VALUE"""),"https://docs.google.com/spreadsheets/d/1HMQwNLTvcw7aXmjjL7cXmZSdjAF_62ehWpwDIdjqEGs/edit") -> https://docs.google.com/spreadsheets/d/1HMQwNLTvcw7aXmjjL7cXmZSdjAF_62ehWpwDIdjqEGs/edit | AG1: =IFERROR(__xludf.DUMMYFUNCTION("""COMPUTED_VALUE"""),"✅") -> ✅ | AH1: =IFERROR(__xludf.DUMMYFUNCTION("""COMPUTED_VALUE"""),"Cards Presets") -> Cards Presets | AI1: =IFERROR(__xludf.DUMMYFUNCTION("""COMPUTED_VALUE"""),"v2.2.3") -> v2.2.3 | AJ1: =IFERROR(__xludf.DUMMYFUNCTION("""COMPUTED_VALUE"""),17.0) -> 17 | AM1: =IFERROR(__xludf.DUMMYFUNCTION("""COMPUTED_VALUE"""),"Relics") -> Relics | AN1: =IFERROR(__xludf.DUMMYFUNCTION("""COMPUTED_VALUE"""),"https://docs.google.com/spreadsheets/d/1Dll0IofJTWYkzhzhRWx1aA-_xtO3i_1iD65nAP6R_Ec/edit") -> https://docs.google.com/spreadsheets/d/1Dll0IofJTWYkzhzhRWx1aA-_xtO3i_1iD65nAP6R_Ec/edit | AO1: =IFERROR(__xludf.DUMMYFUNCTION("""COMPUTED_VALUE"""),"✅") -> ✅ | AP1: =IFERROR(__xludf.DUMMYFUNCTION("""COMPUTED_VALUE"""),"Vault") -> Vault | AR1: =IFERROR(__xludf.DUMMYFUNCTION("""COMPUTED_VALUE"""),"") | AS1: =IFERROR(__xludf.DUMMYFUNCTION("""COMPUTED_VALUE"""),"Bots") -> Bots | AT1: =IFERROR(__xludf.DUMMYFUNCTION("""COMPUTED_VALUE"""),"https://docs.google.com/spreadsheets/d/1H3PYvtIH7kId6WswEeMmrx7u5_g1GlkNPJtJhkASrbs/edit") -> https://docs.google.com/spreadsheets/d/1H3PYvtIH7kId6WswEeMmrx7u5_g1GlkNPJtJhkASrbs/edit | AU1: =IFERROR(__xludf.DUMMYFUNCTION("""COMPUTED_VALUE"""),"✅") -> ✅ | AV1: =IFERROR(__xludf.DUMMYFUNCTION("""COMPUTED_VALUE"""),"v2.2.1") -> v2.2.1 | AY1: =IFERROR(__xludf.DUMMYFUNCTION("""COMPUTED_VALUE"""),"Themes & Songs") -> Themes & Songs | AZ1: =IFERROR(__xludf.DUMMYFUNCTION("""COMPUTED_VALUE"""),"https://docs.google.com/spreadsheets/d/19KliigQhAeXztRPa9cSGZ7n9Q-REp4dyqMNI9d-UB0k/edit") -> https://docs.google.com/spreadsheets/d/19KliigQhAeXztRPa9cSGZ7n9Q-REp4dyqMNI9d-UB0k/edit | BA1: =IFERROR(__xludf.DUMMYFUNCTION("""COMPUTED_VALUE"""),"✅") -> ✅ | BB1: =IFERROR(__xludf.DUMMYFUNCTION("""COMPUTED_VALUE"""),"Modules") -> Modules | BC1: =IFERROR(__xludf.DUMMYFUNCTION("""COMPUTED_VALUE"""),"https://docs.google.com/spreadsheets/d/1rOoSY6TK918myJ6Mn6zO4rmUaFbPu6qJnGI17kc9DzQ/edit") -> https://docs.google.com/spreadsheets/d/1rOoSY6TK918myJ6Mn6zO4rmUaFbPu6qJnGI17kc9DzQ/edit | BD1: =IFERROR(__xludf.DUMMYFUNCTION("""COMPUTED_VALUE"""),"✅") -> ✅ | BE1: =IFERROR(__xludf.DUMMYFUNCTION("""COMPUTED_VALUE"""),"v5.13") -> v5.13 | BU1: =IFERROR(__xludf.DUMMYFUNCTION("""COMPUTED_VALUE"""),"Guardians") -> Guardians | BV1: =IFERROR(__xludf.DUMMYFUNCTION("""COMPUTED_VALUE"""),"https://docs.google.com/spreadsheets/d/1J4UPKzR9MLY_zzM7u7SzmyclgTEYX_PUvBcua4EbsSU/edit") -> https://docs.google.com/spreadsheets/d/1J4UPKzR9MLY_zzM7u7SzmyclgTEYX_PUvBcua4EbsSU/edit | BW1: =IFERROR(__xludf.DUMMYFUNCTION("""COMPUTED_VALUE"""),"✅") -> ✅ | BX1: =IFERROR(__xludf.DUMMYFUNCTION("""COMPUTED_VALUE"""),"v2.3.6") -> v2.3.6
A2: =IFERROR(__xludf.DUMMYFUNCTION("""COMPUTED_VALUE"""),"Game Speed") -> Game Speed | B2: =IFERROR(__xludf.DUMMYFUNCTION("""COMPUTED_VALUE"""),7.0) -> 7 | C2: =IFERROR(__xludf.DUMMYFUNCTION("""COMPUTED_VALUE"""),7.0) -> 7 | D2: =IFERROR(__xludf.DUMMYFUNCTION("""COMPUTED_VALUE"""),7.0) -> 7 | E2: =IFERROR(__xludf.DUMMYFUNCTION("""COMPUTED_VALUE"""),"U") -> U | F2: =IFERROR(__xludf.DUMMYFUNCTION("""COMPUTED_VALUE"""),"Workshop Upgrade") -> Workshop Upgrade | G2: =IFERROR(__xludf.DUMMYFUNCTION("""COMPUTED_VALUE"""),"Farming") -> Farming | I2: =IFERROR(__xludf.DUMMYFUNCTION("""COMPUTED_VALUE"""),"Tourney") -> Tourney | K2: =IFERROR(__xludf.DUMMYFUNCTION("""COMPUTED_VALUE"""),"Preset 3") -> Preset 3 | M2: =IFERROR(__xludf.DUMMYFUNCTION("""COMPUTED_VALUE"""),"Preset 4") -> Preset 4 | O2: =IFERROR(__xludf.DUMMYFUNCTION("""COMPUTED_VALUE"""),"Preset 5") -> Preset 5 | R2: =IFERROR(__xludf.DUMMYFUNCTION("""COMPUTED_VALUE"""),"Workshop Enhancement") -> Workshop Enhancement | T2: =IFERROR(__xludf.DUMMYFUNCTION("""COMPUTED_VALUE"""),"Farming") -> Farming | U2: =IFERROR(__xludf.DUMMYFUNCTION("""COMPUTED_VALUE"""),"Tourney") -> Tourney | V2: =IFERROR(__xludf.DUMMYFUNCTION("""COMPUTED_VALUE"""),"Preset 3") -> Preset 3 | W2: =IFERROR(__xludf.DUMMYFUNCTION("""COMPUTED_VALUE"""),"Preset 4") -> Preset 4 | X2: =IFERROR(__xludf.DUMMYFUNCTION("""COMPUTED_VALUE"""),"Preset 5") -> Preset 5 | Y2: =IFERROR(__xludf.DUMMYFUNCTION("""COMPUTED_VALUE"""),"7 q") -> 7 q | Z2: =IFERROR(__xludf.DUMMYFUNCTION("""COMPUTED_VALUE"""),"Chain Lightning") -> Chain Lightning | AB2: =IFERROR(__xludf.DUMMYFUNCTION("""COMPUTED_VALUE"""),"Damage") -> Damage | AC2: =IFERROR(__xludf.DUMMYFUNCTION("""COMPUTED_VALUE"""),898.0) -> 898 | AD2: =IFERROR(__xludf.DUMMYFUNCTION("""COMPUTED_VALUE"""),"19 | x898 | Cost 302 ⧌ | Next 362 ⧌") -> 19 | x898 | Cost 302 ⧌ | Next 362 ⧌ | AE2: =IFERROR(__xludf.DUMMYFUNCTION("""COMPUTED_VALUE"""),"Damage") -> Damage | AF2: =IFERROR(__xludf.DUMMYFUNCTION("""COMPUTED_VALUE"""),7.0) -> 7 | AG2: =IFERROR(__xludf.DUMMYFUNCTION("""COMPUTED_VALUE"""),FALSE) -> FALSE | AH2: =IFERROR(__xludf.DUMMYFUNCTION("""COMPUTED_VALUE"""),"Farming") -> Farming | AI2: =IFERROR(__xludf.DUMMYFUNCTION("""COMPUTED_VALUE"""),"Tourney") -> Tourney | AJ2: =IFERROR(__xludf.DUMMYFUNCTION("""COMPUTED_VALUE"""),"Preset 3") -> Preset 3 | AK2: =IFERROR(__xludf.DUMMYFUNCTION("""COMPUTED_VALUE"""),"Preset 4") -> Preset 4 | AL2: =IFERROR(__xludf.DUMMYFUNCTION("""COMPUTED_VALUE"""),"Preset 5") -> Preset 5 | AM2: =IFERROR(__xludf.DUMMYFUNCTION("""COMPUTED_VALUE"""),"Relics") -> Relics | AN2: =IFERROR(__xludf.DUMMYFUNCTION("""COMPUTED_VALUE"""),"Owned") -> Owned | AO2: =IFERROR(__xludf.DUMMYFUNCTION("""COMPUTED_VALUE"""),"v2.3.7") -> v2.3.7 | AP2: =IFERROR(__xludf.DUMMYFUNCTION("""COMPUTED_VALUE"""),"Keys spent") -> Keys spent | AQ2: =IFERROR(__xludf.DUMMYFUNCTION("""COMPUTED_VALUE"""),0.0) -> 0 | AS2: =IFERROR(__xludf.DUMMYFUNCTION("""COMPUTED_VALUE"""),"Flame Bot") -> Flame Bot | AU2: =IFERROR(__xludf.DUMMYFUNCTION("""COMPUTED_VALUE"""),"Damage R.") -> Damage R. | AV2: =IFERROR(__xludf.DUMMYFUNCTION("""COMPUTED_VALUE"""),0.3500000000000001) -> 0.35 | AW2: =IFERROR(__xludf.DUMMYFUNCTION("""COMPUTED_VALUE"""),"05 | 35% | Cost 260 ⧓ | Next 300 ⧓") -> 05 | 35% | Cost 260 ⧓ | Next 300 ⧓ | AY2: =IFERROR(__xludf.DUMMYFUNCTION("""COMPUTED_VALUE"""),1.682) -> 1.682 | BA2: =IFERROR(__xludf.DUMMYFUNCTION("""COMPUTED_VALUE"""),"v2.2.3") -> v2.2.3 | BB2: =IFERROR(__xludf.DUMMYFUNCTION("""COMPUTED_VALUE"""),"Assist Slot") -> Assist Slot | BC2: =IFERROR(__xludf.DUMMYFUNCTION("""COMPUTED_VALUE"""),FALSE) -> FALSE | BD2: =IFERROR(__xludf.DUMMYFUNCTION("""COMPUTED_VALUE"""),0.0) -> 0 | BG2: =IFERROR(__xludf.DUMMYFUNCTION("""COMPUTED_VALUE"""),"Assist Slot") -> Assist Slot | BH2: =IFERROR(__xludf.DUMMYFUNCTION("""COMPUTED_VALUE"""),TRUE) -> TRUE | BI2: =IFERROR(__xludf.DUMMYFUNCTION("""COMPUTED_VALUE"""),41.0) -> 41 | BL2: =IFERROR(__xludf.DUMMYFUNCTION("""COMPUTED_VALUE"""),"Assist Slot") -> Assist Slot | BM2: =IFERROR(__xludf.DUMMYFUNCTION("""COMPUTED_VALUE"""),TRUE) -> TRUE | BN2: =IFERROR(__xludf.DUMMYFUNCTION("""COMPUTED_VALUE"""),97.0) -> 97 | BQ2: =IFERROR(__xludf.DUMMYFUNCTION("""COMPUTED_VALUE"""),"Assist Slot") -> Assist Slot | BR2: =IFERROR(__xludf.DUMMYFUNCTION("""COMPUTED_VALUE"""),TRUE) -> TRUE | BS2: =IFERROR(__xludf.DUMMYFUNCTION("""COMPUTED_VALUE"""),101.0) -> 101 | BU2: =IFERROR(__xludf.DUMMYFUNCTION("""COMPUTED_VALUE"""),"Attack") -> Attack | BW2: =IFERROR(__xludf.DUMMYFUNCTION("""COMPUTED_VALUE"""),"Percentage") -> Percentage | BX2: =IFERROR(__xludf.DUMMYFUNCTION("""COMPUTED_VALUE"""),0.01) -> 0.01 | BY2: =IFERROR(__xludf.DUMMYFUNCTION("""COMPUTED_VALUE"""),"00 | 1% | Cost 0 ⧈ | Next 25 ⧈") -> 00 | 1% | Cost 0 ⧈ | Next 25 ⧈
A3: =IFERROR(__xludf.DUMMYFUNCTION("""COMPUTED_VALUE"""),"Starting Cash") -> Starting Cash | B3: =IFERROR(__xludf.DUMMYFUNCTION("""COMPUTED_VALUE"""),6.0) -> 6 | D3: =IFERROR(__xludf.DUMMYFUNCTION("""COMPUTED_VALUE"""),99.0) -> 99 | G3: =IFERROR(__xludf.DUMMYFUNCTION("""COMPUTED_VALUE"""),"¢ Level") -> ¢ Level | H3: =IFERROR(__xludf.DUMMYFUNCTION("""COMPUTED_VALUE"""),"$ Level") -> $ Level | I3: =IFERROR(__xludf.DUMMYFUNCTION("""COMPUTED_VALUE"""),"¢ Level") -> ¢ Level | J3: =IFERROR(__xludf.DUMMYFUNCTION("""COMPUTED_VALUE"""),"$ Level") -> $ Level | K3: =IFERROR(__xludf.DUMMYFUNCTION("""COMPUTED_VALUE"""),"¢ Level") -> ¢ Level | L3: =IFERROR(__xludf.DUMMYFUNCTION("""COMPUTED_VALUE"""),"$ Level") -> $ Level | M3: =IFERROR(__xludf.DUMMYFUNCTION("""COMPUTED_VALUE"""),"¢ Level") -> ¢ Level | N3: =IFERROR(__xludf.DUMMYFUNCTION("""COMPUTED_VALUE"""),"$ Level") -> $ Level | O3: =IFERROR(__xludf.DUMMYFUNCTION("""COMPUTED_VALUE"""),"¢ Level") -> ¢ Level | P3: =IFERROR(__xludf.DUMMYFUNCTION("""COMPUTED_VALUE"""),"$ Level") -> $ Level | Q3: =IFERROR(__xludf.DUMMYFUNCTION("""COMPUTED_VALUE"""),"Max") -> Max | T3: =IFERROR(__xludf.DUMMYFUNCTION("""COMPUTED_VALUE"""),"WS+") -> WS+ | U3: =IFERROR(__xludf.DUMMYFUNCTION("""COMPUTED_VALUE"""),"WS+") -> WS+ | V3: =IFERROR(__xludf.DUMMYFUNCTION("""COMPUTED_VALUE"""),"WS+") -> WS+ | W3: =IFERROR(__xludf.DUMMYFUNCTION("""COMPUTED_VALUE"""),"WS+") -> WS+ | X3: =IFERROR(__xludf.DUMMYFUNCTION("""COMPUTED_VALUE"""),"WS+") -> WS+ | Y3: =IFERROR(__xludf.DUMMYFUNCTION("""COMPUTED_VALUE"""),"Max") -> Max | AB3: =IFERROR(__xludf.DUMMYFUNCTION("""COMPUTED_VALUE"""),"Quantity") -> Quantity | AC3: =IFERROR(__xludf.DUMMYFUNCTION("""COMPUTED_VALUE"""),4.0) -> 4 | AD3: =IFERROR(__xludf.DUMMYFUNCTION("""COMPUTED_VALUE"""),"03 | #4 | Cost 150 ⧌ | Next 400 ⧌") -> 03 | #4 | Cost 150 ⧌ | Next 400 ⧌ | AE3: =IFERROR(__xludf.DUMMYFUNCTION("""COMPUTED_VALUE"""),"Attack Speed") -> Attack Speed | AF3: =IFERROR(__xludf.DUMMYFUNCTION("""COMPUTED_VALUE"""),7.0) -> 7 | AG3: =IFERROR(__xludf.DUMMYFUNCTION("""COMPUTED_VALUE"""),FALSE) -> FALSE | AH3: =IFERROR(__xludf.DUMMYFUNCTION("""COMPUTED_VALUE"""),"Enemy Balance") -> Enemy Balance | AI3: =IFERROR(__xludf.DUMMYFUNCTION("""COMPUTED_VALUE"""),"Attack Speed") -> Attack Speed | AM3: =IFERROR(__xludf.DUMMYFUNCTION("""COMPUTED_VALUE"""),"Event Relics") -> Event Relics | AN3: =IFERROR(__xludf.DUMMYFUNCTION("""COMPUTED_VALUE"""),112.0) -> 112 | AU3: =IFERROR(__xludf.DUMMYFUNCTION("""COMPUTED_VALUE"""),"Cooldown") -> Cooldown | AV3: =IFERROR(__xludf.DUMMYFUNCTION("""COMPUTED_VALUE"""),51.0) -> 51 | AW3: =IFERROR(__xludf.DUMMYFUNCTION("""COMPUTED_VALUE"""),"08 | 51s | Cost 380 ⧓ | Next 420 ⧓") -> 08 | 51s | Cost 380 ⧓ | Next 420 ⧓ | BB3: =IFERROR(__xludf.DUMMYFUNCTION("""COMPUTED_VALUE"""),"Rarity Cap") -> Rarity Cap | BC3: =IFERROR(__xludf.DUMMYFUNCTION("""COMPUTED_VALUE"""),"Epic") -> Epic | BG3: =IFERROR(__xludf.DUMMYFUNCTION("""COMPUTED_VALUE"""),"Rarity Cap") -> Rarity Cap | BH3: =IFERROR(__xludf.DUMMYFUNCTION("""COMPUTED_VALUE"""),"Epic") -> Epic | BL3: =IFERROR(__xludf.DUMMYFUNCTION("""COMPUTED_VALUE"""),"Rarity Cap") -> Rarity Cap | BM3: =IFERROR(__xludf.DUMMYFUNCTION("""COMPUTED_VALUE"""),"Epic") -> Epic | BQ3: =IFERROR(__xludf.DUMMYFUNCTION("""COMPUTED_VALUE"""),"Rarity Cap") -> Rarity Cap | BR3: =IFERROR(__xludf.DUMMYFUNCTION("""COMPUTED_VALUE"""),"Epic") -> Epic | BW3: =IFERROR(__xludf.DUMMYFUNCTION("""COMPUTED_VALUE"""),"Cooldown") -> Cooldown | BX3: =IFERROR(__xludf.DUMMYFUNCTION("""COMPUTED_VALUE"""),120.0) -> 120 | BY3: =IFERROR(__xludf.DUMMYFUNCTION("""COMPUTED_VALUE"""),"00 | 120s | Cost 0 ⧈ | Next 1 ⧈") -> 00 | 120s | Cost 0 ⧈ | Next 1 ⧈
